Workbook
Name AE: Feedform!$A$2:$A$64
Name Four: Feedform!$F$2:$F$66
Name Avgs: FGL!$O$13
Name Two: Feedform!$D$2:$D$66
Name All: Feedform!$B$2:$B$66
Name Chapter: Feedform!$B$2:$B$66
Name One: Feedform!$C$2:$C$66
Name Actives: Feedform!$B$2:$B$51
Name Five: Feedform!$G$2:$G$66
Name Avg: FGL!$C$13:$O$13
Name SIx: Feedform!$H$2:$H$62
Name Seven: Feedform!$I$2:$I$70
Name Three: Feedform!$E$2:$E$66

Sheet Feedform
A1: AE | B1: Name | C1: 45170 | D1: 45184 | E1: 45198 | F1: 45212 | G1: 45226 | H1: 45240 | I1: 45261
A2: 1564 | B2: Carson Dodd | C2: {=IFERROR(INDEX('Sep 1'!$C$2:$C$321, MATCH($A2,'Sep 1'!$B$2:$B$320,0)),"")} -> 4 | D2: {=IFERROR(INDEX('Sep 15'!$C$2:$C$370, MATCH($A2, 'Sep 15'!$B$2:$B$370,0)),"")} -> 3.85 | E2: {=IFERROR(INDEX('Sep 29'!$C$2:$C$435, MATCH($A2, 'Sep 29'!$B$2:$B$435,0)),"")} -> 3.845 | F2: {=IFERROR(INDEX('Oct 13'!$C$2:$C$389, MATCH($A2, 'Oct 13'!$B$2:$B$389,0)),"")} -> 3.462 | G2: {=IFERROR(INDEX('Oct 27'!$C$2:$C$434, MATCH($A2, 'Oct 27'!$B$2:$B$434,0)),"")} -> 3.538 | H2: {=IFERROR(INDEX('Nov 10'!$C$2:$C$485, MATCH($A2, 'Nov 10'!$B$2:$B$485,0)),"")} -> 3.538 | I2: {=IFERROR(INDEX('Dec 1'!$C$2:$C$542, MATCH($A2, 'Dec 1'!$B$2:$B$542,0)),"")} -> 3.744
A3: 1577 | B3: Brady Sorbin | C3: {=IFERROR(INDEX('Sep 1'!$C$2:$C$321, MATCH($A3,'Sep 1'!$B$2:$B$320,0)),"")} -> 3.84 | D3: {=IFERROR(INDEX('Sep 15'!$C$2:$C$370, MATCH($A3, 'Sep 15'!$B$2:$B$370,0)),"")} -> 4 | E3: {=IFERROR(INDEX('Sep 29'!$C$2:$C$435, MATCH($A3, 'Sep 29'!$B$2:$B$435,0)),"")} -> 4 | F3: {=IFERROR(INDEX('Oct 13'!$C$2:$C$389, MATCH($A3, 'Oct 13'!$B$2:$B$389,0)),"")} -> 2 | G3: {=IFERROR(INDEX('Oct 27'!$C$2:$C$434, MATCH($A3, 'Oct 27'!$B$2:$B$434,0)),"")} -> 2 | H3: {=IFERROR(INDEX('Nov 10'!$C$2:$C$485, MATCH($A3, 'Nov 10'!$B$2:$B$485,0)),"")} -> 3.47 | I3: {=IFERROR(INDEX('Dec 1'!$C$2:$C$542, MATCH($A3, 'Dec 1'!$B$2:$B$542,0)),"")} -> 2
A4: 1582 | B4: Toby Tobin | C4: - | D4: {=IFERROR(INDEX('Sep 15'!$C$2:$C$370, MATCH($A4, 'Sep 15'!$B$2:$B$370,0)),"")} | E4: {=IFERROR(INDEX('Sep 29'!$C$2:$C$435, MATCH($A4, 'Sep 29'!$B$2:$B$435,0)),"")} | F4: {=IFERROR(INDEX('Oct 13'!$C$2:$C$389, MATCH($A4, 'Oct 13'!$B$2:$B$389,0)),"")} | G4: {=IFERROR(INDEX('Oct 27'!$C$2:$C$434, MATCH($A4, 'Oct 27'!$B$2:$B$434,0)),"")} | H4: {=IFERROR(INDEX('Nov 10'!$C$2:$C$485, MATCH($A4, 'Nov 10'!$B$2:$B$485,0)),"")} | I4: {=IFERROR(INDEX('Dec 1'!$C$2:$C$542, MATCH($A4, 'Dec 1'!$B$2:$B$542,0)),"")}
A5: 1591 | B5: Nate Hollenbeck | C5: {=IFERROR(INDEX('Sep 1'!$C$2:$C$321, MATCH($A5,'Sep 1'!$B$2:$B$320,0)),"")} -> 4 | D5: {=IFERROR(INDEX('Sep 15'!$C$2:$C$370, MATCH($A5, 'Sep 15'!$B$2:$B$370,0)),"")} -> 4 | E5: {=IFERROR(INDEX('Sep 29'!$C$2:$C$435, MATCH($A5, 'Sep 29'!$B$2:$B$435,0)),"")} -> 4 | F5: {=IFERROR(INDEX('Oct 13'!$C$2:$C$389, MATCH($A5, 'Oct 13'!$B$2:$B$389,0)),"")} -> 4 | G5: {=IFERROR(INDEX('Oct 27'!$C$2:$C$434, MATCH($A5, 'Oct 27'!$B$2:$B$434,0)),"")} -> 4 | H5: {=IFERROR(INDEX('Nov 10'!$C$2:$C$485, MATCH($A5, 'Nov 10'!$B$2:$B$485,0)),"")} -> 4 | I5: {=IFERROR(INDEX('Dec 1'!$C$2:$C$542, MATCH($A5, 'Dec 1'!$B$2:$B$542,0)),"")} -> 4
A6: 1592 | B6: Antonio Soto | C6: {=IFERROR(INDEX('Sep 1'!$C$2:$C$321, MATCH($A6,'Sep 1'!$B$2:$B$320,0)),"")} -> 4 | D6: {=IFERROR(INDEX('Sep 15'!$C$2:$C$370, MATCH($A6, 'Sep 15'!$B$2:$B$370,0)),"")} -> 3.6 | E6: {=IFERROR(INDEX('Sep 29'!$C$2:$C$435, MATCH($A6, 'Sep 29'!$B$2:$B$435,0)),"")} -> 3.6 | F6: {=IFERROR(INDEX('Oct 13'!$C$2:$C$389, MATCH($A6, 'Oct 13'!$B$2:$B$389,0)),"")} -> 4 | G6: {=IFERROR(INDEX('Oct 27'!$C$2:$C$434, MATCH($A6, 'Oct 27'!$B$2:$B$434,0)),"")} -> 3.695 | H6: {=IFERROR(INDEX('Nov 10'!$C$2:$C$485, MATCH($A6, 'Nov 10'!$B$2:$B$485,0)),"")} -> 3.69 | I6: {=IFERROR(INDEX('Dec 1'!$C$2:$C$542, MATCH($A6, 'Dec 1'!$B$2:$B$542,0)),"")} -> 3.69
A7: 1594 | B7: Thomas Hope | C7: {=IFERROR(INDEX('Sep 1'!$C$2:$C$321, MATCH($A7,'Sep 1'!$B$2:$B$320,0)),"")} -> 4 | D7: {=IFERROR(INDEX('Sep 15'!$C$2:$C$370, MATCH($A7, 'Sep 15'!$B$2:$B$370,0)),"")} -> 4 | E7: {=IFERROR(INDEX('Sep 29'!$C$2:$C$435, MATCH($A7, 'Sep 29'!$B$2:$B$435,0)),"")} -> 3.5 | F7: {=IFERROR(INDEX('Oct 13'!$C$2:$C$389, MATCH($A7, 'Oct 13'!$B$2:$B$389,0)),"")} -> 3.5 | G7: {=IFERROR(INDEX('Oct 27'!$C$2:$C$434, MATCH($A7, 'Oct 27'!$B$2:$B$434,0)),"")} -> 3.5 | H7: {=IFERROR(INDEX('Nov 10'!$C$2:$C$485, MATCH($A7, 'Nov 10'!$B$2:$B$485,0)),"")} -> 3.6 | I7: {=IFERROR(INDEX('Dec 1'!$C$2:$C$542, MATCH($A7, 'Dec 1'!$B$2:$B$542,0)),"")} -> 3.5
A8: 1596 | B8: Michael Leiting | C8: {=IFERROR(INDEX('Sep 1'!$C$2:$C$321, MATCH($A8,'Sep 1'!$B$2:$B$320,0)),"")} -> 4 | D8: {=IFERROR(INDEX('Sep 15'!$C$2:$C$370, MATCH($A8, 'Sep 15'!$B$2:$B$370,0)),"")} -> 4 | E8: {=IFERROR(INDEX('Sep 29'!$C$2:$C$435, MATCH($A8, 'Sep 29'!$B$2:$B$435,0)),"")} -> 3.786 | F8: {=IFERROR(INDEX('Oct 13'!$C$2:$C$389, MATCH($A8, 'Oct 13'!$B$2:$B$389,0)),"")} -> 3.86 | G8: {=IFERROR(INDEX('Oct 27'!$C$2:$C$434, MATCH($A8, 'Oct 27'!$B$2:$B$434,0)),"")} -> 3.88 | H8: {=IFERROR(INDEX('Nov 10'!$C$2:$C$485, MATCH($A8, 'Nov 10'!$B$2:$B$485,0)),"")} -> 3.929 | I8: {=IFERROR(INDEX('Dec 1'!$C$2:$C$542, MATCH($A8, 'Dec 1'!$B$2:$B$542,0)),"")} -> 3.856
A9: 1597 | B9: Hunter Kinnaman | C9: {=IFERROR(INDEX('Sep 1'!$C$2:$C$321, MATCH($A9,'Sep 1'!$B$2:$B$320,0)),"")} -> 4 | D9: {=IFERROR(INDEX('Sep 15'!$C$2:$C$370, MATCH($A9, 'Sep 15'!$B$2:$B$370,0)),"")} -> 2.23 | E9: {=IFERROR(INDEX('Sep 29'!$C$2:$C$435, MATCH($A9, 'Sep 29'!$B$2:$B$435,0)),"")} -> 2.6 | F9: {=IFERROR(INDEX('Oct 13'!$C$2:$C$389, MATCH($A9, 'Oct 13'!$B$2:$B$389,0)),"")} -> 2.5 | G9: {=IFERROR(INDEX('Oct 27'!$C$2:$C$434, MATCH($A9, 'Oct 27'!$B$2:$B$434,0)),"")} -> 2.35 | H9: {=IFERROR(INDEX('Nov 10'!$C$2:$C$485, MATCH($A9, 'Nov 10'!$B$2:$B$485,0)),"")} -> 2.23 | I9: {=IFERROR(INDEX('Dec 1'!$C$2:$C$542, MATCH($A9, 'Dec 1'!$B$2:$B$542,0)),"")} -> 2.58
A10: 1598 | B10: Callahan Weeks | C10: {=IFERROR(INDEX('Sep 1'!$C$2:$C$321, MATCH($A10,'Sep 1'!$B$2:$B$320,0)),"")} -> 4 | D10: {=IFERROR(INDEX('Sep 15'!$C$2:$C$370, MATCH($A10, 'Sep 15'!$B$2:$B$370,0)),"")} -> 3.334 | E10: {=IFERROR(INDEX('Sep 29'!$C$2:$C$435, MATCH($A10, 'Sep 29'!$B$2:$B$435,0)),"")} -> 3.072 | F10: {=IFERROR(INDEX('Oct 13'!$C$2:$C$389, MATCH($A10, 'Oct 13'!$B$2:$B$389,0)),"")} -> 3.5 | G10: {=IFERROR(INDEX('Oct 27'!$C$2:$C$434, MATCH($A10, 'Oct 27'!$B$2:$B$434,0)),"")} -> 3.5 | H10: {=IFERROR(INDEX('Nov 10'!$C$2:$C$485, MATCH($A10, 'Nov 10'!$B$2:$B$485,0)),"")} -> 3.856 | I10: {=IFERROR(INDEX('Dec 1'!$C$2:$C$542, MATCH($A10, 'Dec 1'!$B$2:$B$542,0)),"")} -> 3.786
A11: 1599 | B11: Rishik Kancharla | C11: {=IFERROR(INDEX('Sep 1'!$C$2:$C$321, MATCH($A11,'Sep 1'!$B$2:$B$320,0)),"")} -> 3.4 | D11: {=IFERROR(INDEX('Sep 15'!$C$2:$C$370, MATCH($A11, 'Sep 15'!$B$2:$B$370,0)),"")} -> 3.8 | E11: {=IFERROR(INDEX('Sep 29'!$C$2:$C$435, MATCH($A11, 'Sep 29'!$B$2:$B$435,0)),"")} -> 3.2 | F11: {=IFERROR(INDEX('Oct 13'!$C$2:$C$389, MATCH($A11, 'Oct 13'!$B$2:$B$389,0)),"")} -> 3 | G11: {=IFERROR(INDEX('Oct 27'!$C$2:$C$434, MATCH($A11, 'Oct 27'!$B$2:$B$434,0)),"")} -> 3 | H11: {=IFERROR(INDEX('Nov 10'!$C$2:$C$485, MATCH($A11, 'Nov 10'!$B$2:$B$485,0)),"")} -> 2.86 | I11: {=IFERROR(INDEX('Dec 1'!$C$2:$C$542, MATCH($A11, 'Dec 1'!$B$2:$B$542,0)),"")} -> 2.626
A12: 1602 | B12: Elijah Doyle | C12: {=IFERROR(INDEX('Sep 1'!$C$2:$C$321, MATCH($A12,'Sep 1'!$B$2:$B$320,0)),"")} -> 4 | D12: {=IFERROR(INDEX('Sep 15'!$C$2:$C$370, MATCH($A12, 'Sep 15'!$B$2:$B$370,0)),"")} -> 4 | E12: {=IFERROR(INDEX('Sep 29'!$C$2:$C$435, MATCH($A12, 'Sep 29'!$B$2:$B$435,0)),"")} -> 3.835 | F12: {=IFERROR(INDEX('Oct 13'!$C$2:$C$389, MATCH($A12, 'Oct 13'!$B$2:$B$389,0)),"")} -> 3.918 | G12: {=IFERROR(INDEX('Oct 27'!$C$2:$C$434, MATCH($A12, 'Oct 27'!$B$2:$B$434,0)),"")} -> 3.918 | H12: {=IFERROR(INDEX('Nov 10'!$C$2:$C$485, MATCH($A12, 'Nov 10'!$B$2:$B$485,0)),"")} -> 3.83 | I12: {=IFERROR(INDEX('Dec 1'!$C$2:$C$542, MATCH($A12, 'Dec 1'!$B$2:$B$542,0)),"")} -> 3.75
A13: 1605 | B13: Jan Gomez | C13: {=IFERROR(INDEX('Sep 1'!$C$2:$C$321, MATCH($A13,'Sep 1'!$B$2:$B$320,0)),"")} -> 4 | D13: {=IFERROR(INDEX('Sep 15'!$C$2:$C$370, MATCH($A13, 'Sep 15'!$B$2:$B$370,0)),"")} -> 3.8 | E13: {=IFERROR(INDEX('Sep 29'!$C$2:$C$435, MATCH($A13, 'Sep 29'!$B$2:$B$435,0)),"")} -> 3.4 | F13: {=IFERROR(INDEX('Oct 13'!$C$2:$C$389, MATCH($A13, 'Oct 13'!$B$2:$B$389,0)),"")} -> 3.4 | G13: {=IFERROR(INDEX('Oct 27'!$C$2:$C$434, MATCH($A13, 'Oct 27'!$B$2:$B$434,0)),"")} -> 3.2 | H13: {=IFERROR(INDEX('Nov 10'!$C$2:$C$485, MATCH($A13, 'Nov 10'!$B$2:$B$485,0)),"")} -> 3.2 | I13: {=IFERROR(INDEX('Dec 1'!$C$2:$C$542, MATCH($A13, 'Dec 1'!$B$2:$B$542,0)),"")} -> 3.066
A14: 1608 | B14: Kris Anwar | C14: {=IFERROR(INDEX('Sep 1'!$C$2:$C$321, MATCH($A14,'Sep 1'!$B$2:$B$320,0)),"")} -> 3.08 | D14: {=IFERROR(INDEX('Sep 15'!$C$2:$C$370, MATCH($A14, 'Sep 15'!$B$2:$B$370,0)),"")} -> 3.58 | E14: {=IFERROR(INDEX('Sep 29'!$C$2:$C$435, MATCH($A14, 'Sep 29'!$B$2:$B$435,0)),"")} -> 3.415 | F14: {=IFERROR(INDEX('Oct 13'!$C$2:$C$389, MATCH($A14, 'Oct 13'!$B$2:$B$389,0)),"")} -> 3.165 | G14: {=IFERROR(INDEX('Oct 27'!$C$2:$C$434, MATCH($A14, 'Oct 27'!$B$2:$B$434,0)),"")} -> 3.498 | H14: {=IFERROR(INDEX('Nov 10'!$C$2:$C$485, MATCH($A14, 'Nov 10'!$B$2:$B$485,0)),"")} -> 3.583 | I14: {=IFERROR(INDEX('Dec 1'!$C$2:$C$542, MATCH($A14, 'Dec 1'!$B$2:$B$542,0)),"")} -> 3.58
A15: 1613 | B15: Andrew Wellman | C15: {=IFERROR(INDEX('Sep 1'!$C$2:$C$321, MATCH($A15,'Sep 1'!$B$2:$B$320,0)),"")} -> 4 | D15: {=IFERROR(INDEX('Sep 15'!$C$2:$C$370, MATCH($A15, 'Sep 15'!$B$2:$B$370,0)),"")} -> 4 | E15: {=IFERROR(INDEX('Sep 29'!$C$2:$C$435, MATCH($A15, 'Sep 29'!$B$2:$B$435,0)),"")} -> 3.31 | F15: {=IFERROR(INDEX('Oct 13'!$C$2:$C$389, MATCH($A15, 'Oct 13'!$B$2:$B$389,0)),"")} -> 3.534 | G15: {=IFERROR(INDEX('Oct 27'!$C$2:$C$434, MATCH($A15, 'Oct 27'!$B$2:$B$434,0)),"")} -> 3.5 | H15: {=IFERROR(INDEX('Nov 10'!$C$2:$C$485, MATCH($A15, 'Nov 10'!$B$2:$B$485,0)),"")} -> 3.534 | I15: {=IFERROR(INDEX('Dec 1'!$C$2:$C$542, MATCH($A15, 'Dec 1'!$B$2:$B$542,0)),"")} -> 3.53
A16: 1615 | B16: Harry Wells | C16: {=IFERROR(INDEX('Sep 1'!$C$2:$C$321, MATCH($A16,'Sep 1'!$B$2:$B$320,0)),"")} -> 4 | D16: {=IFERROR(INDEX('Sep 15'!$C$2:$C$370, MATCH($A16, 'Sep 15'!$B$2:$B$370,0)),"")} -> 4 | E16: {=IFERROR(INDEX('Sep 29'!$C$2:$C$435, MATCH($A16, 'Sep 29'!$B$2:$B$435,0)),"")} -> 3.95 | F16: {=IFERROR(INDEX('Oct 13'!$C$2:$C$389, MATCH($A16, 'Oct 13'!$B$2:$B$389,0)),"")} -> 4 | G16: {=IFERROR(INDEX('Oct 27'!$C$2:$C$434, MATCH($A16, 'Oct 27'!$B$2:$B$434,0)),"")} -> 4 | H16: {=IFERROR(INDEX('Nov 10'!$C$2:$C$485, MATCH($A16, 'Nov 10'!$B$2:$B$485,0)),"")} -> 4 | I16: {=IFERROR(INDEX('Dec 1'!$C$2:$C$542, MATCH($A16, 'Dec 1'!$B$2:$B$542,0)),"")} -> 4
... A25: 1625 | B25: Owen Micek | C25: {=IFERROR(INDEX('Sep 1'!$C$2:$C$321, MATCH($A25,'Sep 1'!$B$2:$B$320,0)),"")} -> 4 | D25: {=IFERROR(INDEX('Sep 15'!$C$2:$C$370, MATCH($A25, 'Sep 15'!$B$2:$B$370,0)),"")} -> 3.89 | E25: {=IFERROR(INDEX('Sep 29'!$C$2:$C$435, MATCH($A25, 'Sep 29'!$B$2:$B$435,0)),"")} -> 3.668 | F25: {=IFERROR(INDEX('Oct 13'!$C$2:$C$389, MATCH($A25, 'Oct 13'!$B$2:$B$389,0)),"")} -> 3.001 | G25: {=IFERROR(INDEX('Oct 27'!$C$2:$C$434, MATCH($A25, 'Oct 27'!$B$2:$B$434,0)),"")} -> 3 | H25: {=IFERROR(INDEX('Nov 10'!$C$2:$C$485, MATCH($A25, 'Nov 10'!$B$2:$B$485,0)),"")} -> 3.083 | I25: {=IFERROR(INDEX('Dec 1'!$C$2:$C$542, MATCH($A25, 'Dec 1'!$B$2:$B$542,0)),"")} -> 3.083
A26: 1626 | B26: Jordan Lockert | C26: {=IFERROR(INDEX('Sep 1'!$C$2:$C$321, MATCH($A26,'Sep 1'!$B$2:$B$320,0)),"")} -> 2 | D26: {=IFERROR(INDEX('Sep 15'!$C$2:$C$370, MATCH($A26, 'Sep 15'!$B$2:$B$370,0)),"")} -> 3.667 | E26: {=IFERROR(INDEX('Sep 29'!$C$2:$C$435, MATCH($A26, 'Sep 29'!$B$2:$B$435,0)),"")} -> 2 | F26: - | G26: - | H26: {=IFERROR(INDEX('Nov 10'!$C$2:$C$485, MATCH($A26, 'Nov 10'!$B$2:$B$485,0)),"")} | I26: {=IFERROR(INDEX('Dec 1'!$C$2:$C$542, MATCH($A26, 'Dec 1'!$B$2:$B$542,0)),"")} | J26: -
A27: 1627 | B27: Connor Radde | C27: {=IFERROR(INDEX('Sep 1'!$C$2:$C$321, MATCH($A27,'Sep 1'!$B$2:$B$320,0)),"")} -> 4 | D27: {=IFERROR(INDEX('Sep 15'!$C$2:$C$370, MATCH($A27, 'Sep 15'!$B$2:$B$370,0)),"")} -> 3.65 | E27: {=IFERROR(INDEX('Sep 29'!$C$2:$C$435, MATCH($A27, 'Sep 29'!$B$2:$B$435,0)),"")} -> 3.33 | F27: {=IFERROR(INDEX('Oct 13'!$C$2:$C$389, MATCH($A27, 'Oct 13'!$B$2:$B$389,0)),"")} -> 3.083 | G27: {=IFERROR(INDEX('Oct 27'!$C$2:$C$434, MATCH($A27, 'Oct 27'!$B$2:$B$434,0)),"")} -> 3.085 | H27: {=IFERROR(INDEX('Nov 10'!$C$2:$C$485, MATCH($A27, 'Nov 10'!$B$2:$B$485,0)),"")} -> 3.083 | I27: {=IFERROR(INDEX('Dec 1'!$C$2:$C$542, MATCH($A27, 'Dec 1'!$B$2:$B$542,0)),"")} -> 3
A28: 1628 | B28: James Moeller | C28: {=IFERROR(INDEX('Sep 1'!$C$2:$C$321, MATCH($A28,'Sep 1'!$B$2:$B$320,0)),"")} -> 4 | D28: {=IFERROR(INDEX('Sep 15'!$C$2:$C$370, MATCH($A28, 'Sep 15'!$B$2:$B$370,0)),"")} -> 3.769 | E28: {=IFERROR(INDEX('Sep 29'!$C$2:$C$435, MATCH($A28, 'Sep 29'!$B$2:$B$435,0)),"")} -> 3.924 | F28: {=IFERROR(INDEX('Oct 13'!$C$2:$C$389, MATCH($A28, 'Oct 13'!$B$2:$B$389,0)),"")} -> 3.924 | G28: {=IFERROR(INDEX('Oct 27'!$C$2:$C$434, MATCH($A28, 'Oct 27'!$B$2:$B$434,0)),"")} -> 4 | H28: {=IFERROR(INDEX('Nov 10'!$C$2:$C$485, MATCH($A28, 'Nov 10'!$B$2:$B$485,0)),"")} -> 3.845 | I28: {=IFERROR(INDEX('Dec 1'!$C$2:$C$542, MATCH($A28, 'Dec 1'!$B$2:$B$542,0)),"")} -> 3.845
A29: 1630 | B29: Nico Bianchette | C29: {=IFERROR(INDEX('Sep 1'!$C$2:$C$321, MATCH($A29,'Sep 1'!$B$2:$B$320,0)),"")} -> 3.833 | D29: {=IFERROR(INDEX('Sep 15'!$C$2:$C$370, MATCH($A29, 'Sep 15'!$B$2:$B$370,0)),"")} -> 3.866 | E29: {=IFERROR(INDEX('Sep 29'!$C$2:$C$435, MATCH($A29, 'Sep 29'!$B$2:$B$435,0)),"")} -> 3.86 | F29: {=IFERROR(INDEX('Oct 13'!$C$2:$C$389, MATCH($A29, 'Oct 13'!$B$2:$B$389,0)),"")} -> 3.2 | G29: {=IFERROR(INDEX('Oct 27'!$C$2:$C$434, MATCH($A29, 'Oct 27'!$B$2:$B$434,0)),"")} -> 3.068 | H29: {=IFERROR(INDEX('Nov 10'!$C$2:$C$485, MATCH($A29, 'Nov 10'!$B$2:$B$485,0)),"")} -> 3.334 | I29: {=IFERROR(INDEX('Dec 1'!$C$2:$C$542, MATCH($A29, 'Dec 1'!$B$2:$B$542,0)),"")} -> 3.134
A30: 1631 | B30: Sean Pate | C30: {=IFERROR(INDEX('Sep 1'!$C$2:$C$321, MATCH($A30,'Sep 1'!$B$2:$B$320,0)),"")} -> 4 | D30: {=IFERROR(INDEX('Sep 15'!$C$2:$C$370, MATCH($A30, 'Sep 15'!$B$2:$B$370,0)),"")} -> 4 | E30: {=IFERROR(INDEX('Sep 29'!$C$2:$C$435, MATCH($A30, 'Sep 29'!$B$2:$B$435,0)),"")} -> 3.2 | F30: {=IFERROR(INDEX('Oct 13'!$C$2:$C$389, MATCH($A30, 'Oct 13'!$B$2:$B$389,0)),"")} -> 3 | G30: {=IFERROR(INDEX('Oct 27'!$C$2:$C$434, MATCH($A30, 'Oct 27'!$B$2:$B$434,0)),"")} -> 3.4 | H30: {=IFERROR(INDEX('Nov 10'!$C$2:$C$485, MATCH($A30, 'Nov 10'!$B$2:$B$485,0)),"")} -> 2 | I30: {=IFERROR(INDEX('Dec 1'!$C$2:$C$542, MATCH($A30, 'Dec 1'!$B$2:$B$542,0)),"")} -> 2.934
A31: 1632 | B31: Del Casteel | C31: {=IFERROR(INDEX('Sep 1'!$C$2:$C$321, MATCH($A31,'Sep 1'!$B$2:$B$320,0)),"")} -> 3.3 | D31: {=IFERROR(INDEX('Sep 15'!$C$2:$C$370, MATCH($A31, 'Sep 15'!$B$2:$B$370,0)),"")} -> 3 | E31: {=IFERROR(INDEX('Sep 29'!$C$2:$C$435, MATCH($A31, 'Sep 29'!$B$2:$B$435,0)),"")} -> 2.9 | F31: {=IFERROR(INDEX('Oct 13'!$C$2:$C$389, MATCH($A31, 'Oct 13'!$B$2:$B$389,0)),"")} -> 2.9 | G31: - | H31: {=IFERROR(INDEX('Nov 10'!$C$2:$C$485, MATCH($A31, 'Nov 10'!$B$2:$B$485,0)),"")} | I31: {=IFERROR(INDEX('Dec 1'!$C$2:$C$542, MATCH($A31, 'Dec 1'!$B$2:$B$542,0)),"")} | J31: -
A32: 1634 | B32: Braeden Haptonstall | C32: {=IFERROR(INDEX('Sep 1'!$C$2:$C$321, MATCH($A32,'Sep 1'!$B$2:$B$320,0)),"")} -> 4 | D32: {=IFERROR(INDEX('Sep 15'!$C$2:$C$370, MATCH($A32, 'Sep 15'!$B$2:$B$370,0)),"")} -> 4 | E32: {=IFERROR(INDEX('Sep 29'!$C$2:$C$435, MATCH($A32, 'Sep 29'!$B$2:$B$435,0)),"")} -> 4 | F32: {=IFERROR(INDEX('Oct 13'!$C$2:$C$389, MATCH($A32, 'Oct 13'!$B$2:$B$389,0)),"")} -> 4 | G32: {=IFERROR(INDEX('Oct 27'!$C$2:$C$434, MATCH($A32, 'Oct 27'!$B$2:$B$434,0)),"")} -> 4 | H32: {=IFERROR(INDEX('Nov 10'!$C$2:$C$485, MATCH($A32, 'Nov 10'!$B$2:$B$485,0)),"")} -> 4 | I32: {=IFERROR(INDEX('Dec 1'!$C$2:$C$542, MATCH($A32, 'Dec 1'!$B$2:$B$542,0)),"")} -> 4
A33: 1635 | B33: Braeden Aherns | C33: {=IFERROR(INDEX('Sep 1'!$C$2:$C$321, MATCH($A33,'Sep 1'!$B$2:$B$320,0)),"")} -> 4 | D33: {=IFERROR(INDEX('Sep 15'!$C$2:$C$370, MATCH($A33, 'Sep 15'!$B$2:$B$370,0)),"")} -> 4 | E33: {=IFERROR(INDEX('Sep 29'!$C$2:$C$435, MATCH($A33, 'Sep 29'!$B$2:$B$435,0)),"")} -> 3.918 | F33: {=IFERROR(INDEX('Oct 13'!$C$2:$C$389, MATCH($A33, 'Oct 13'!$B$2:$B$389,0)),"")} -> 2.583 | G33: {=IFERROR(INDEX('Oct 27'!$C$2:$C$434, MATCH($A33, 'Oct 27'!$B$2:$B$434,0)),"")} -> 2.5 | H33: {=IFERROR(INDEX('Nov 10'!$C$2:$C$485, MATCH($A33, 'Nov 10'!$B$2:$B$485,0)),"")} -> 2.668 | I33: {=IFERROR(INDEX('Dec 1'!$C$2:$C$542, MATCH($A33, 'Dec 1'!$B$2:$B$542,0)),"")}
A34: 1636 | B34: Nik Ostrowski | C34: {=IFERROR(INDEX('Sep 1'!$C$2:$C$321, MATCH($A34,'Sep 1'!$B$2:$B$320,0)),"")} -> 3.62 | D34: {=IFERROR(INDEX('Sep 15'!$C$2:$C$370, MATCH($A34, 'Sep 15'!$B$2:$B$370,0)),"")} -> 3.62 | E34: {=IFERROR(INDEX('Sep 29'!$C$2:$C$435, MATCH($A34, 'Sep 29'!$B$2:$B$435,0)),"")} -> 3.46 | F34: {=IFERROR(INDEX('Oct 13'!$C$2:$C$389, MATCH($A34, 'Oct 13'!$B$2:$B$389,0)),"")} -> 3.41 | G34: {=IFERROR(INDEX('Oct 27'!$C$2:$C$434, MATCH($A34, 'Oct 27'!$B$2:$B$434,0)),"")} -> 3.1 | H34: {=IFERROR(INDEX('Nov 10'!$C$2:$C$485, MATCH($A34, 'Nov 10'!$B$2:$B$485,0)),"")} -> 2 | I34: {=IFERROR(INDEX('Dec 1'!$C$2:$C$542, MATCH($A34, 'Dec 1'!$B$2:$B$542,0)),"")} -> 2
A35: 1637 | B35: Sebastian Palka | C35: {=IFERROR(INDEX('Sep 1'!$C$2:$C$321, MATCH($A35,'Sep 1'!$B$2:$B$320,0)),"")} -> 4 | D35: {=IFERROR(INDEX('Sep 15'!$C$2:$C$370, MATCH($A35, 'Sep 15'!$B$2:$B$370,0)),"")} -> 4 | E35: {=IFERROR(INDEX('Sep 29'!$C$2:$C$435, MATCH($A35, 'Sep 29'!$B$2:$B$435,0)),"")} -> 3.6 | F35: {=IFERROR(INDEX('Oct 13'!$C$2:$C$389, MATCH($A35, 'Oct 13'!$B$2:$B$389,0)),"")} -> 3.753 | G35: {=IFERROR(INDEX('Oct 27'!$C$2:$C$434, MATCH($A35, 'Oct 27'!$B$2:$B$434,0)),"")} -> 3.734 | H35: {=IFERROR(INDEX('Nov 10'!$C$2:$C$485, MATCH($A35, 'Nov 10'!$B$2:$B$485,0)),"")} -> 3.868 | I35: {=IFERROR(INDEX('Dec 1'!$C$2:$C$542, MATCH($A35, 'Dec 1'!$B$2:$B$542,0)),"")} -> 4
A36: 1639 | B36: Danny Smyth | C36: {=IFERROR(INDEX('Sep 1'!$C$2:$C$321, MATCH($A36,'Sep 1'!$B$2:$B$320,0)),"")} -> 4 | D36: {=IFERROR(INDEX('Sep 15'!$C$2:$C$370, MATCH($A36, 'Sep 15'!$B$2:$B$370,0)),"")} -> 3.934 | E36: {=IFERROR(INDEX('Sep 29'!$C$2:$C$435, MATCH($A36, 'Sep 29'!$B$2:$B$435,0)),"")} -> 4 | F36: {=IFERROR(INDEX('Oct 13'!$C$2:$C$389, MATCH($A36, 'Oct 13'!$B$2:$B$389,0)),"")} -> 3.918 | G36: {=IFERROR(INDEX('Oct 27'!$C$2:$C$434, MATCH($A36, 'Oct 27'!$B$2:$B$434,0)),"")} -> 3.918 | H36: {=IFERROR(INDEX('Nov 10'!$C$2:$C$485, MATCH($A36, 'Nov 10'!$B$2:$B$485,0)),"")} -> 3.918 | I36: {=IFERROR(INDEX('Dec 1'!$C$2:$C$542, MATCH($A36, 'Dec 1'!$B$2:$B$542,0)),"")} -> 3.833
A37: 1640 | B37: Garrett Smith | C37: {=IFERROR(INDEX('Sep 1'!$C$2:$C$321, MATCH($A37,'Sep 1'!$B$2:$B$320,0)),"")} -> 4 | D37: {=IFERROR(INDEX('Sep 15'!$C$2:$C$370, MATCH($A37, 'Sep 15'!$B$2:$B$370,0)),"")} -> 4 | E37: {=IFERROR(INDEX('Sep 29'!$C$2:$C$435, MATCH($A37, 'Sep 29'!$B$2:$B$435,0)),"")} -> 3.693 | F37: {=IFERROR(INDEX('Oct 13'!$C$2:$C$389, MATCH($A37, 'Oct 13'!$B$2:$B$389,0)),"")} -> 3.693 | G37: {=IFERROR(INDEX('Oct 27'!$C$2:$C$434, MATCH($A37, 'Oct 27'!$B$2:$B$434,0)),"")} -> 3.538 | H37: {=IFERROR(INDEX('Nov 10'!$C$2:$C$485, MATCH($A37, 'Nov 10'!$B$2:$B$485,0)),"")} -> 3.538 | I37: {=IFERROR(INDEX('Dec 1'!$C$2:$C$542, MATCH($A37, 'Dec 1'!$B$2:$B$542,0)),"")} -> 3.308
A38: 1641 | B38: Hayden Smith | C38: {=IFERROR(INDEX('Sep 1'!$C$2:$C$321, MATCH($A38,'Sep 1'!$B$2:$B$320,0)),"")} -> 3.222 | D38: {=IFERROR(INDEX('Sep 15'!$C$2:$C$370, MATCH($A38, 'Sep 15'!$B$2:$B$370,0)),"")} -> 1.616 | E38: {=IFERROR(INDEX('Sep 29'!$C$2:$C$435, MATCH($A38, 'Sep 29'!$B$2:$B$435,0)),"")} -> 2 | F38: {=IFERROR(INDEX('Oct 13'!$C$2:$C$389, MATCH($A38, 'Oct 13'!$B$2:$B$389,0)),"")} -> 2.2 | G38: {=IFERROR(INDEX('Oct 27'!$C$2:$C$434, MATCH($A38, 'Oct 27'!$B$2:$B$434,0)),"")} -> 1.868 | H38: {=IFERROR(INDEX('Nov 10'!$C$2:$C$485, MATCH($A38, 'Nov 10'!$B$2:$B$485,0)),"")} -> 2.181 | I38: {=IFERROR(INDEX('Dec 1'!$C$2:$C$542, MATCH($A38, 'Dec 1'!$B$2:$B$542,0)),"")} -> 2.488
A39: 1642 | B39: Riley Pankow | C39: {=IFERROR(INDEX('Sep 1'!$C$2:$C$321, MATCH($A39,'Sep 1'!$B$2:$B$320,0)),"")} -> 4 | D39: {=IFERROR(INDEX('Sep 15'!$C$2:$C$370, MATCH($A39, 'Sep 15'!$B$2:$B$370,0)),"")} -> 4 | E39: {=IFERROR(INDEX('Sep 29'!$C$2:$C$435, MATCH($A39, 'Sep 29'!$B$2:$B$435,0)),"")} -> 3.4 | F39: {=IFERROR(INDEX('Oct 13'!$C$2:$C$389, MATCH($A39, 'Oct 13'!$B$2:$B$389,0)),"")} -> 3.46 | G39: {=IFERROR(INDEX('Oct 27'!$C$2:$C$434, MATCH($A39, 'Oct 27'!$B$2:$B$434,0)),"")} -> 3.4 | H39: {=IFERROR(INDEX('Nov 10'!$C$2:$C$485, MATCH($A39, 'Nov 10'!$B$2:$B$485,0)),"")} -> 3.4 | I39: {=IFERROR(INDEX('Dec 1'!$C$2:$C$542, MATCH($A39, 'Dec 1'!$B$2:$B$542,0)),"")} -> 3.14
A40: 1643 | B40: Colby Hehnke | C40: {=IFERROR(INDEX('Sep 1'!$C$2:$C$321, MATCH($A40,'Sep 1'!$B$2:$B$320,0)),"")} -> 3.9 | D40: {=IFERROR(INDEX('Sep 15'!$C$2:$C$370, MATCH($A40, 'Sep 15'!$B$2:$B$370,0)),"")} -> 3.85 | E40: {=IFERROR(INDEX('Sep 29'!$C$2:$C$435, MATCH($A40, 'Sep 29'!$B$2:$B$435,0)),"")} -> 3.85 | F40: {=IFERROR(INDEX('Oct 13'!$C$2:$C$389, MATCH($A40, 'Oct 13'!$B$2:$B$389,0)),"")} -> 2 | G40: {=IFERROR(INDEX('Oct 27'!$C$2:$C$434, MATCH($A40, 'Oct 27'!$B$2:$B$434,0)),"")} -> 2.714 | H40: {=IFERROR(INDEX('Nov 10'!$C$2:$C$485, MATCH($A40, 'Nov 10'!$B$2:$B$485,0)),"")} -> 2.882 | I40: {=IFERROR(INDEX('Dec 1'!$C$2:$C$542, MATCH($A40, 'Dec 1'!$B$2:$B$542,0)),"")} -> 2.882
A41: 1644 | B41: Brady Perna | C41: {=IFERROR(INDEX('Sep 1'!$C$2:$C$321, MATCH($A41,'Sep 1'!$B$2:$B$320,0)),"")} -> 4 | D41: {=IFERROR(INDEX('Sep 15'!$C$2:$C$370, MATCH($A41, 'Sep 15'!$B$2:$B$370,0)),"")} -> 4 | E41: {=IFERROR(INDEX('Sep 29'!$C$2:$C$435, MATCH($A41, 'Sep 29'!$B$2:$B$435,0)),"")} -> 3.6 | F41: {=IFERROR(INDEX('Oct 13'!$C$2:$C$389, MATCH($A41, 'Oct 13'!$B$2:$B$389,0)),"")} -> 3 | G41: {=IFERROR(INDEX('Oct 27'!$C$2:$C$434, MATCH($A41, 'Oct 27'!$B$2:$B$434,0)),"")} -> 3.09 | H41: {=IFERROR(INDEX('Nov 10'!$C$2:$C$485, MATCH($A41, 'Nov 10'!$B$2:$B$485,0)),"")} -> 3.585 | I41: {=IFERROR(INDEX('Dec 1'!$C$2:$C$542, MATCH($A41, 'Dec 1'!$B$2:$B$542,0)),"")} -> 3.585
A42: 1645 | B42: Mac Clarke | C42: {=IFERROR(INDEX('Sep 1'!$C$2:$C$321, MATCH($A42,'Sep 1'!$B$2:$B$320,0)),"")} -> 4 | D42: {=IFERROR(INDEX('Sep 15'!$C$2:$C$370, MATCH($A42, 'Sep 15'!$B$2:$B$370,0)),"")} -> 4 | E42: {=IFERROR(INDEX('Sep 29'!$C$2:$C$435, MATCH($A42, 'Sep 29'!$B$2:$B$435,0)),"")} -> 4 | F42: {=IFERROR(INDEX('Oct 13'!$C$2:$C$389, MATCH($A42, 'Oct 13'!$B$2:$B$389,0)),"")} -> 3.75 | G42: {=IFERROR(INDEX('Oct 27'!$C$2:$C$434, MATCH($A42, 'Oct 27'!$B$2:$B$434,0)),"")} -> 3.6675 | H42: {=IFERROR(INDEX('Nov 10'!$C$2:$C$485, MATCH($A42, 'Nov 10'!$B$2:$B$485,0)),"")} -> 3.6675 | I42: {=IFERROR(INDEX('Dec 1'!$C$2:$C$542, MATCH($A42, 'Dec 1'!$B$2:$B$542,0)),"")} -> 3.258
A43: 1646 | B43: Cutter Riveland | C43: {=IFERROR(INDEX('Sep 1'!$C$2:$C$321, MATCH($A43,'Sep 1'!$B$2:$B$320,0)),"")} -> 3.816 | D43: {=IFERROR(INDEX('Sep 15'!$C$2:$C$370, MATCH($A43, 'Sep 15'!$B$2:$B$370,0)),"")} -> 3.625 | E43: {=IFERROR(INDEX('Sep 29'!$C$2:$C$435, MATCH($A43, 'Sep 29'!$B$2:$B$435,0)),"")} -> 3.126 | F43: {=IFERROR(INDEX('Oct 13'!$C$2:$C$389, MATCH($A43, 'Oct 13'!$B$2:$B$389,0)),"")} -> 3.186 | G43: {=IFERROR(INDEX('Oct 27'!$C$2:$C$434, MATCH($A43, 'Oct 27'!$B$2:$B$434,0)),"")} -> 2.561 | H43: {=IFERROR(INDEX('Nov 10'!$C$2:$C$485, MATCH($A43, 'Nov 10'!$B$2:$B$485,0)),"")} -> 2.499 | I43: {=IFERROR(INDEX('Dec 1'!$C$2:$C$542, MATCH($A43, 'Dec 1'!$B$2:$B$542,0)),"")} -> 2.645
... A51: 1656 | B51: JD Loera | C51: {=IFERROR(INDEX('Sep 1'!$C$2:$C$321, MATCH($A51,'Sep 1'!$B$2:$B$320,0)),"")} -> 3.42 | D51: {=IFERROR(INDEX('Sep 15'!$C$2:$C$370, MATCH($A51, 'Sep 15'!$B$2:$B$370,0)),"")} -> 3.3 | E51: {=IFERROR(INDEX('Sep 29'!$C$2:$C$435, MATCH($A51, 'Sep 29'!$B$2:$B$435,0)),"")} -> 3.28 | F51: {=IFERROR(INDEX('Oct 13'!$C$2:$C$389, MATCH($A51, 'Oct 13'!$B$2:$B$389,0)),"")} -> 2 | G51: {=IFERROR(INDEX('Oct 27'!$C$2:$C$434, MATCH($A51, 'Oct 27'!$B$2:$B$434,0)),"")} -> 3.29 | H51: {=IFERROR(INDEX('Nov 10'!$C$2:$C$485, MATCH($A51, 'Nov 10'!$B$2:$B$485,0)),"")} -> 2 | I51: {=IFERROR(INDEX('Dec 1'!$C$2:$C$542, MATCH($A51, 'Dec 1'!$B$2:$B$542,0)),"")} -> 2.95
A52: 1657 | B52: Ben Stearnes | C52: 4 | D52: 4 | E52: 4 | F52: 4 | G52: 4 | H52: 4 | I52: {=IFERROR(INDEX('Dec 1'!$C$2:$C$542, MATCH($A52, 'Dec 1'!$B$2:$B$542,0)),"")} -> 4
A53: 1658 | B53: Tag Niepomnik | C53: 4 | D53: 4 | E53: 3.79 | F53: 3.71 | G53: 3.69 | H53: 3.642 | I53: {=IFERROR(INDEX('Dec 1'!$C$2:$C$542, MATCH($A53, 'Dec 1'!$B$2:$B$542,0)),"")} -> 3.64
A54: 1659 | B54: Cole Bader | C54: 2.26 | D54: 3.668 | E54: 3.33 | F54: 3.491 | G54: 3.556 | H54: 3.623 | I54: {=IFERROR(INDEX('Dec 1'!$C$2:$C$542, MATCH($A54, 'Dec 1'!$B$2:$B$542,0)),"")} -> 3.667
A55: 1660 | B55: Charlie Poitras | C55: 3 | D55: 3.3 | E55: 3.6 | F55: 3.5 | G55: 3.44 | H55: 3.5 | I55: {=IFERROR(INDEX('Dec 1'!$C$2:$C$542, MATCH($A55, 'Dec 1'!$B$2:$B$542,0)),"")} -> 3.4
...

Sheet Grade History
A1: AE | B1: Name | C1: Spring 2023 | D1: Cumulative | I1: Name | J1: Fall 2022 | K1: Name | L1: Spring 2022 | M1: Name | N1: Fall 2021
A2: 1577 | B2: Brady Sorbin | C2: No Data | D2: Est - 3 | I2: Adam Varghese | J2: 4 | K2: Toby Tobin | L2: No data | M2: Nathan Herrera | N2: 0
A3: 1582 | B3: Toby Tobin | C3: No Data | D3: Est - 2.3 | I3: Connor McCratic | J3: 4 | K3: Jack Kay | L3: No data | M3: Kobee Brewer | N3: 0.666
A4: 1594 | B4: Thomas Hope | C4: 4 | D4: 3.951 | I4: Thomas Hope | J4: 4 | K4: Kobee Brewer | L4: No data | M4: Ethan Webster | N4: 1.468
A5: 1615 | B5: Harry Wells | C5: 4 | D5: 3.984 | I5: Harry Wells | J5: 4 | K5: Jared Ott | L5: 4 | M5: Sean Doumitt | N5: 1.534
A6: 1628 | B6: James Moeller | C6: 3.934 | D6: 3.334 | I6: Nolan Johnson | J6: 4 | K6: Trenton Sedlacek | L6: 4 | M6: AJ Fields | N6: 1.75
A7: 1613 | B7: Andrew Wellman | C7: 3.917 | D7: 3.679 | I7: Braeden Haptonstall | J7: 4 | K7: Nolan Johnson | L7: 4 | M7: Kris Anwar | N7: 1.869
A8: 1620 | B8: Trenton Sedlacek | C8: 3.917 | D8: 3.93 | I8: Danny Smyth | J8: 4 | K8: Braeden Haptonstall | L8: 4 | M8: Evan Seipold | N8: 1.998
A9: 1598 | B9: Callahan Weeks | C9: 3.856 | D9: 3.388 | I9: Charlie Gifford | J9: 3.917 | K9: Harrison Wells | L9: 3.93 | M9: Dennis Ngyuyen | N9: 2.334
A10: 1591 | B10: Nate Hollenbeck | C10: 3.835 | D10: 3.708 | I10: Michael Leiting | J10: 3.881 | K10: Tyler Day | L10: 3.832 | M10: Hunter Kinnaman | N10: 2.375
A11: 1637 | B11: Sebastian Palka | C11: 3.8 | D11: 3.733 | I11: Trenton Sedlacek | J11: 3.832 | K11: Charlie Gifford | L11: 3.823 | M11: Alex Pahadi | N11: 2.477
A12: 1639 | B12: Danny Smyth | C12: 3.762 | D12: 3.889 | I12: Nate Hollenbeck | J12: 3.769 | K12: Jeffrey Noh | L12: 3.814 | M12: James Moeller | N12: 2.536
A13: 1634 | B13: Braeden Haptonstall | C13: 3.742 | D13: 3.744 | I13: Jordan Lockert | J13: 3.76 | K13: Connor McCratic | L13: 3.8 | M13: Rishik Kancharla | N13: 2.6
A14: 1621 | B14: Nolan Johnson | C14: 3.707 | D14: 3.914 | I14: Logan McDonald | J14: 3.706 | K14: Tanner Hipnar | L14: 3.776 | M14: Jack Nicholl | N14: 2.666
A15: 1648 | B15: Sam Mueggenberg | C15: 3.667 | D15: 3.617 | I15: Sebastian Palka | J15: 3.686 | K15: Brady Ferryman | L15: 3.75 | M15: Nico Bianchette | N15: 2.734
A16: 1626 | B16: Jordan Lockert | C16: 3.625 | D16: 3.734 | I16: Connor Wieseman | J16: 3.668 | K16: AJ Fields | L16: 3.743 | M16: Anibal Grajeda | N16: 2.75
... A51: 1636 | B51: Nikolas Ostrowski | C51: 2 | D51: 1.4 | I51: Elijah Doyle | J51: 2.691 | K51: Connor Radde | L51: 2.668 | M51: Connor McCratic | N51: 3.666
I52: Colby Hehnke | J52: 2.642 | K52: Del Casteel | L52: 2.603 | M52: Max Dikker | N52: 3.667
I53: Brady Perna | J53: 2.582 | K53: Grant Crockett | L53: 2.582 | M53: Nolan Johnson | N53: 3.667
I54: Del Casteel | J54: 2.547 | K54: Dennis Nguyen | L54: 2.4 | M54: Michael Leiting | N54: 3.71
I55: AJ Fields | J55: 2.534 | K55: Nikolas Ostrowski | L55: 2.332 | M55: Logan McDonald | N55: 3.75
I56: Jack Kay | J56: 2.5 | K56: Anibal Grajeda | L56: 2 | M56: Randy Rafert | N56: 3.75
I57: Anibal Grajeda | J57: 2.5 | M57: Jeffrey Noh | N57: 3.778
I58: Jaren Hoffart | J58: 2.5 | M58: Charlie Gifford | N58: 3.812
I59: Toby Tobin | J59: 2.332 | M59: Tyler Lechner | N59: 3.822
I60: Braeden Aherns | J60: 1.667 | M60: Zach Hamilton | N60: 3.855
I61: Mac Clarke | J61: 1.572 | M61: Jared Ott | N61: 3.862
I62: Andrew Quick | J62: 0.915 | M62: Joe Kopetka | N62: 3.866
I63: Nikolas Ostrowski | J63: 0.417 | M63: Andrew Wellman | N63: 3.866
M64: Jordan Lockert | N64: 3.876
M65: Trenton Sedlacek | N65: 3.923
M66: Thomas Hope | N66: 3.955
M67: Carter Lawson | N67: 4
M68: Harrison Wells | N68: 4

Sheet FGL
A1: Fantasy Grades League Standings
A2: C | B2: Ben Morse | C2: {=IFERROR(INDEX(SIN(, MATCH($B2, Chapter,0)),""),"")} | D2: Rishik Kancharla | E2: {=IFERROR(INDEX(Seven, MATCH($D2, Chapter,0)),"")} -> 2.626 | F2: Braeden Aherns | G2: {=IFERROR(INDEX(Seven, MATCH($D2, Chapter,0)),"")} -> 2.626 | H2: Scott Lundin | I2: {=IFERROR(INDEX(Seven, MATCH($H2, Chapter,0)),"")} -> 2.665 | J2: James Moeller | K2: {=IFERROR(INDEX(Seven, MATCH($J2, Chapter,0)),"")} -> 3.845 | L2: Sean Pate | M2: {=IFERROR(INDEX(Seven, MATCH($L2, Chapter,0)),"")} -> 2.934 | N2: Harry Wells | O2: {=IFERROR(INDEX(Seven, MATCH($N2, Chapter,0)),"")} -> 4 | P2: C | R2: Spring 2022 | S2: Team Captains
A3: 1 | B3: Callahan Weeks | C3: {=IFERROR(INDEX(SIx, MATCH($B3, Chapter,0)),"")} -> 3.856 | D3: Nate Hollenbeck | E3: {=IFERROR(INDEX(Seven, MATCH($D3, Chapter,0)),"")} -> 4 | F3: Thomas Hope | G3: {=IFERROR(INDEX(Seven, MATCH($F3, Chapter,0)),"")} -> 3.5 | H3: Andrew Wellman | I3: {=IFERROR(INDEX(Seven, MATCH($H3, Chapter,0)),"")} -> 3.53 | J3: Trenton Sedlacek | K3: {=IFERROR(INDEX(Seven, MATCH($J3, Chapter,0)),"")} -> 3.668 | L3: Sebastian Palka | M3: {=IFERROR(INDEX(Seven, MATCH($L3, Chapter,0)),"")} -> 4 | N3: Danny Smyth | O3: {=IFERROR(INDEX(Seven, MATCH($N3, Chapter,0)),"")} -> 3.833 | P3: 1 | S3: x | T3: Nolan Johnson | U3: Nate Hollenbeck | V3: Callahan | W3: Elijah | X3: Ben | Y3: Brady | Z3: Hubert
A4: 2 | B4: Antonio Soto | C4: {=IFERROR(INDEX(Seven, MATCH($B4, Chapter,0)),"")} -> 3.69 | D4: Michael Leiting | E4: {=IFERROR(INDEX(Seven, MATCH($D4, Chapter,0)),"")} -> 3.856 | F4: Evan Siepold | G4: {=IFERROR(INDEX(Seven, MATCH($F4, Chapter,0)),"")} -> 2 | H4: Elijah Doyle | I4: {=IFERROR(INDEX(Seven, MATCH($H4, Chapter,0)),"")} -> 3.75 | J4: Sam Mueggenberg | K4: {=IFERROR(INDEX(Seven, MATCH($J4, Chapter,0)),"")} -> 3.75 | L4: Joe Schmit | M4: {=IFERROR(INDEX(Seven, MATCH($L4, Chapter,0)),"")} -> 2.667 | N4: Nolan Johnson | O4: {=IFERROR(INDEX(Seven, MATCH($N4, Chapter,0)),"")} -> 4 | P4: 2 | R4: Above House Avg | S4: 1 | T4: Harrison | U4: Tyler Lechner | V4: Connor McCratic | W4: Carter Lawson | X4: Charlie | Y4: Randy | Z4: Max Dikker
A5: 3 | B5: Owen Micek | C5: {=IFERROR(INDEX(Seven, MATCH($B5, Chapter,0)),"")} -> 3.083 | D5: Carson Dodd | E5: {=IFERROR(INDEX(Seven, MATCH($D5, Chapter,0)),"")} -> 3.744 | F5: Garrett Smith | G5: {=IFERROR(INDEX(Seven, MATCH($F5, Chapter,0)),"")} -> 3.308 | H5: Connor Radde | I5: {=IFERROR(INDEX(Seven, MATCH($H5, Chapter,0)),"")} -> 3 | J5: Logan McDonald | K5: {=IFERROR(INDEX(Seven, MATCH($J5, Chapter,0)),"")} -> 3.687 | L5: Cutter Riveland | M5: {=IFERROR(INDEX(Seven, MATCH($L5, Chapter,0)),"")} -> 2.645 | N5: AJ Fields | O5: {=IFERROR(INDEX(Seven, MATCH($N5, Chapter,0)),"")} -> 3.534 | P5: 3 | R5: Below House Avg | S5: 2 | T5: Joe Kopetka | U5: Zachary Hamilton | V5: Logan McDonald | W5: Jared Ott | X5: Jordan Lockert | Y5: David Frohardt | Z5: Tyler Day
A6: 4 | B6: Nick Nemec | C6: {=IFERROR(INDEX(Seven, MATCH($B6, Chapter,0)),"")} -> 2.89 | D6: Brady Perna | E6: {=IFERROR(INDEX(Seven, MATCH($D6, Chapter,0)),"")} -> 3.585 | F6: Riley Pankow | G6: {=IFERROR(INDEX(Seven, MATCH($F6, Chapter,0)),"")} -> 3.14 | H6: Nik Ostrowski | I6: {=IFERROR(INDEX(Seven, MATCH($H6, Chapter,0)),"")} -> 2 | J6: Nico Bianchette | K6: {=IFERROR(INDEX(Seven, MATCH($J6, Chapter,0)),"")} -> 3.134 | L6: JD Loera | M6: {=IFERROR(INDEX(Seven, MATCH($L6, Chapter,0)),"")} -> 2.95 | N6: Miles Budzinski | O6: {=IFERROR(INDEX(Seven, MATCH($N6, Chapter,0)),"")} -> 3.083 | P6: 4 | R6: Below 2.75 | S6: 3 | T6: Jan Gomez | U6: Jeffrey | V6: Grant Crockett | W6: Adam Varghese | X6: Michael Leiting | Y6: Andrew Wellman | Z6: Robert Killgore
A7: 5 | B7: Carlos Garcia | C7: {=IFERROR(INDEX(Seven, MATCH($B7, Chapter,0)),"")} -> 3.085 | D7: Grant Crockett | E7: {=IFERROR(INDEX(Seven, MATCH($D7, Chapter,0)),"")} -> 3.335 | F7: Spencer Sartore | G7: {=IFERROR(INDEX(Seven, MATCH($F7, Chapter,0)),"")} -> 3.365 | H7: Kris Anwar | I7: {=IFERROR(INDEX(Seven, MATCH($H7, Chapter,0)),"")} -> 3.58 | J7: Hunter Kinnaman | K7: {=IFERROR(INDEX(Seven, MATCH($J7, Chapter,0)),"")} -> 2.58 | L7: Colby Hehnke | M7: {=IFERROR(INDEX(Seven, MATCH($L7, Chapter,0)),"")} -> 2.882 | N7: Jan Gomez | O7: {=IFERROR(INDEX(Seven, MATCH($N7, Chapter,0)),"")} -> 3.066 | P7: 5 | R7: No Data | S7: 4 | T7: Connor Wieseman | U7: Chuck | V7: Rishik Kancharla | W7: Tanner Hipnar | X7: Sean Pate | Y7: Grant Casey | Z7: Brady Sorbin
A8: 6 | B8: Brady Sorbin | C8: {=IFERROR(INDEX(Seven, MATCH($B8, Chapter,0)),"")} -> 2 | D8: Mac Clarke | E8: {=IFERROR(INDEX(Seven, MATCH($D8, Chapter,0)),"")} -> 3.258 | G8: {=IFERROR(INDEX(Seven, MATCH($F8, Chapter,0)),"")} | I8: {=IFERROR(INDEX(Seven, MATCH($H8, Chapter,0)),"")} | J8: William Miller | K8: {=IFERROR(INDEX(Seven, MATCH($J8, Chapter,0)),"")} -> 3.471 | L8: Maverick Kellar | M8: {=IFERROR(INDEX(Seven, MATCH($L8, Chapter,0)),"")} -> 3.138 | N8: Hayden Smith | O8: {=IFERROR(INDEX(Seven, MATCH($N8, Chapter,0)),"")} -> 2.488 | P8: 6 | R8: House Avg = 3.331 | S8: 5 | T8: Mason Mattes | U8: Tommy | V8: Scott Lundin | W8: Gage | X8: James Moeller | Y8: Antonio Soto | Z8: Del
A9: 7 | B9: Zach Moeller | C9: {=IFERROR(INDEX(Seven, MATCH($B9, Chapter,0)),"")} -> 3.132 | D9: Tag Niepomnik | E9: {=IFERROR(INDEX(Seven, MATCH($D9, Chapter,0)),"")} -> 3.64 | F9: Tucker May | G9: {=IFERROR(INDEX(Seven, MATCH($F9, Chapter,0)),"")} -> 3.333 | H9: Ved Patel | I9: {=IFERROR(INDEX(Seven, MATCH($H9, Chapter,0)),"")} -> 3.765 | K9: {=IFERROR(INDEX(SIx, MATCH($J9, Chapter,0)),"")} | L9: Jared Dodson | M9: {=IFERROR(INDEX(Seven, MATCH($L9, Chapter,0)),"")} -> 3.65 | N9: Ben Stearnes | O9: {=IFERROR(INDEX(Seven, MATCH($N9, Chapter,0)),"")} -> 4 | P9: 7 | S9: 6 | T9: Connor Radde | U9: Kris | V9: Ethan Halliday | W9: Owen Micek | X9: Anibal | Y9: Joel | Z9: Hunter fitton
A10: 8 | C10: {=IFERROR(INDEX(SIx, MATCH($B10, Chapter,0)),"")} | D10: Cole Bader | E10: {=IFERROR(INDEX(Seven, MATCH($D10, Chapter,0)),"")} -> 3.667 | F10: Charlie Poitras | G10: {=IFERROR(INDEX(Seven, MATCH($F10, Chapter,0)),"")} -> 3.4 | H10: Luke Peterson | I10: {=IFERROR(INDEX(Seven, MATCH($H10, Chapter,0)),"")} -> 2.715 | K10: {=IFERROR(INDEX(SIx, MATCH($J10, Chapter,0)),"")} | M10: {=IFERROR(INDEX(SIx, MATCH($L10, Chapter,0)),"")} | N10: Max Lowrance | O10: {=IFERROR(INDEX(Seven, MATCH($N10, Chapter,0)),"")} -> 3.195 | P10: 8 | S10: 7 | T10: Drew Olsen | U10: Alex Pahadi | V10: Jack Kay | W10: Carson Dodd | X10: Dennis Nguyen | Y10: Andrew Quick | Z10: matthew rowland
A11: 9 | C11: {=IFERROR(INDEX(Four, MATCH($B11, Chapter,0)),"")} | E11: {=IFERROR(INDEX(Three, MATCH($D11, Chapter,0)),"")} | F11: Aiden Estrada | G11: {=IFERROR(INDEX(Seven, MATCH($F11, Chapter,0)),"")} -> 2 | I11: {=IFERROR(INDEX(Five, MATCH($H11, Chapter,0)),"")} | K11: {=IFERROR(INDEX(Five, MATCH($J11, Chapter,0)),"")} | M11: {=IFERROR(INDEX(Three, MATCH($L11, Chapter,0)),"")} | O11: {=IFERROR(INDEX(SIx, MATCH($N11, Chapter,0)),"")} | P11: 9 | S11: 8 | T11: Toby | U11: Sean Doumitt | V11: Kobee | W11: Jack nicholl | X11: AJ Fields | Y11: Nico | Z11: Braden
A12: 10 | C12: {=IFERROR(INDEX(One, MATCH($B12, Chapter,0)),"")} | E12: {=IFERROR(INDEX(One, MATCH($D12, Chapter,0)),"")} | G12: {=IFERROR(INDEX(One, MATCH($F12, Chapter,0)),"")} | I12: {=IFERROR(INDEX(One, MATCH($H12, Chapter,0)),"")} | K12: {=IFERROR(INDEX(One, MATCH($J12, Chapter,0)),"")} | M12: {=IFERROR(INDEX(One, MATCH($L12, Chapter,0)),"")} | O12: {=IFERROR(INDEX(One, MATCH($N12, Chapter,0)),"")} | P12: 10 | S12: 9 | T12: Braeden Haptonstall | U12: Jaren Hoffart | V12: Braeden Aherns | W12: Evan Siepold | X12: Sebastian Palka | Y12: Nikolas Ostrowski
B13: Avg | C13: =AVERAGE(C2:C12) -> 3.1051429 | D13: Avg | E13: =AVERAGE(E2:E12) -> 3.5234444 | F13: Avg | G13: =AVERAGE(G2:G12) -> 2.9635556 | H13: Avg | I13: =AVERAGE(I2:I12) -> 3.125625 | J13: Avg | K13: =AVERAGE(K2:K12) -> 3.4478571 | L13: Avg | M13: =AVERAGE(M2:M12) -> 3.10825 | N13: Avg | O13: =AVERAGE(O2:O12) -> 3.4665556
B14: Rank | C14: =RANK(C13,$C$13:$O$13,0) -> 6 | D14: Rank | E14: =RANK(E13,$C$13:$O$13,0) -> 1 | F14: Rank | G14: =RANK(G13,$C$13:$O$13,0) -> 7 | H14: Rank | I14: =RANK(I13,$C$13:$O$13,0) -> 4 | J14: Rank | K14: =RANK(K13,$C$13:$O$13,0) -> 3 | L14: Rank | M14: =RANK(M13,$C$13:$O$13,0) -> 5 | N14: Rank | O14: =RANK(O13,$C$13:$O$13,0) -> 2 | R14: Autumn 2022
S15: Fantasy Grades League Standings
R16: Above House Avg | S16: C | T16: Nolan Johnson | U16: Braeden Haptonstall | V16: Elijah Doyle | W16: Ben Morse | X16: Callahan Weeks | Y16: Brady Ferryman | Z16: Nate Hollenbeck
R17: Below House Avg | S17: 1 | T17: Harry Wells | U17: Jared Ott | V17: Charlie Gifford | W17: Andrew Wellman | X17: Jeffrey Noh | Y17: Connor McCratic | Z17: Zach Hamilton
R18: Below 2.75 | S18: 2 | T18: Tommy Lemon | U18: Logan McDonald | V18: Max Dikker | W18: Sebastian Palka | X18: Adam Varghese | Y18: Jordan Lockert | Z18: Tyler Day
R19: No Data | S19: 3 | T19: Michael Leiting | U19: Rishik Kancharla | V19: Sean Pate | W19: Connor Wieseman | X19: AJ Fields | Y19: Antonio Soto | Z19: Chuck Schultz
R20: House Avg = 3.169 | S20: 4 | T20: Jan Gomez | U20: Braeden Aherns | V20: Carson Dodd | W20: Scott Lundin | X20: Ethan Halliday | Y20: Thomas Hope | Z20: Nico Bianchette
S21: 5 | T21: Jaren Hoffart | U21: Owen Micek | V21: Dennis Nguyen | W21: Connor Radde | X21: James Moeller | Y21: Hunter Fitton | Z21: Hunter Kinnaman
S22: 6 | T22: Del Casteel | U22: Kris Anwar | V22: Braden Harris | W22: Andrew Quick | X22: Brady Sorbin | Y22: Grant Crockett | Z22: Evan Siepold
S23: 7 | T23: Jack Kay | U23: Toby Tobin | W23: Nikolas Ostrowski | Y23: Anibal Grajeda | Z23: Gage Crowell
S24: 8 | T24: Riley Pankow | U24: Miles Budzinski | V24: Mac Clarke | W24: Colton Billings | X24: Jacob Hornbeck | Y24: Garrett Smith | Z24: Danny Smyth
S25: 9 | V25: Cutter Riveland | X25: Sam Mueggenberg | Y25: Brady Perna | Z25: Hayden Smith
S26: 10 | Y26: William Miller

Sheet Sep 1
A1: Timestamp | B1: AE | C1: GPA | D1: Canvas Screenshot(s) | E1: Questions/Comments
A2: 45165.824 | B2: 1634 | C2: 4 | D2: https://drive.google.com/open?id=11cta5LRgQtovJBaJ4NY2V1DwCJPbmQAd | E2: plz wrk
A3: 45165.838 | B3: 1613 | C3: 4 | D3: https://drive.google.com/open?id=1N6QioBCzhRgicgFuinywS3-dwCT1NiGs | E3: Balls
A4: 45166.319 | B4: 1621 | C4: 4 | D4: https://drive.google.com/open?id=1bTYUwTsTYfkLlL2ga8Q1T9NeB6oijPRL
A5: 45166.354 | B5: 1647 | C5: 4 | D5: https://drive.google.com/open?id=1BX5LRy00MivKvNCrwSbwzLyiE0tLHDWf
A6: 45166.474 | B6: 3 | C6: 3 | D6: https://drive.google.com/open?id=1hNJU-0Fg56XdBvkTC9dkzDiQ5ECBH6mg, https://drive.google.com/open?id=1OpqBCnqt0Kg-owKWG_qIO-AM4RsgzRpA
A7: 45166.506 | B7: 1645 | C7: 4 | D7: https://drive.google.com/open?id=1Qz9NxzjB4Qgxys98BjumB2aNu-TJvAo_ | E7: Hiiiiiiiii Brrraaaeeedeeeeennnn
A8: 45166.598 | B8: 1597 | C8: 4 | D8: https://drive.google.com/open?id=1VMdDWyjHyQViQIlX81M8V3g6gf3eNwE7 | E8: I have no grades in yet so I put a 4
A9: 45166.645 | B9: 1594 | C9: 4 | D9: https://drive.google.com/open?id=1cpZv6wSAjT_Q1R1HmcJdKSyoocIPfJV9 | E9: No grades in
A10: 45166.712 | B10: 1564 | C10: 4 | D10: https://drive.google.com/open?id=1h3v47SDCawlykcboFuOCZzHzTisbKAM0, https://drive.google.com/open?id=1puU7uZNYYafQbH38j1qP9uucYwSdQrKQ
A11: 45166.75 | B11: 1618 | C11: 4 | D11: https://drive.google.com/open?id=1IOVBxFDBtzd7D-KhKz9J1wuyJSxL049g
A12: 45166.854 | B12: 1631 | C12: 4 | D12: https://drive.google.com/open?id=1574lo42U6L4cTAd6h2GzCPSMTDW5hQ-4
A13: 45166.92 | B13: 1641 | C13: 3.222 | D13: https://drive.google.com/open?id=1TLrbc0iRDbT-EkZYKKVxJAXsw0hDn8vv | E13: ADPR 283 zero from ungraded syllabus quiz. Real grade is 100
A14: 45167.522 | B14: 1648 | C14: 4 | D14: https://drive.google.com/open?id=1eHqBNYe7POyr62MH1vm3ksmL-_gtRe1j
A15: 45168.651 | B15: 1644 | C15: 4 | D15: https://drive.google.com/open?id=1pXxc6DBJJIdrWgHdSbaVlFouoaeXu10I | E15: Balls
A16: 45169.498 | B16: 1595 | C16: 4 | D16: https://drive.google.com/open?id=11LgfsUY8sMOQX_DmhUVUHylU6ekGLx8i, https://drive.google.com/open?id=1VS5QLq_m23-cUVt34g4NzMUboYjaXJKn
A17: 45169.499 | B17: 1596 | C17: 4 | D17: https://drive.google.com/open?id=16Ia50xYIMSLwLd2jeZElcwnK-72bVqhy
A18: 45169.501 | B18: 1653 | C18: 2.9 | D18: https://drive.google.com/open?id=1rHW13flVQteVE0X_8k6TX91M5sGhR-TX, https://drive.google.com/open?id=1qhZoEubAyurQn01VAIR36WSVOeDmMiEy, https://drive.google.com/open?id=10PIjUc4-codkh94bUq0tKahdrQC90mRZ
A19: 45169.504 | B19: 1650 | C19: 4 | D19: https://drive.google.com/open?id=1U6TaHhAZR1pJBiLGqt0y76w-EdJxdv6k
A20: 45169.505 | B20: 1625 | C20: 4 | D20: https://drive.google.com/open?id=14wCYborAjmr4cQs-FcQnBae8MCZ5y4Xw
A21: 45169.525 | B21: 1627 | C21: 4 | D21: https://drive.google.com/open?id=1-74S43oFu3wN1_HhlkzWQ7dxsfBrho9E
A22: 45169.525 | B22: 1639 | C22: 4 | D22: https://drive.google.com/open?id=1wo9x7SsAzNXzNu8Ne_JDQXYZBenHkfvf, https://drive.google.com/open?id=1VXnP-lsUhTPQ_RQuzafoi2PqOH219Azq
A23: 45169.529 | B23: 1598 | C23: 4 | D23: https://drive.google.com/open?id=1dOu-XzZmLBMZ8kGbSPoKTzt0syxDGVPC
A24: 45169.534 | B24: 1637 | C24: 4 | D24: https://drive.google.com/open?id=1aZP0u9C0A-GTnFKiiS7WaRY70rdhMKf9 | E24: Skeet skeet yet yeet
A25: 45169.544 | B25: 1640 | C25: 4 | D25: https://drive.google.com/open?id=1C73hLUj8XGfKzhGdOukB2DOQ-ZP-x0SN, https://drive.google.com/open?id=10raJC_qypT43pdDea7k53tFFNWm6_iCt | E25: 4.0 bitch
A26: 45169.56 | B26: 1620 | C26: 4 | D26: https://drive.google.com/open?id=1-gM6EAWpCksxoiwwdADS2f4MVyBt8iNN | E26: Grade forms make me happy :):) keep being awesome!
A27: 45169.602 | B27: 1654 | C27: 4 | D27: https://drive.google.com/open?id=1IQ27WMLKUppNAhQ6XthkTTsFVbs3hwqs
A28: 45169.817 | B28: 13 | C28: 4 | D28: https://drive.google.com/open?id=1J0iMVubKnv-ebjWWR6v1EU1aV0ImvcdI | E28: i’m him
A29: 45169.823 | B29: 1 | C29: 2.8 | D29: https://drive.google.com/open?id=1ps7KZccEvYD5p3TzKUeaHbOtWIjBy1ef, https://drive.google.com/open?id=1cwgNfYyy4iD_8pTzBz9lCsw-GeKwWHdf
A30: 45170.3 | B30: 11 | C30: 3.917 | D30: https://drive.google.com/open?id=15owxuVdbEh9xOub-sIlBbjiFwAsfYMtN, https://drive.google.com/open?id=1tsDo4so4mDEwDCAHNODk8QUGo1i1kYG6 | E30: I have 2 zero credit classes. I didn’t add those into the calculations because they have no credits. Lmk if that wrong.
A31: 45170.371 | B31: 1599 | C31: 3.4 | D31: https://drive.google.com/open?id=10BFb7y9gPrQOvm9PE0qn9eE30pIZbQS7, https://drive.google.com/open?id=1xJScv6lp5zZK9CwdNs4NSlCnYT3BUzoa | E31: I got a 5/8 on my SCMA quiz that’s why it says 62
A32: 45170.371 | B32: 1635 | C32: 4 | D32: https://drive.google.com/open?id=1zWhb4sWf8oR9FEnTxP_zBB4K3dCa0Y9j
A33: 45170.386 | B33: 1623 | C33: 4 | D33: https://drive.google.com/open?id=1oBpV7BIKF2piSg4LCXPOwUU2ZQE_0gni
A34: 45170.401 | B34: 6 | C34: 3.4 | D34: https://drive.google.com/open?id=1somufITS4KX7BFEY26zNqs-FstI51bLn
A35: 45170.403 | B35: 1652 | C35: 3.25 | D35: https://drive.google.com/open?id=18ileF0233t-64J979_zHH3FKVPkkqf_K, https://drive.google.com/open?id=1vbktVi6g9GLzxQ94D-_8sxUMCRoAarUx
A36: 45170.447 | B36: 1632 | C36: 3.3 | D36: https://drive.google.com/open?id=1eyksYdMh06N9GStndX99CbEDVyF78_5Y, https://drive.google.com/open?id=1r2zlNWqsCC5PutQz51pDhLqzWeXbkopT
A37: 45170.45 | B37: 2 | C37: 4 | D37: https://drive.google.com/open?id=1bxMJdeTg_RwNjuaeRMs7bQG4FSgDWNHb
A38: 45170.462 | B38: 8 | C38: 4 | D38: https://drive.google.com/open?id=1bvbWtPRJGvtwpEIpFor5jrqutCLDexnU | E38: None
A39: 45170.491 | B39: 1630 | C39: 3.833 | D39: https://drive.google.com/open?id=1Y19eSwzjrHZDTauQL6Ahzw3GcVgN4G44
A40: 45170.501 | B40: 1643 | C40: 3.9 | D40: https://drive.google.com/open?id=13qaODTytVTx0ItZ67RaoUl3ux0xhPrIV
...

Sheet Sep 15
A1: Timestamp | B1: AE | C1: GPA | D1: Canvas Screenshots | E1: GPA Calculator Screeshot | F1: Questions/Comments
A2: 45180.471 | B2: 1613 | C2: 4 | D2: https://drive.google.com/open?id=1ZBj1q2Ck8Num8Z7lvFlWhSnsWvnQ4Pfh | E2: https://drive.google.com/open?id=1Iw9TUfl-0SiCYXlXP-y4e06FAM3llzvv
A3: 45180.473 | B3: 1637 | C3: 4 | D3: https://drive.google.com/open?id=1y_Q-FhvRvcYT1iP-mahm-6F8XFUC9YXd | E3: https://drive.google.com/open?id=1meWlRnRqeh_GBH0GIrteFkxXaHEqAuJr
A4: 45180.473 | B4: 1645 | C4: 4 | D4: https://drive.google.com/open?id=1waHCEKy6dsT0_xgaVcpO1FipozzHgvP0 | E4: https://drive.google.com/open?id=1D7lZLWXIk5JKBieABEzfiuNoK_NRj9fR | F4: Wasn’t sure if I had to add the grade calculator ss since I still have all As, I knew it was 4.0
A5: 45180.476 | B5: 1597 | C5: 2.23 | D5: https://drive.google.com/open?id=1LlB7AWT2wO_J_D4LfaRSvevXyjdo5p9j | E5: https://drive.google.com/open?id=1RMvPFsn6AQ2If899OWpej4mQIReUD_No | F5: I’ve only had a 3 question quiz in my 367 class I’ll get it up
A6: 45180.496 | B6: 11 | C6: 3.9 | D6: https://drive.google.com/open?id=1XIGI9oOyiKVbDPDD4GdCcFS9uXi2fFcY, https://drive.google.com/open?id=1Ff9WHL2rdXPUSUArBPOoBWHR9utIwiSl | E6: https://drive.google.com/open?id=1flS0dlmMSk593ayF3bzWMXaum4SXPbiN, https://drive.google.com/open?id=1hPrHiVYGZd3VanlUsG7EgiHwJ-GZ_iYy
A7: 45180.498 | B7: 1634 | C7: 4 | D7: https://drive.google.com/open?id=164l8OrzzuXEa8gY6HAWFIV_vITF1BZR3 | E7: https://drive.google.com/open?id=1yf60gpCjw3172BRROtuUdoNIwIEDmoFb
A8: 45180.572 | B8: 13 | C8: 4 | D8: https://drive.google.com/open?id=1dMR2XnXaXUR3lDISmXoUsnw1JdKM3UOP | E8: https://drive.google.com/open?id=1Rx-m89Tnd5g2uBCH_5cwwUPreAlb2pYL
A9: 45180.605 | B9: 1653 | C9: 4 | D9: https://drive.google.com/open?id=1Ch6CtzLil09fI7dHRdIyZSuQeMAY-xTF, https://drive.google.com/open?id=1V6YNA-okexB1z542fxexswdAKtqUgdgO, https://drive.google.com/open?id=1FzYDtsNIzIsexmuwH9JxIHwSjY_1TKGE, https://drive.google.com/open?id=1f12dtMoxz50LtUbpl9w6PIoefBWrQZnh | E9: https://drive.google.com/open?id=12Ae068zbE2LIvy-jz7TpBj88gvW0uCYX
A10: 45180.612 | B10: 3 | C10: 3.3 | D10: https://drive.google.com/open?id=1Z3vOQXa17M8I0M7RkO_53d2b1lm7wySI, https://drive.google.com/open?id=1tb1rX17LEcQ5qTD7pw-eGqALG26bC5CG | E10: https://drive.google.com/open?id=18h32CvHDrtKAkthjGR-G0oW42cJVCjjD
A11: 45180.647 | B11: 1620 | C11: 4 | D11: https://drive.google.com/open?id=1clUdkvRy_Flf-51li0QjqvJd4hHe3lzs | E11: https://drive.google.com/open?id=1qYvCFjfUfoGG8jnNyvEqIaQAUCurgb7C | F11: GIS has had just one assignment. EDLC has weird grading thing where it doesn’t show but I have 100% right now
A12: 45180.676 | B12: 1640 | C12: 4 | D12: https://drive.google.com/open?id=100Y9Fp5xVDjGu6v6Wt2gxvEnRuKkxko4, https://drive.google.com/open?id=1JO44RuJ41hVU7O098RItYPLqUCSLF1H_ | E12: https://drive.google.com/open?id=1ti9SU_VMzcx2VRJhI6Wk_h42Zok_1Dhh
A13: 45180.677 | B13: 1644 | C13: 4 | D13: https://drive.google.com/open?id=1am47T4bWZ_RevdI6Bpkxj1OGk-I0BHUu | E13: https://drive.google.com/open?id=1Zy-M5msJ40kcOFP2hdv1CZAPH082y5Ws | F13: Why are my balls always itchy
A14: 45180.712 | B14: 1623 | C14: 4 | D14: https://drive.google.com/open?id=1MnO3a_AWktAIkLERwpve3MWA9vsMlXN_ | E14: https://drive.google.com/open?id=1zc4CT7m0bHGP1JM68Lo1Lr2Bv8h-10eg | F14: Too lazy to do gpa calc I have all 100s its a 4 jit
A15: 45180.739 | B15: 1618 | C15: 3.751 | D15: https://drive.google.com/open?id=1QSGfR2UkykyMKMcaEA8-hdIXfKp-NLCM | E15: https://drive.google.com/open?id=1t2UCgX63lipucCNkr8Y6HcxegKdzwjAO
A16: 45181.262 | B16: 1594 | C16: 4 | D16: https://drive.google.com/open?id=1ZYSAgV7HUwdY7FqvnTgXjtjn3DmKLvAn | E16: https://drive.google.com/open?id=1-hL05o0ACDrWy5NPx2Z5t96cRNjPp-Pq
A17: 45181.519 | B17: 2 | C17: 4 | D17: https://drive.google.com/open?id=1z_AnftL-akGuRRgEZGgjqRyjsHGs8JBE | E17: https://drive.google.com/open?id=1lGosSAYrimEnHSogzLGefaSYEhyKOX_1 | F17: N/A
A18: 45181.525 | B18: 1597 | C18: 2.23 | D18: https://drive.google.com/open?id=1MUdNE6r0jGx3uhecnrO23hWEDedtH8Um | E18: https://drive.google.com/open?id=1Ol5gqzZOGd32szy9U6SaKjMVwKzdrSra
A19: 45181.63 | B19: 1639 | C19: 3.934 | D19: https://drive.google.com/open?id=1x5oSb61v684MXTRUBvDzYY3V19CFY7Pj, https://drive.google.com/open?id=1FFV5KwvI3q3i_E87rQyMRNEODNSQLopm | E19: https://drive.google.com/open?id=1lWlL7OkNQ39sprkD4V5b0Gyrm-mOVDi9, https://drive.google.com/open?id=18ZJhsZhWA8lcMjxMCY4TLsbEsZFcvMHn | F19: Free R. Kelly
A20: 45181.882 | B20: 1596 | C20: 4 | D20: https://drive.google.com/open?id=1J6DqjBGJzNGzdJYaCUC15C6uLqIMZlPX | E20: https://drive.google.com/open?id=1R4EqLAuz95bygsQOcimCZLQCMcVbcHjY | F20: I ain’t sendin all dat
A21: 45181.895 | B21: 1654 | C21: 4 | D21: https://drive.google.com/open?id=1TH7GJ-WiXTiPAkxzSlDvBsh_yxhS9XYg | E21: https://drive.google.com/open?id=150EAdVVlemSqcylzmRobgHPVxrcgkK7F
A22: 45182.313 | B22: 1621 | C22: 4 | D22: https://drive.google.com/open?id=14VAuiJKcefZ_LPO6sFCCA1-dmWfcFmtj | E22: https://drive.google.com/open?id=1ePhkZKV1YTZiKZ42v7QluRn7ReR5oZVO
A23: 45182.449 | B23: 1564 | C23: 3.85 | D23: https://drive.google.com/open?id=1lB-B6J2xGEuzfcya6t8lfwBQKnh3X2Sk | E23: https://drive.google.com/open?id=1uPMuKJ0Bcfe7ex1hlaHl5mo4GOVI1nrQ
A24: 45182.471 | B24: 1643 | C24: 3.85 | D24: https://drive.google.com/open?id=1R1pBanhb5cY4s4jv6YcUYzKufPv0AvVm | E24: https://drive.google.com/open?id=1C-5HuTGA7GrOiQ_EUziJUCfut5SGDpKT
A25: 45182.631 | B25: 1625 | C25: 3.89 | D25: https://drive.google.com/open?id=1Q-O-vTHpkiJ4OAE_92K6BDc5tbqdDAtp | E25: https://drive.google.com/open?id=1ZytF_go7p8KDu9Vlkynh09cH-pPWegsp
A26: 45183.437 | B26: 1642 | C26: 4 | D26: https://drive.google.com/open?id=1RrBOAOrLxtOR6wrV-1ClBLxZLqyclkl9 | E26: https://drive.google.com/open?id=1Wd4c2tteiDqKAxnOZONqfja133iW8vki
A27: 45183.508 | B27: 1595 | C27: 4 | D27: https://drive.google.com/open?id=16E_6MZ8r5A7uWs1ukOxBRF3cBmVRXJBN, https://drive.google.com/open?id=1jM3tE26QBhVbe6LTHeB2EGAU_AgkXCyd | E27: https://drive.google.com/open?id=1dd7riHZZ8fN4QvstVkKFVB7YygRr0srK
A28: 45183.521 | B28: 17 | C28: 3.538 | D28: https://drive.google.com/open?id=15edWldWIvl-rppQQZ08gZtWVcMDzqvvV, https://drive.google.com/open?id=1Q00smqh9XjPBOKJOovLQQci9WAMOxGy0, https://drive.google.com/open?id=1qUoO-b7YPheu5B1Q99BGVnaa94Xu4Hpk | E28: https://drive.google.com/open?id=1Q_wtmye3YRUBYfVngMCUU1sCZU4CvPCJ | F28: None
A29: 45183.985 | B29: 1608 | C29: 3.58 | D29: https://drive.google.com/open?id=1McwMk4F2im5NxOeSnZ6AbwXUFfBLfKOR | E29: https://drive.google.com/open?id=1H7niUCFu5rSWPNwypizINmZG5FyFxXHz
A30: 45184.32 | B30: 1650 | C30: 3.58 | D30: https://drive.google.com/open?id=1aZF07_Aq8hgKJduY6lqNoBqnBVbql4BS | E30: https://drive.google.com/open?id=15Cbst0f-QvDG5iTzBOMZQS4O5acoQlYL
A31: 45184.388 | B31: 1635 | C31: 4 | D31: https://drive.google.com/open?id=1infA-HrDdHGI1qjBrQQov8oWnt1uuhFY | E31: https://drive.google.com/open?id=1LOR7QzaOmM0wFeKGl52i9jdJ1AET3171
A32: 45184.396 | B32: 1599 | C32: 3.8 | D32: https://drive.google.com/open?id=1MKvMSUany1YQnQ5snA838q9AnTbXKJE3, https://drive.google.com/open?id=1G_1ykf3NxPwQY8bVX2VjSEP1k2b7oFz9 | E32: https://drive.google.com/open?id=1_dZc3jPIKwYSv-wNdcDWO9MYhCAyLtk3
A33: 45184.431 | B33: 1626 | C33: 3.667 | D33: https://drive.google.com/open?id=15OaK6IlgKW-7GkPSIYdzbsiSiu7pa2jY | E33: https://drive.google.com/open?id=1MtPnWxhEBAcIExyhIuTOMPsZJVmVKNQI
A34: 45184.449 | B34: 1630 | C34: 3.866 | D34: https://drive.google.com/open?id=1GlUEQU8qkA4H1GPj7DdTN64fZF8kXn7H | E34: https://drive.google.com/open?id=1pFVVs1YM_8ZV-snU_kEOx8FV95Up3TBi
A35: 45184.451 | B35: 6 | C35: 3.377 | D35: https://drive.google.com/open?id=1NWQt9nhzIlUA1E4lIT7H2nFeV86uw0dJ | E35: https://drive.google.com/open?id=1s50-C69uHOze64rU-h19RmWAtUlpkiai
A36: 45184.479 | B36: 1652 | C36: 3.375 | D36: https://drive.google.com/open?id=1u2D00c580QDJrWLcwGU4_sNYnizF4RIe, https://drive.google.com/open?id=1q4fXIJGLaz5yZY24HDrV3UlqkMT3dDSu | E36: https://drive.google.com/open?id=1XGEvKrJuFWaL9lbbUaHxYBlr-pSCi00g
A37: 45184.493 | B37: 1627 | C37: 3.65 | D37: https://drive.google.com/open?id=109mNk2HssC6nGzy2kun33lk7xELdlBwE | E37: https://drive.google.com/open?id=1Z4h3Mm4c0Gl7dsXKpwpiy48KC9ZwT-lz
A38: 45184.497 | B38: 1655 | C38: 3.083 | D38: https://drive.google.com/open?id=1_voqD6Ui4HXCm15MK04uVSif_Hzs95WR | E38: https://drive.google.com/open?id=1V8oKtz56e6XeHrQvVESxANzgczs--XUj | F38: Same extra credit quiz thing for the 77.5
A39: 45184.521 | B39: 14 | C39: 3.89 | D39: https://drive.google.com/open?id=1l9kmDHPpOFlWiJCmW1knHuQMBbtY8bQz, https://drive.google.com/open?id=1iXcGjFUrRhIW1ETdqH-elBDYx0AhTw0_, https://drive.google.com/open?id=1_pG2awkxIuhEfWPsUPUtiYb8UW1zcl5U, https://drive.google.com/open?id=1qcHtV80QlhO8Bm6LQN4F7cEf12-BN2Pb, https://drive.google.com/open?id=1QP-pgxsrUtQuLK6ZrZjFzz2o1U3el53A | E39: https://drive.google.com/open?id=1mmyTcVY3PPWQaYQCaj7XmN1rcEDT7DWH
A40: 45184.566 | B40: 16 | C40: 3.97 | D40: https://drive.google.com/open?id=1W4ZllRSTknUbvdaMXE_mSsw9LhbWeZvs | E40: https://drive.google.com/open?id=1fiyxwWAiWMtpuDd1EgP3YSFSWXFq1as_ | F40: None
...

Sheet Sep 29
A1: Timestamp | B1: AE | C1: GPA | D1: Canvas Screenshot | E1: GPA Calculator Screenshot | F1: Questions/Comments
A3: 45194.651 | B3: 1613 | C3: 3.31 | D3: https://drive.google.com/open?id=1ZuUDcOfFifIb5cINIF6OoUJp8UtGGyjy | E3: https://drive.google.com/open?id=1bpz587jTKlsPKNuMfWup1lFjS5aYEFfy
A4: 45194.655 | B4: 1623 | C4: 4 | D4: https://drive.google.com/open?id=1DBNknZKuEaFpQcck5sPfd2zwq__IoAlP | E4: https://drive.google.com/open?id=1Zkqus3SbKSyKs2NJCVx6R8s0xC8SPiEz
A5: 45194.655 | B5: 1634 | C5: 4 | D5: https://drive.google.com/open?id=11aArWs6NMgMrqp2He3sgNNmTDCSDOCJu | E5: https://drive.google.com/open?id=16iLOMi8QFAvuxa0Lyt0rmef9Xgi9043T | F5: Plz
A6: 45194.658 | B6: 1644 | C6: 3.6 | D6: https://drive.google.com/open?id=1mwXFSq3lwtm_KGmgYoYt9iazUE-7aGxC | E6: https://drive.google.com/open?id=1QWOdQ7p-Jw9XxaHV7yCtuWVbXfVi_uTg | F6: I watch you sleep
A7: 45194.658 | B7: 1620 | C7: 4 | D7: https://drive.google.com/open?id=1BQ_ReE-HWWwj-_cp4Vn5Zkoqp7CkLdRn | E7: https://drive.google.com/open?id=1KyloG1ANJUG-eMrODpUWRvsYahhB59ly | F7: Green is tutoring classes. GIS class is pretty much completion based. EDLC grade will never show FYI but first exam this week. First finance exam this week. Feeling good about them
A8: 45194.661 | B8: 1637 | C8: 3.6 | D8: https://drive.google.com/open?id=1P3L3NdS6w6h5gG-lbOEFieCWP40JqDDg | E8: https://drive.google.com/open?id=1LeL5ittcsQ9EtUoQPlI-vw_fwkKmv6pH | F8: This semester might be rough ngl
A9: 45194.662 | B9: 1618 | C9: 3.563 | D9: https://drive.google.com/open?id=14-ur036n4qXzM0e4ShaWYQ2Jw4rajwVK | E9: https://drive.google.com/open?id=1jjHKvB-uhouvPV9VrZbJUV8vUelyPvhA
A10: 45194.668 | B10: 1577 | C10: 4 | D10: https://drive.google.com/open?id=1hu8O0Rp9Mp2nBW8dd6wGrWK3BQqRLpZu | E10: https://drive.google.com/open?id=1fWyg2TccmEOXgahwSFE-fxLWdhCtt9VZ
A11: 45194.67 | B11: 1653 | C11: 3.91 | D11: https://drive.google.com/open?id=1MVs4r6Tume89QImmW9viGruIMQOzKH3s, https://drive.google.com/open?id=14pZwDPMTPVLGgVnDEBVKt-Evjx-S4G8M, https://drive.google.com/open?id=1OsbIfmI8jZqrFmumvBZ1CTlMzXYXLGV8, https://drive.google.com/open?id=1oTX9NxYAA8kuvw0-dOFCR4xroN21H5pW | E11: https://drive.google.com/open?id=1ABpnKtNKpoWWw-hZ0X6zwdIccO2ko0Tc
A12: 45194.842 | B12: 1597 | C12: 2.6 | D12: https://drive.google.com/open?id=1a7x0SBRqIkys_MUgdTofpTqpreu4wbzy | E12: https://drive.google.com/open?id=1YNRV9soRn5lOzlCtymGifIG050xV-emK
A13: 45195.373 | B13: 3 | C13: 3.6 | D13: https://drive.google.com/open?id=1Jyfx-3vsV6cgDjZ4pRhyogBe9qc_MPCI, https://drive.google.com/open?id=1j33grHwlCOrdOvErbVRmd3WKNFtEcHnQ | E13: https://drive.google.com/open?id=1VJgVYa2g8ViUzyF_F23l6kaYPHEOTSrd
A14: 45195.519 | B14: 1618 | C14: 3.625 | D14: https://drive.google.com/open?id=1JoSXsx3VRFpVZ45bkYaNe8ZW6b9gICVY | E14: https://drive.google.com/open?id=15Jm6JadGnUUEzeeVrNZMp2EriVPGHarz | F14: Ignore my first submission, my gpa went up since yesterday lol
A15: 45195.902 | B15: 1639 | C15: 4 | D15: https://drive.google.com/open?id=18aIG7NykwokPDF8RA3FrF3Y9HfJUGMZT, https://drive.google.com/open?id=1PTzRgQ6uDKzZV4KrJpR6jryzJ8xS-ok7 | E15: https://drive.google.com/open?id=1MPkd3C5mC_ubV0Jpn1jHbhN-0Xa4Z0A7
A16: 45196.294 | B16: 1591 | C16: 4 | D16: https://drive.google.com/open?id=1Yd6y5E7ypTwO_BGhfqLQ22G0PQBfOSZb | E16: https://drive.google.com/open?id=1SCz8RcKeZqnBPneSWe_KOoIEtcrwotSY | F16: I’m over 100% in the jazz class with extra credit if you need proof lmk
A17: 45196.383 | B17: 1625 | C17: 3.668 | D17: https://drive.google.com/open?id=1-RyYFhMUj0IbV6L5x_yKrk151GYTp_8n | E17: https://drive.google.com/open?id=11F_FVo8J0kZFwxB8jSIXYYvadqq_gSiq
A18: 45196.388 | B18: 13 | C18: 3.79 | D18: https://drive.google.com/open?id=1dzltaPBeod_BGFHPgjea3lJR4NiMJhe_ | E18: https://drive.google.com/open?id=1oYekO25UiwynM9ZkhzcysIC7OfC0QNdW
A19: 45196.4 | B19: 1640 | C19: 3.693 | D19: https://drive.google.com/open?id=1Gw1vyhx10J0kxD8L5URQr3UU2xD5e4Kt, https://drive.google.com/open?id=1PGKJO1YjeNPtc86FZfZFZUIhOMVLp4BZ | E19: https://drive.google.com/open?id=16SwlhTSJ3zwse37SmZ-Cl-HLplEhJkUZ
A20: 45196.479 | B20: 1598 | C20: 3.072 | D20: https://drive.google.com/open?id=16dFlo0pqlBbR4fij6g9Sjz8-6m9YCXvD | E20: https://drive.google.com/open?id=1h9ZI5CsFEAZdYJohGKCkuqFJ7zSQZ1w_
A21: 45196.489 | B21: 1622 | C21: 2.33 | D21: https://drive.google.com/open?id=1wwWagOfQWUVCq0iPtbRVG5EHExKgH0go | E21: https://drive.google.com/open?id=1CStOvbh4yxTl-w1XSsh4fhIm6aStQgOO | F21: The only grade in two of my classes are my exam which they moved on me giving me two hours to study for each. Accounting is just kicking my ass but I will be getting it up as I am about to turn in a big project
A22: 45196.649 | B22: 1564 | C22: 3.845 | D22: https://drive.google.com/open?id=1QxN_vYsjcpHsBc_Vg4C-o5l9UHn7sT7v | E22: https://drive.google.com/open?id=1d8jNxuBncxqo75V7NyHL0UowLvl1LKed | F22: Miss you daddy
A23: 45196.745 | B23: 1631 | C23: 3.2 | D23: https://drive.google.com/open?id=1KizFJAU-qDYolQhOWPB8laldD8dc2Y0y | E23: https://drive.google.com/open?id=1VWtUMSdeMmPWQJhfo4mh8Uii42oLuAgQ
A24: 45196.789 | B24: 1621 | C24: 4 | D24: https://drive.google.com/open?id=1yMaFlNhAJt_akXgbIiOeoRvNhBBJFS4Z | E24: https://drive.google.com/open?id=1V9olrrbrldx14P0_99jGs1iSi5kFAKvv | F24: SKEE YEE
A25: 45197.351 | B25: 1594 | C25: 3.5 | D25: https://drive.google.com/open?id=1Wvj5KK4eGOT2KB_1jwV88H4vTgnA7Tt- | E25: https://drive.google.com/open?id=1ol-okhzur0SdN71iyY9KVx-pNkkBY7P2
A26: 45197.482 | B26: 17 | C26: 3.5 | D26: https://drive.google.com/open?id=1SAPECrO6xtaM3N9F8AiAj78lo7M8M3id, https://drive.google.com/open?id=1Cx6MuOSy33bdHhkvwtmEzWg0jsWGnN2V, https://drive.google.com/open?id=1f49XwBAmyiIQgOGLtj9bKYInz7TaAIhy | E26: https://drive.google.com/open?id=1yLVdAc_LpKxrDQBtEBL6Zj7J4q0gOFM- | F26: None
A27: 45197.573 | B27: 18 | C27: 2.048 | D27: https://drive.google.com/open?id=1rCupmR-qnyArQ9fk-3xhX5DxMsgHf0k- | E27: https://drive.google.com/open?id=1Dnid_Emv3Eq1prgK_vP9pyLJXBskq4oO, https://drive.google.com/open?id=1iEfSPcFisDHx-i6oXnwQEy3zJo2BPW1X | F27: Wasn’t sure which part of the calculator to screenshot so there’s two attached files Grades are rough this week, exams didn’t go well in math and chem, but I retake both exams next week.
A28: 45197.645 | B28: 1624 | C28: 3.168 | D28: https://drive.google.com/open?id=1oU7JrxEMQvGk6XMSP9DCuaBkTwcHPtP2 | E28: https://drive.google.com/open?id=119K8_XfXxdBffKqrHZsCkOyR-1eP_Cql
A29: 45197.948 | B29: 1608 | C29: 3.415 | D29: https://drive.google.com/open?id=1oUEpDO6Ve5pdQYlQkX1CoDHIYRaUdDjz | E29: https://drive.google.com/open?id=1HAdFYItPxqfAPTWVG6hE08nHVRv0t2x5
A30: 45198.286 | B30: 1599 | C30: 3.2 | D30: https://drive.google.com/open?id=1ZcwmXSX5vH_Aj2JZg4s04A8yQyv35Fsl, https://drive.google.com/open?id=1nEj-o9vPBILiDcAkv_8xLRqiZhZHyVCf | E30: https://drive.google.com/open?id=1syvZYCCTyAAn3RhwFzS7iGDklrAh0Gj7
