Workbook

Sheet By Semester
A1: Theta Xi vs the IFC
A2: Every semester since Fall 2018, from UNL's report cards. IFC Avg = the average IFC house that semester.
A4: Semester | B4: TX GPA | C4: All Greek Men GPA | D4: TX vs Greek Men | E4: All UNL Men GPA | F4: TX GPA Rank in IFC | G4: TX Members | H4: IFC Avg Members | I4: TX New Members | J4: IFC Avg New Members | K4: TX New Member Rank in IFC
A5: Fall 2018 | B5: =IF($A5="","",IF(COUNTIFS('UNL Data'!$A$2:$A$1500,$A5,'UNL Data'!$B$2:$B$1500,"Theta Xi",'UNL Data'!$E$2:$E$1500,"<>")=0,"",SUMIFS('UNL Data'!$E$2:$E$1500,'UNL Data'!$A$2:$A$1500,$A5,'UNL Data'!$B$2:$B$1500,"Theta Xi"))) -> 2.733 | C5: =IF($A5="","",IFERROR(IF(INDEX('UNL Averages'!$C:$C,MATCH($A5,'UNL Averages'!$A:$A,0))="","",INDEX('UNL Averages'!$C:$C,MATCH($A5,'UNL Averages'!$A:$A,0))),"")) -> 3.149 | D5: =IF(OR(B5="",C5=""),"",B5-C5) -> -0.416 | E5: =IF($A5="","",IFERROR(IF(INDEX('UNL Averages'!$B:$B,MATCH($A5,'UNL Averages'!$A:$A,0))="","",INDEX('UNL Averages'!$B:$B,MATCH($A5,'UNL Averages'!$A:$A,0))),"")) -> 2.976 | F5: =IF(B5="","",COUNTIFS('UNL Data'!$A$2:$A$1500,$A5,'UNL Data'!$E$2:$E$1500,">"&B5)+1&" of "&COUNTIFS('UNL Data'!$A$2:$A$1500,$A5,'UNL Data'!$E$2:$E$1500,">0")) -> 23 of 25 | G5: =IF($A5="","",IF(COUNTIFS('UNL Data'!$A$2:$A$1500,$A5,'UNL Data'!$B$2:$B$1500,"Theta Xi",'UNL Data'!$C$2:$C$1500,"<>")=0,"",SUMIFS('UNL Data'!$C$2:$C$1500,'UNL Data'!$A$2:$A$1500,$A5,'UNL Data'!$B$2:$B$1500,"Theta Xi"))) -> 62 | H5: =IF($A5="","",IFERROR(AVERAGEIFS('UNL Data'!$C$2:$C$1500,'UNL Data'!$A$2:$A$1500,$A5),"")) -> 65.64 | I5: =IF($A5="","",IF(COUNTIFS('UNL Data'!$A$2:$A$1500,$A5,'UNL Data'!$B$2:$B$1500,"Theta Xi",'UNL Data'!$D$2:$D$1500,"<>")=0,"",SUMIFS('UNL Data'!$D$2:$D$1500,'UNL Data'!$A$2:$A$1500,$A5,'UNL Data'!$B$2:$B$1500,"Theta Xi"))) -> 22 | J5: =IF($A5="","",IFERROR(AVERAGEIFS('UNL Data'!$D$2:$D$1500,'UNL Data'!$A$2:$A$1500,$A5),"")) -> 19.44 | K5: =IF(I5="","",COUNTIFS('UNL Data'!$A$2:$A$1500,$A5,'UNL Data'!$D$2:$D$1500,">"&I5)+1&" of "&COUNTIFS('UNL Data'!$A$2:$A$1500,$A5,'UNL Data'!$D$2:$D$1500,">=0")) -> 13 of 25
A6: Spring 2019 | B6: =IF($A6="","",IF(COUNTIFS('UNL Data'!$A$2:$A$1500,$A6,'UNL Data'!$B$2:$B$1500,"Theta Xi",'UNL Data'!$E$2:$E$1500,"<>")=0,"",SUMIFS('UNL Data'!$E$2:$E$1500,'UNL Data'!$A$2:$A$1500,$A6,'UNL Data'!$B$2:$B$1500,"Theta Xi"))) -> 2.919 | C6: =IF($A6="","",IFERROR(IF(INDEX('UNL Averages'!$C:$C,MATCH($A6,'UNL Averages'!$A:$A,0))="","",INDEX('UNL Averages'!$C:$C,MATCH($A6,'UNL Averages'!$A:$A,0))),"")) -> 3.154 | D6: =IF(OR(B6="",C6=""),"",B6-C6) -> -0.235 | E6: =IF($A6="","",IFERROR(IF(INDEX('UNL Averages'!$B:$B,MATCH($A6,'UNL Averages'!$A:$A,0))="","",INDEX('UNL Averages'!$B:$B,MATCH($A6,'UNL Averages'!$A:$A,0))),"")) -> 3.012 | F6: =IF(B6="","",COUNTIFS('UNL Data'!$A$2:$A$1500,$A6,'UNL Data'!$E$2:$E$1500,">"&B6)+1&" of "&COUNTIFS('UNL Data'!$A$2:$A$1500,$A6,'UNL Data'!$E$2:$E$1500,">0")) -> 21 of 24 | G6: =IF($A6="","",IF(COUNTIFS('UNL Data'!$A$2:$A$1500,$A6,'UNL Data'!$B$2:$B$1500,"Theta Xi",'UNL Data'!$C$2:$C$1500,"<>")=0,"",SUMIFS('UNL Data'!$C$2:$C$1500,'UNL Data'!$A$2:$A$1500,$A6,'UNL Data'!$B$2:$B$1500,"Theta Xi"))) -> 64 | H6: =IF($A6="","",IFERROR(AVERAGEIFS('UNL Data'!$C$2:$C$1500,'UNL Data'!$A$2:$A$1500,$A6),"")) -> 64.04 | I6: =IF($A6="","",IF(COUNTIFS('UNL Data'!$A$2:$A$1500,$A6,'UNL Data'!$B$2:$B$1500,"Theta Xi",'UNL Data'!$D$2:$D$1500,"<>")=0,"",SUMIFS('UNL Data'!$D$2:$D$1500,'UNL Data'!$A$2:$A$1500,$A6,'UNL Data'!$B$2:$B$1500,"Theta Xi"))) -> 9 | J6: =IF($A6="","",IFERROR(AVERAGEIFS('UNL Data'!$D$2:$D$1500,'UNL Data'!$A$2:$A$1500,$A6),"")) -> 2.72 | K6: =IF(I6="","",COUNTIFS('UNL Data'!$A$2:$A$1500,$A6,'UNL Data'!$D$2:$D$1500,">"&I6)+1&" of "&COUNTIFS('UNL Data'!$A$2:$A$1500,$A6,'UNL Data'!$D$2:$D$1500,">=0")) -> 3 of 25
A7: Fall 2019 | B7: =IF($A7="","",IF(COUNTIFS('UNL Data'!$A$2:$A$1500,$A7,'UNL Data'!$B$2:$B$1500,"Theta Xi",'UNL Data'!$E$2:$E$1500,"<>")=0,"",SUMIFS('UNL Data'!$E$2:$E$1500,'UNL Data'!$A$2:$A$1500,$A7,'UNL Data'!$B$2:$B$1500,"Theta Xi"))) -> 2.819 | C7: =IF($A7="","",IFERROR(IF(INDEX('UNL Averages'!$C:$C,MATCH($A7,'UNL Averages'!$A:$A,0))="","",INDEX('UNL Averages'!$C:$C,MATCH($A7,'UNL Averages'!$A:$A,0))),"")) -> 3.133 | D7: =IF(OR(B7="",C7=""),"",B7-C7) -> -0.314 | E7: =IF($A7="","",IFERROR(IF(INDEX('UNL Averages'!$B:$B,MATCH($A7,'UNL Averages'!$A:$A,0))="","",INDEX('UNL Averages'!$B:$B,MATCH($A7,'UNL Averages'!$A:$A,0))),"")) -> 3.032 | F7: =IF(B7="","",COUNTIFS('UNL Data'!$A$2:$A$1500,$A7,'UNL Data'!$E$2:$E$1500,">"&B7)+1&" of "&COUNTIFS('UNL Data'!$A$2:$A$1500,$A7,'UNL Data'!$E$2:$E$1500,">0")) -> 24 of 27 | G7: =IF($A7="","",IF(COUNTIFS('UNL Data'!$A$2:$A$1500,$A7,'UNL Data'!$B$2:$B$1500,"Theta Xi",'UNL Data'!$C$2:$C$1500,"<>")=0,"",SUMIFS('UNL Data'!$C$2:$C$1500,'UNL Data'!$A$2:$A$1500,$A7,'UNL Data'!$B$2:$B$1500,"Theta Xi"))) -> 86 | H7: =IF($A7="","",IFERROR(AVERAGEIFS('UNL Data'!$C$2:$C$1500,'UNL Data'!$A$2:$A$1500,$A7),"")) -> 71.851852 | I7: =IF($A7="","",IF(COUNTIFS('UNL Data'!$A$2:$A$1500,$A7,'UNL Data'!$B$2:$B$1500,"Theta Xi",'UNL Data'!$D$2:$D$1500,"<>")=0,"",SUMIFS('UNL Data'!$D$2:$D$1500,'UNL Data'!$A$2:$A$1500,$A7,'UNL Data'!$B$2:$B$1500,"Theta Xi"))) -> 25 | J7: =IF($A7="","",IFERROR(AVERAGEIFS('UNL Data'!$D$2:$D$1500,'UNL Data'!$A$2:$A$1500,$A7),"")) -> 21 | K7: =IF(I7="","",COUNTIFS('UNL Data'!$A$2:$A$1500,$A7,'UNL Data'!$D$2:$D$1500,">"&I7)+1&" of "&COUNTIFS('UNL Data'!$A$2:$A$1500,$A7,'UNL Data'!$D$2:$D$1500,">=0")) -> 14 of 27
A8: Spring 2020 | B8: =IF($A8="","",IF(COUNTIFS('UNL Data'!$A$2:$A$1500,$A8,'UNL Data'!$B$2:$B$1500,"Theta Xi",'UNL Data'!$E$2:$E$1500,"<>")=0,"",SUMIFS('UNL Data'!$E$2:$E$1500,'UNL Data'!$A$2:$A$1500,$A8,'UNL Data'!$B$2:$B$1500,"Theta Xi"))) | C8: =IF($A8="","",IFERROR(IF(INDEX('UNL Averages'!$C:$C,MATCH($A8,'UNL Averages'!$A:$A,0))="","",INDEX('UNL Averages'!$C:$C,MATCH($A8,'UNL Averages'!$A:$A,0))),"")) -> 3.439 | D8: =IF(OR(B8="",C8=""),"",B8-C8) | E8: =IF($A8="","",IFERROR(IF(INDEX('UNL Averages'!$B:$B,MATCH($A8,'UNL Averages'!$A:$A,0))="","",INDEX('UNL Averages'!$B:$B,MATCH($A8,'UNL Averages'!$A:$A,0))),"")) -> 3.365 | F8: =IF(B8="","",COUNTIFS('UNL Data'!$A$2:$A$1500,$A8,'UNL Data'!$E$2:$E$1500,">"&B8)+1&" of "&COUNTIFS('UNL Data'!$A$2:$A$1500,$A8,'UNL Data'!$E$2:$E$1500,">0")) | G8: =IF($A8="","",IF(COUNTIFS('UNL Data'!$A$2:$A$1500,$A8,'UNL Data'!$B$2:$B$1500,"Theta Xi",'UNL Data'!$C$2:$C$1500,"<>")=0,"",SUMIFS('UNL Data'!$C$2:$C$1500,'UNL Data'!$A$2:$A$1500,$A8,'UNL Data'!$B$2:$B$1500,"Theta Xi"))) -> 73 | H8: =IF($A8="","",IFERROR(AVERAGEIFS('UNL Data'!$C$2:$C$1500,'UNL Data'!$A$2:$A$1500,$A8),"")) -> 64.75 | I8: =IF($A8="","",IF(COUNTIFS('UNL Data'!$A$2:$A$1500,$A8,'UNL Data'!$B$2:$B$1500,"Theta Xi",'UNL Data'!$D$2:$D$1500,"<>")=0,"",SUMIFS('UNL Data'!$D$2:$D$1500,'UNL Data'!$A$2:$A$1500,$A8,'UNL Data'!$B$2:$B$1500,"Theta Xi"))) | J8: =IF($A8="","",IFERROR(AVERAGEIFS('UNL Data'!$D$2:$D$1500,'UNL Data'!$A$2:$A$1500,$A8),"")) | K8: =IF(I8="","",COUNTIFS('UNL Data'!$A$2:$A$1500,$A8,'UNL Data'!$D$2:$D$1500,">"&I8)+1&" of "&COUNTIFS('UNL Data'!$A$2:$A$1500,$A8,'UNL Data'!$D$2:$D$1500,">=0"))
A9: Fall 2020 | B9: =IF($A9="","",IF(COUNTIFS('UNL Data'!$A$2:$A$1500,$A9,'UNL Data'!$B$2:$B$1500,"Theta Xi",'UNL Data'!$E$2:$E$1500,"<>")=0,"",SUMIFS('UNL Data'!$E$2:$E$1500,'UNL Data'!$A$2:$A$1500,$A9,'UNL Data'!$B$2:$B$1500,"Theta Xi"))) -> 2.957 | C9: =IF($A9="","",IFERROR(IF(INDEX('UNL Averages'!$C:$C,MATCH($A9,'UNL Averages'!$A:$A,0))="","",INDEX('UNL Averages'!$C:$C,MATCH($A9,'UNL Averages'!$A:$A,0))),"")) -> 3.213 | D9: =IF(OR(B9="",C9=""),"",B9-C9) -> -0.256 | E9: =IF($A9="","",IFERROR(IF(INDEX('UNL Averages'!$B:$B,MATCH($A9,'UNL Averages'!$A:$A,0))="","",INDEX('UNL Averages'!$B:$B,MATCH($A9,'UNL Averages'!$A:$A,0))),"")) -> 3.032 | F9: =IF(B9="","",COUNTIFS('UNL Data'!$A$2:$A$1500,$A9,'UNL Data'!$E$2:$E$1500,">"&B9)+1&" of "&COUNTIFS('UNL Data'!$A$2:$A$1500,$A9,'UNL Data'!$E$2:$E$1500,">0")) -> 20 of 24 | G9: =IF($A9="","",IF(COUNTIFS('UNL Data'!$A$2:$A$1500,$A9,'UNL Data'!$B$2:$B$1500,"Theta Xi",'UNL Data'!$C$2:$C$1500,"<>")=0,"",SUMIFS('UNL Data'!$C$2:$C$1500,'UNL Data'!$A$2:$A$1500,$A9,'UNL Data'!$B$2:$B$1500,"Theta Xi"))) -> 78 | H9: =IF($A9="","",IFERROR(AVERAGEIFS('UNL Data'!$C$2:$C$1500,'UNL Data'!$A$2:$A$1500,$A9),"")) -> 72.038462 | I9: =IF($A9="","",IF(COUNTIFS('UNL Data'!$A$2:$A$1500,$A9,'UNL Data'!$B$2:$B$1500,"Theta Xi",'UNL Data'!$D$2:$D$1500,"<>")=0,"",SUMIFS('UNL Data'!$D$2:$D$1500,'UNL Data'!$A$2:$A$1500,$A9,'UNL Data'!$B$2:$B$1500,"Theta Xi"))) -> 28 | J9: =IF($A9="","",IFERROR(AVERAGEIFS('UNL Data'!$D$2:$D$1500,'UNL Data'!$A$2:$A$1500,$A9),"")) -> 21 | K9: =IF(I9="","",COUNTIFS('UNL Data'!$A$2:$A$1500,$A9,'UNL Data'!$D$2:$D$1500,">"&I9)+1&" of "&COUNTIFS('UNL Data'!$A$2:$A$1500,$A9,'UNL Data'!$D$2:$D$1500,">=0")) -> 9 of 26
A10: Spring 2021 | B10: =IF($A10="","",IF(COUNTIFS('UNL Data'!$A$2:$A$1500,$A10,'UNL Data'!$B$2:$B$1500,"Theta Xi",'UNL Data'!$E$2:$E$1500,"<>")=0,"",SUMIFS('UNL Data'!$E$2:$E$1500,'UNL Data'!$A$2:$A$1500,$A10,'UNL Data'!$B$2:$B$1500,"Theta Xi"))) -> 3.267 | C10: =IF($A10="","",IFERROR(IF(INDEX('UNL Averages'!$C:$C,MATCH($A10,'UNL Averages'!$A:$A,0))="","",INDEX('UNL Averages'!$C:$C,MATCH($A10,'UNL Averages'!$A:$A,0))),"")) -> 3.307 | D10: =IF(OR(B10="",C10=""),"",B10-C10) -> -0.04 | E10: =IF($A10="","",IFERROR(IF(INDEX('UNL Averages'!$B:$B,MATCH($A10,'UNL Averages'!$A:$A,0))="","",INDEX('UNL Averages'!$B:$B,MATCH($A10,'UNL Averages'!$A:$A,0))),"")) -> 3.187 | F10: =IF(B10="","",COUNTIFS('UNL Data'!$A$2:$A$1500,$A10,'UNL Data'!$E$2:$E$1500,">"&B10)+1&" of "&COUNTIFS('UNL Data'!$A$2:$A$1500,$A10,'UNL Data'!$E$2:$E$1500,">0")) -> 15 of 26 | G10: =IF($A10="","",IF(COUNTIFS('UNL Data'!$A$2:$A$1500,$A10,'UNL Data'!$B$2:$B$1500,"Theta Xi",'UNL Data'!$C$2:$C$1500,"<>")=0,"",SUMIFS('UNL Data'!$C$2:$C$1500,'UNL Data'!$A$2:$A$1500,$A10,'UNL Data'!$B$2:$B$1500,"Theta Xi"))) -> 74 | H10: =IF($A10="","",IFERROR(AVERAGEIFS('UNL Data'!$C$2:$C$1500,'UNL Data'!$A$2:$A$1500,$A10),"")) -> 68.769231 | I10: =IF($A10="","",IF(COUNTIFS('UNL Data'!$A$2:$A$1500,$A10,'UNL Data'!$B$2:$B$1500,"Theta Xi",'UNL Data'!$D$2:$D$1500,"<>")=0,"",SUMIFS('UNL Data'!$D$2:$D$1500,'UNL Data'!$A$2:$A$1500,$A10,'UNL Data'!$B$2:$B$1500,"Theta Xi"))) -> 10 | J10: =IF($A10="","",IFERROR(AVERAGEIFS('UNL Data'!$D$2:$D$1500,'UNL Data'!$A$2:$A$1500,$A10),"")) -> 3.3461538 | K10: =IF(I10="","",COUNTIFS('UNL Data'!$A$2:$A$1500,$A10,'UNL Data'!$D$2:$D$1500,">"&I10)+1&" of "&COUNTIFS('UNL Data'!$A$2:$A$1500,$A10,'UNL Data'!$D$2:$D$1500,">=0")) -> 2 of 26
A11: Fall 2021 | B11: =IF($A11="","",IF(COUNTIFS('UNL Data'!$A$2:$A$1500,$A11,'UNL Data'!$B$2:$B$1500,"Theta Xi",'UNL Data'!$E$2:$E$1500,"<>")=0,"",SUMIFS('UNL Data'!$E$2:$E$1500,'UNL Data'!$A$2:$A$1500,$A11,'UNL Data'!$B$2:$B$1500,"Theta Xi"))) -> 3.167 | C11: =IF($A11="","",IFERROR(IF(INDEX('UNL Averages'!$C:$C,MATCH($A11,'UNL Averages'!$A:$A,0))="","",INDEX('UNL Averages'!$C:$C,MATCH($A11,'UNL Averages'!$A:$A,0))),"")) -> 3.221 | D11: =IF(OR(B11="",C11=""),"",B11-C11) -> -0.054 | E11: =IF($A11="","",IFERROR(IF(INDEX('UNL Averages'!$B:$B,MATCH($A11,'UNL Averages'!$A:$A,0))="","",INDEX('UNL Averages'!$B:$B,MATCH($A11,'UNL Averages'!$A:$A,0))),"")) -> 3.084 | F11: =IF(B11="","",COUNTIFS('UNL Data'!$A$2:$A$1500,$A11,'UNL Data'!$E$2:$E$1500,">"&B11)+1&" of "&COUNTIFS('UNL Data'!$A$2:$A$1500,$A11,'UNL Data'!$E$2:$E$1500,">0")) -> 14 of 25 | G11: =IF($A11="","",IF(COUNTIFS('UNL Data'!$A$2:$A$1500,$A11,'UNL Data'!$B$2:$B$1500,"Theta Xi",'UNL Data'!$C$2:$C$1500,"<>")=0,"",SUMIFS('UNL Data'!$C$2:$C$1500,'UNL Data'!$A$2:$A$1500,$A11,'UNL Data'!$B$2:$B$1500,"Theta Xi"))) -> 74 | H11: =IF($A11="","",IFERROR(AVERAGEIFS('UNL Data'!$C$2:$C$1500,'UNL Data'!$A$2:$A$1500,$A11),"")) -> 70.36 | I11: =IF($A11="","",IF(COUNTIFS('UNL Data'!$A$2:$A$1500,$A11,'UNL Data'!$B$2:$B$1500,"Theta Xi",'UNL Data'!$D$2:$D$1500,"<>")=0,"",SUMIFS('UNL Data'!$D$2:$D$1500,'UNL Data'!$A$2:$A$1500,$A11,'UNL Data'!$B$2:$B$1500,"Theta Xi"))) -> 14 | J11: =IF($A11="","",IFERROR(AVERAGEIFS('UNL Data'!$D$2:$D$1500,'UNL Data'!$A$2:$A$1500,$A11),"")) -> 21 | K11: =IF(I11="","",COUNTIFS('UNL Data'!$A$2:$A$1500,$A11,'UNL Data'!$D$2:$D$1500,">"&I11)+1&" of "&COUNTIFS('UNL Data'!$A$2:$A$1500,$A11,'UNL Data'!$D$2:$D$1500,">=0")) -> 16 of 25
A12: Spring 2022 | B12: =IF($A12="","",IF(COUNTIFS('UNL Data'!$A$2:$A$1500,$A12,'UNL Data'!$B$2:$B$1500,"Theta Xi",'UNL Data'!$E$2:$E$1500,"<>")=0,"",SUMIFS('UNL Data'!$E$2:$E$1500,'UNL Data'!$A$2:$A$1500,$A12,'UNL Data'!$B$2:$B$1500,"Theta Xi"))) -> 3.316 | C12: =IF($A12="","",IFERROR(IF(INDEX('UNL Averages'!$C:$C,MATCH($A12,'UNL Averages'!$A:$A,0))="","",INDEX('UNL Averages'!$C:$C,MATCH($A12,'UNL Averages'!$A:$A,0))),"")) -> 3.29 | D12: =IF(OR(B12="",C12=""),"",B12-C12) -> 0.026 | E12: =IF($A12="","",IFERROR(IF(INDEX('UNL Averages'!$B:$B,MATCH($A12,'UNL Averages'!$A:$A,0))="","",INDEX('UNL Averages'!$B:$B,MATCH($A12,'UNL Averages'!$A:$A,0))),"")) -> 3.161 | F12: =IF(B12="","",COUNTIFS('UNL Data'!$A$2:$A$1500,$A12,'UNL Data'!$E$2:$E$1500,">"&B12)+1&" of "&COUNTIFS('UNL Data'!$A$2:$A$1500,$A12,'UNL Data'!$E$2:$E$1500,">0")) -> 10 of 25 | G12: =IF($A12="","",IF(COUNTIFS('UNL Data'!$A$2:$A$1500,$A12,'UNL Data'!$B$2:$B$1500,"Theta Xi",'UNL Data'!$C$2:$C$1500,"<>")=0,"",SUMIFS('UNL Data'!$C$2:$C$1500,'UNL Data'!$A$2:$A$1500,$A12,'UNL Data'!$B$2:$B$1500,"Theta Xi"))) -> 68 | H12: =IF($A12="","",IFERROR(AVERAGEIFS('UNL Data'!$C$2:$C$1500,'UNL Data'!$A$2:$A$1500,$A12),"")) -> 68.56 | I12: =IF($A12="","",IF(COUNTIFS('UNL Data'!$A$2:$A$1500,$A12,'UNL Data'!$B$2:$B$1500,"Theta Xi",'UNL Data'!$D$2:$D$1500,"<>")=0,"",SUMIFS('UNL Data'!$D$2:$D$1500,'UNL Data'!$A$2:$A$1500,$A12,'UNL Data'!$B$2:$B$1500,"Theta Xi"))) | J12: =IF($A12="","",IFERROR(AVERAGEIFS('UNL Data'!$D$2:$D$1500,'UNL Data'!$A$2:$A$1500,$A12),"")) | K12: =IF(I12="","",COUNTIFS('UNL Data'!$A$2:$A$1500,$A12,'UNL Data'!$D$2:$D$1500,">"&I12)+1&" of "&COUNTIFS('UNL Data'!$A$2:$A$1500,$A12,'UNL Data'!$D$2:$D$1500,">=0"))
A13: Fall 2022 | B13: =IF($A13="","",IF(COUNTIFS('UNL Data'!$A$2:$A$1500,$A13,'UNL Data'!$B$2:$B$1500,"Theta Xi",'UNL Data'!$E$2:$E$1500,"<>")=0,"",SUMIFS('UNL Data'!$E$2:$E$1500,'UNL Data'!$A$2:$A$1500,$A13,'UNL Data'!$B$2:$B$1500,"Theta Xi"))) -> 3.096 | C13: =IF($A13="","",IFERROR(IF(INDEX('UNL Averages'!$C:$C,MATCH($A13,'UNL Averages'!$A:$A,0))="","",INDEX('UNL Averages'!$C:$C,MATCH($A13,'UNL Averages'!$A:$A,0))),"")) -> 3.265 | D13: =IF(OR(B13="",C13=""),"",B13-C13) -> -0.169 | E13: =IF($A13="","",IFERROR(IF(INDEX('UNL Averages'!$B:$B,MATCH($A13,'UNL Averages'!$A:$A,0))="","",INDEX('UNL Averages'!$B:$B,MATCH($A13,'UNL Averages'!$A:$A,0))),"")) -> 3.131 | F13: =IF(B13="","",COUNTIFS('UNL Data'!$A$2:$A$1500,$A13,'UNL Data'!$E$2:$E$1500,">"&B13)+1&" of "&COUNTIFS('UNL Data'!$A$2:$A$1500,$A13,'UNL Data'!$E$2:$E$1500,">0")) -> 18 of 24 | G13: =IF($A13="","",IF(COUNTIFS('UNL Data'!$A$2:$A$1500,$A13,'UNL Data'!$B$2:$B$1500,"Theta Xi",'UNL Data'!$C$2:$C$1500,"<>")=0,"",SUMIFS('UNL Data'!$C$2:$C$1500,'UNL Data'!$A$2:$A$1500,$A13,'UNL Data'!$B$2:$B$1500,"Theta Xi"))) -> 71 | H13: =IF($A13="","",IFERROR(AVERAGEIFS('UNL Data'!$C$2:$C$1500,'UNL Data'!$A$2:$A$1500,$A13),"")) -> 74.25 | I13: =IF($A13="","",IF(COUNTIFS('UNL Data'!$A$2:$A$1500,$A13,'UNL Data'!$B$2:$B$1500,"Theta Xi",'UNL Data'!$D$2:$D$1500,"<>")=0,"",SUMIFS('UNL Data'!$D$2:$D$1500,'UNL Data'!$A$2:$A$1500,$A13,'UNL Data'!$B$2:$B$1500,"Theta Xi"))) -> 17 | J13: =IF($A13="","",IFERROR(AVERAGEIFS('UNL Data'!$D$2:$D$1500,'UNL Data'!$A$2:$A$1500,$A13),"")) -> 19.791667 | K13: =IF(I13="","",COUNTIFS('UNL Data'!$A$2:$A$1500,$A13,'UNL Data'!$D$2:$D$1500,">"&I13)+1&" of "&COUNTIFS('UNL Data'!$A$2:$A$1500,$A13,'UNL Data'!$D$2:$D$1500,">=0")) -> 14 of 24
A14: Spring 2023 | B14: =IF($A14="","",IF(COUNTIFS('UNL Data'!$A$2:$A$1500,$A14,'UNL Data'!$B$2:$B$1500,"Theta Xi",'UNL Data'!$E$2:$E$1500,"<>")=0,"",SUMIFS('UNL Data'!$E$2:$E$1500,'UNL Data'!$A$2:$A$1500,$A14,'UNL Data'!$B$2:$B$1500,"Theta Xi"))) -> 3.121 | C14: =IF($A14="","",IFERROR(IF(INDEX('UNL Averages'!$C:$C,MATCH($A14,'UNL Averages'!$A:$A,0))="","",INDEX('UNL Averages'!$C:$C,MATCH($A14,'UNL Averages'!$A:$A,0))),"")) -> 3.337 | D14: =IF(OR(B14="",C14=""),"",B14-C14) -> -0.216 | E14: =IF($A14="","",IFERROR(IF(INDEX('UNL Averages'!$B:$B,MATCH($A14,'UNL Averages'!$A:$A,0))="","",INDEX('UNL Averages'!$B:$B,MATCH($A14,'UNL Averages'!$A:$A,0))),"")) -> 3.198 | F14: =IF(B14="","",COUNTIFS('UNL Data'!$A$2:$A$1500,$A14,'UNL Data'!$E$2:$E$1500,">"&B14)+1&" of "&COUNTIFS('UNL Data'!$A$2:$A$1500,$A14,'UNL Data'!$E$2:$E$1500,">0")) -> 19 of 25 | G14: =IF($A14="","",IF(COUNTIFS('UNL Data'!$A$2:$A$1500,$A14,'UNL Data'!$B$2:$B$1500,"Theta Xi",'UNL Data'!$C$2:$C$1500,"<>")=0,"",SUMIFS('UNL Data'!$C$2:$C$1500,'UNL Data'!$A$2:$A$1500,$A14,'UNL Data'!$B$2:$B$1500,"Theta Xi"))) -> 71 | H14: =IF($A14="","",IFERROR(AVERAGEIFS('UNL Data'!$C$2:$C$1500,'UNL Data'!$A$2:$A$1500,$A14),"")) -> 67.72 | I14: =IF($A14="","",IF(COUNTIFS('UNL Data'!$A$2:$A$1500,$A14,'UNL Data'!$B$2:$B$1500,"Theta Xi",'UNL Data'!$D$2:$D$1500,"<>")=0,"",SUMIFS('UNL Data'!$D$2:$D$1500,'UNL Data'!$A$2:$A$1500,$A14,'UNL Data'!$B$2:$B$1500,"Theta Xi"))) -> 6 | J14: =IF($A14="","",IFERROR(AVERAGEIFS('UNL Data'!$D$2:$D$1500,'UNL Data'!$A$2:$A$1500,$A14),"")) -> 5.9411765 | K14: =IF(I14="","",COUNTIFS('UNL Data'!$A$2:$A$1500,$A14,'UNL Data'!$D$2:$D$1500,">"&I14)+1&" of "&COUNTIFS('UNL Data'!$A$2:$A$1500,$A14,'UNL Data'!$D$2:$D$1500,">=0")) -> 6 of 17
A15: Fall 2023 | B15: =IF($A15="","",IF(COUNTIFS('UNL Data'!$A$2:$A$1500,$A15,'UNL Data'!$B$2:$B$1500,"Theta Xi",'UNL Data'!$E$2:$E$1500,"<>")=0,"",SUMIFS('UNL Data'!$E$2:$E$1500,'UNL Data'!$A$2:$A$1500,$A15,'UNL Data'!$B$2:$B$1500,"Theta Xi"))) -> 2.997 | C15: =IF($A15="","",IFERROR(IF(INDEX('UNL Averages'!$C:$C,MATCH($A15,'UNL Averages'!$A:$A,0))="","",INDEX('UNL Averages'!$C:$C,MATCH($A15,'UNL Averages'!$A:$A,0))),"")) -> 3.257 | D15: =IF(OR(B15="",C15=""),"",B15-C15) -> -0.26 | E15: =IF($A15="","",IFERROR(IF(INDEX('UNL Averages'!$B:$B,MATCH($A15,'UNL Averages'!$A:$A,0))="","",INDEX('UNL Averages'!$B:$B,MATCH($A15,'UNL Averages'!$A:$A,0))),"")) -> 3.132 | F15: =IF(B15="","",COUNTIFS('UNL Data'!$A$2:$A$1500,$A15,'UNL Data'!$E$2:$E$1500,">"&B15)+1&" of "&COUNTIFS('UNL Data'!$A$2:$A$1500,$A15,'UNL Data'!$E$2:$E$1500,">0")) -> 19 of 25 | G15: =IF($A15="","",IF(COUNTIFS('UNL Data'!$A$2:$A$1500,$A15,'UNL Data'!$B$2:$B$1500,"Theta Xi",'UNL Data'!$C$2:$C$1500,"<>")=0,"",SUMIFS('UNL Data'!$C$2:$C$1500,'UNL Data'!$A$2:$A$1500,$A15,'UNL Data'!$B$2:$B$1500,"Theta Xi"))) -> 60 | H15: =IF($A15="","",IFERROR(AVERAGEIFS('UNL Data'!$C$2:$C$1500,'UNL Data'!$A$2:$A$1500,$A15),"")) -> 72.32 | I15: =IF($A15="","",IF(COUNTIFS('UNL Data'!$A$2:$A$1500,$A15,'UNL Data'!$B$2:$B$1500,"Theta Xi",'UNL Data'!$D$2:$D$1500,"<>")=0,"",SUMIFS('UNL Data'!$D$2:$D$1500,'UNL Data'!$A$2:$A$1500,$A15,'UNL Data'!$B$2:$B$1500,"Theta Xi"))) | J15: =IF($A15="","",IFERROR(AVERAGEIFS('UNL Data'!$D$2:$D$1500,'UNL Data'!$A$2:$A$1500,$A15),"")) | K15: =IF(I15="","",COUNTIFS('UNL Data'!$A$2:$A$1500,$A15,'UNL Data'!$D$2:$D$1500,">"&I15)+1&" of "&COUNTIFS('UNL Data'!$A$2:$A$1500,$A15,'UNL Data'!$D$2:$D$1500,">=0"))
A16: Spring 2024 | B16: =IF($A16="","",IF(COUNTIFS('UNL Data'!$A$2:$A$1500,$A16,'UNL Data'!$B$2:$B$1500,"Theta Xi",'UNL Data'!$E$2:$E$1500,"<>")=0,"",SUMIFS('UNL Data'!$E$2:$E$1500,'UNL Data'!$A$2:$A$1500,$A16,'UNL Data'!$B$2:$B$1500,"Theta Xi"))) -> 3.321 | C16: =IF($A16="","",IFERROR(IF(INDEX('UNL Averages'!$C:$C,MATCH($A16,'UNL Averages'!$A:$A,0))="","",INDEX('UNL Averages'!$C:$C,MATCH($A16,'UNL Averages'!$A:$A,0))),"")) -> 3.328 | D16: =IF(OR(B16="",C16=""),"",B16-C16) -> -0.007 | E16: =IF($A16="","",IFERROR(IF(INDEX('UNL Averages'!$B:$B,MATCH($A16,'UNL Averages'!$A:$A,0))="","",INDEX('UNL Averages'!$B:$B,MATCH($A16,'UNL Averages'!$A:$A,0))),"")) -> 3.208 | F16: =IF(B16="","",COUNTIFS('UNL Data'!$A$2:$A$1500,$A16,'UNL Data'!$E$2:$E$1500,">"&B16)+1&" of "&COUNTIFS('UNL Data'!$A$2:$A$1500,$A16,'UNL Data'!$E$2:$E$1500,">0")) -> 11 of 25 | G16: =IF($A16="","",IF(COUNTIFS('UNL Data'!$A$2:$A$1500,$A16,'UNL Data'!$B$2:$B$1500,"Theta Xi",'UNL Data'!$C$2:$C$1500,"<>")=0,"",SUMIFS('UNL Data'!$C$2:$C$1500,'UNL Data'!$A$2:$A$1500,$A16,'UNL Data'!$B$2:$B$1500,"Theta Xi"))) -> 48 | H16: =IF($A16="","",IFERROR(AVERAGEIFS('UNL Data'!$C$2:$C$1500,'UNL Data'!$A$2:$A$1500,$A16),"")) -> 70.36 | I16: =IF($A16="","",IF(COUNTIFS('UNL Data'!$A$2:$A$1500,$A16,'UNL Data'!$B$2:$B$1500,"Theta Xi",'UNL Data'!$D$2:$D$1500,"<>")=0,"",SUMIFS('UNL Data'!$D$2:$D$1500,'UNL Data'!$A$2:$A$1500,$A16,'UNL Data'!$B$2:$B$1500,"Theta Xi"))) -> 5 | J16: =IF($A16="","",IFERROR(AVERAGEIFS('UNL Data'!$D$2:$D$1500,'UNL Data'!$A$2:$A$1500,$A16),"")) -> 3.8 | K16: =IF(I16="","",COUNTIFS('UNL Data'!$A$2:$A$1500,$A16,'UNL Data'!$D$2:$D$1500,">"&I16)+1&" of "&COUNTIFS('UNL Data'!$A$2:$A$1500,$A16,'UNL Data'!$D$2:$D$1500,">=0")) -> 5 of 25
... A20: Spring 2026 | B20: =IF($A20="","",IF(COUNTIFS('UNL Data'!$A$2:$A$1500,$A20,'UNL Data'!$B$2:$B$1500,"Theta Xi",'UNL Data'!$E$2:$E$1500,"<>")=0,"",SUMIFS('UNL Data'!$E$2:$E$1500,'UNL Data'!$A$2:$A$1500,$A20,'UNL Data'!$B$2:$B$1500,"Theta Xi"))) -> 3.163 | C20: =IF($A20="","",IFERROR(IF(INDEX('UNL Averages'!$C:$C,MATCH($A20,'UNL Averages'!$A:$A,0))="","",INDEX('UNL Averages'!$C:$C,MATCH($A20,'UNL Averages'!$A:$A,0))),"")) -> 3.384 | D20: =IF(OR(B20="",C20=""),"",B20-C20) -> -0.221 | E20: =IF($A20="","",IFERROR(IF(INDEX('UNL Averages'!$B:$B,MATCH($A20,'UNL Averages'!$A:$A,0))="","",INDEX('UNL Averages'!$B:$B,MATCH($A20,'UNL Averages'!$A:$A,0))),"")) -> 3.226 | F20: =IF(B20="","",COUNTIFS('UNL Data'!$A$2:$A$1500,$A20,'UNL Data'!$E$2:$E$1500,">"&B20)+1&" of "&COUNTIFS('UNL Data'!$A$2:$A$1500,$A20,'UNL Data'!$E$2:$E$1500,">0")) -> 17 of 23 | G20: =IF($A20="","",IF(COUNTIFS('UNL Data'!$A$2:$A$1500,$A20,'UNL Data'!$B$2:$B$1500,"Theta Xi",'UNL Data'!$C$2:$C$1500,"<>")=0,"",SUMIFS('UNL Data'!$C$2:$C$1500,'UNL Data'!$A$2:$A$1500,$A20,'UNL Data'!$B$2:$B$1500,"Theta Xi"))) -> 43 | H20: =IF($A20="","",IFERROR(AVERAGEIFS('UNL Data'!$C$2:$C$1500,'UNL Data'!$A$2:$A$1500,$A20),"")) -> 76.347826 | I20: =IF($A20="","",IF(COUNTIFS('UNL Data'!$A$2:$A$1500,$A20,'UNL Data'!$B$2:$B$1500,"Theta Xi",'UNL Data'!$D$2:$D$1500,"<>")=0,"",SUMIFS('UNL Data'!$D$2:$D$1500,'UNL Data'!$A$2:$A$1500,$A20,'UNL Data'!$B$2:$B$1500,"Theta Xi"))) -> 6 | J20: =IF($A20="","",IFERROR(AVERAGEIFS('UNL Data'!$D$2:$D$1500,'UNL Data'!$A$2:$A$1500,$A20),"")) -> 4.1304348 | K20: =IF(I20="","",COUNTIFS('UNL Data'!$A$2:$A$1500,$A20,'UNL Data'!$D$2:$D$1500,">"&I20)+1&" of "&COUNTIFS('UNL Data'!$A$2:$A$1500,$A20,'UNL Data'!$D$2:$D$1500,">=0")) -> 5 of 23
B21: =IF($A21="","",IF(COUNTIFS('UNL Data'!$A$2:$A$1500,$A21,'UNL Data'!$B$2:$B$1500,"Theta Xi",'UNL Data'!$E$2:$E$1500,"<>")=0,"",SUMIFS('UNL Data'!$E$2:$E$1500,'UNL Data'!$A$2:$A$1500,$A21,'UNL Data'!$B$2:$B$1500,"Theta Xi"))) | C21: =IF($A21="","",IFERROR(IF(INDEX('UNL Averages'!$C:$C,MATCH($A21,'UNL Averages'!$A:$A,0))="","",INDEX('UNL Averages'!$C:$C,MATCH($A21,'UNL Averages'!$A:$A,0))),"")) | D21: =IF(OR(B21="",C21=""),"",B21-C21) | E21: =IF($A21="","",IFERROR(IF(INDEX('UNL Averages'!$B:$B,MATCH($A21,'UNL Averages'!$A:$A,0))="","",INDEX('UNL Averages'!$B:$B,MATCH($A21,'UNL Averages'!$A:$A,0))),"")) | F21: =IF(B21="","",COUNTIFS('UNL Data'!$A$2:$A$1500,$A21,'UNL Data'!$E$2:$E$1500,">"&B21)+1&" of "&COUNTIFS('UNL Data'!$A$2:$A$1500,$A21,'UNL Data'!$E$2:$E$1500,">0")) | G21: =IF($A21="","",IF(COUNTIFS('UNL Data'!$A$2:$A$1500,$A21,'UNL Data'!$B$2:$B$1500,"Theta Xi",'UNL Data'!$C$2:$C$1500,"<>")=0,"",SUMIFS('UNL Data'!$C$2:$C$1500,'UNL Data'!$A$2:$A$1500,$A21,'UNL Data'!$B$2:$B$1500,"Theta Xi"))) | H21: =IF($A21="","",IFERROR(AVERAGEIFS('UNL Data'!$C$2:$C$1500,'UNL Data'!$A$2:$A$1500,$A21),"")) | I21: =IF($A21="","",IF(COUNTIFS('UNL Data'!$A$2:$A$1500,$A21,'UNL Data'!$B$2:$B$1500,"Theta Xi",'UNL Data'!$D$2:$D$1500,"<>")=0,"",SUMIFS('UNL Data'!$D$2:$D$1500,'UNL Data'!$A$2:$A$1500,$A21,'UNL Data'!$B$2:$B$1500,"Theta Xi"))) | J21: =IF($A21="","",IFERROR(AVERAGEIFS('UNL Data'!$D$2:$D$1500,'UNL Data'!$A$2:$A$1500,$A21),"")) | K21: =IF(I21="","",COUNTIFS('UNL Data'!$A$2:$A$1500,$A21,'UNL Data'!$D$2:$D$1500,">"&I21)+1&" of "&COUNTIFS('UNL Data'!$A$2:$A$1500,$A21,'UNL Data'!$D$2:$D$1500,">=0"))
B22: =IF($A22="","",IF(COUNTIFS('UNL Data'!$A$2:$A$1500,$A22,'UNL Data'!$B$2:$B$1500,"Theta Xi",'UNL Data'!$E$2:$E$1500,"<>")=0,"",SUMIFS('UNL Data'!$E$2:$E$1500,'UNL Data'!$A$2:$A$1500,$A22,'UNL Data'!$B$2:$B$1500,"Theta Xi"))) | C22: =IF($A22="","",IFERROR(IF(INDEX('UNL Averages'!$C:$C,MATCH($A22,'UNL Averages'!$A:$A,0))="","",INDEX('UNL Averages'!$C:$C,MATCH($A22,'UNL Averages'!$A:$A,0))),"")) | D22: =IF(OR(B22="",C22=""),"",B22-C22) | E22: =IF($A22="","",IFERROR(IF(INDEX('UNL Averages'!$B:$B,MATCH($A22,'UNL Averages'!$A:$A,0))="","",INDEX('UNL Averages'!$B:$B,MATCH($A22,'UNL Averages'!$A:$A,0))),"")) | F22: =IF(B22="","",COUNTIFS('UNL Data'!$A$2:$A$1500,$A22,'UNL Data'!$E$2:$E$1500,">"&B22)+1&" of "&COUNTIFS('UNL Data'!$A$2:$A$1500,$A22,'UNL Data'!$E$2:$E$1500,">0")) | G22: =IF($A22="","",IF(COUNTIFS('UNL Data'!$A$2:$A$1500,$A22,'UNL Data'!$B$2:$B$1500,"Theta Xi",'UNL Data'!$C$2:$C$1500,"<>")=0,"",SUMIFS('UNL Data'!$C$2:$C$1500,'UNL Data'!$A$2:$A$1500,$A22,'UNL Data'!$B$2:$B$1500,"Theta Xi"))) | H22: =IF($A22="","",IFERROR(AVERAGEIFS('UNL Data'!$C$2:$C$1500,'UNL Data'!$A$2:$A$1500,$A22),"")) | I22: =IF($A22="","",IF(COUNTIFS('UNL Data'!$A$2:$A$1500,$A22,'UNL Data'!$B$2:$B$1500,"Theta Xi",'UNL Data'!$D$2:$D$1500,"<>")=0,"",SUMIFS('UNL Data'!$D$2:$D$1500,'UNL Data'!$A$2:$A$1500,$A22,'UNL Data'!$B$2:$B$1500,"Theta Xi"))) | J22: =IF($A22="","",IFERROR(AVERAGEIFS('UNL Data'!$D$2:$D$1500,'UNL Data'!$A$2:$A$1500,$A22),"")) | K22: =IF(I22="","",COUNTIFS('UNL Data'!$A$2:$A$1500,$A22,'UNL Data'!$D$2:$D$1500,">"&I22)+1&" of "&COUNTIFS('UNL Data'!$A$2:$A$1500,$A22,'UNL Data'!$D$2:$D$1500,">=0"))
B23: =IF($A23="","",IF(COUNTIFS('UNL Data'!$A$2:$A$1500,$A23,'UNL Data'!$B$2:$B$1500,"Theta Xi",'UNL Data'!$E$2:$E$1500,"<>")=0,"",SUMIFS('UNL Data'!$E$2:$E$1500,'UNL Data'!$A$2:$A$1500,$A23,'UNL Data'!$B$2:$B$1500,"Theta Xi"))) | C23: =IF($A23="","",IFERROR(IF(INDEX('UNL Averages'!$C:$C,MATCH($A23,'UNL Averages'!$A:$A,0))="","",INDEX('UNL Averages'!$C:$C,MATCH($A23,'UNL Averages'!$A:$A,0))),"")) | D23: =IF(OR(B23="",C23=""),"",B23-C23) | E23: =IF($A23="","",IFERROR(IF(INDEX('UNL Averages'!$B:$B,MATCH($A23,'UNL Averages'!$A:$A,0))="","",INDEX('UNL Averages'!$B:$B,MATCH($A23,'UNL Averages'!$A:$A,0))),"")) | F23: =IF(B23="","",COUNTIFS('UNL Data'!$A$2:$A$1500,$A23,'UNL Data'!$E$2:$E$1500,">"&B23)+1&" of "&COUNTIFS('UNL Data'!$A$2:$A$1500,$A23,'UNL Data'!$E$2:$E$1500,">0")) | G23: =IF($A23="","",IF(COUNTIFS('UNL Data'!$A$2:$A$1500,$A23,'UNL Data'!$B$2:$B$1500,"Theta Xi",'UNL Data'!$C$2:$C$1500,"<>")=0,"",SUMIFS('UNL Data'!$C$2:$C$1500,'UNL Data'!$A$2:$A$1500,$A23,'UNL Data'!$B$2:$B$1500,"Theta Xi"))) | H23: =IF($A23="","",IFERROR(AVERAGEIFS('UNL Data'!$C$2:$C$1500,'UNL Data'!$A$2:$A$1500,$A23),"")) | I23: =IF($A23="","",IF(COUNTIFS('UNL Data'!$A$2:$A$1500,$A23,'UNL Data'!$B$2:$B$1500,"Theta Xi",'UNL Data'!$D$2:$D$1500,"<>")=0,"",SUMIFS('UNL Data'!$D$2:$D$1500,'UNL Data'!$A$2:$A$1500,$A23,'UNL Data'!$B$2:$B$1500,"Theta Xi"))) | J23: =IF($A23="","",IFERROR(AVERAGEIFS('UNL Data'!$D$2:$D$1500,'UNL Data'!$A$2:$A$1500,$A23),"")) | K23: =IF(I23="","",COUNTIFS('UNL Data'!$A$2:$A$1500,$A23,'UNL Data'!$D$2:$D$1500,">"&I23)+1&" of "&COUNTIFS('UNL Data'!$A$2:$A$1500,$A23,'UNL Data'!$D$2:$D$1500,">=0"))
B24: =IF($A24="","",IF(COUNTIFS('UNL Data'!$A$2:$A$1500,$A24,'UNL Data'!$B$2:$B$1500,"Theta Xi",'UNL Data'!$E$2:$E$1500,"<>")=0,"",SUMIFS('UNL Data'!$E$2:$E$1500,'UNL Data'!$A$2:$A$1500,$A24,'UNL Data'!$B$2:$B$1500,"Theta Xi"))) | C24: =IF($A24="","",IFERROR(IF(INDEX('UNL Averages'!$C:$C,MATCH($A24,'UNL Averages'!$A:$A,0))="","",INDEX('UNL Averages'!$C:$C,MATCH($A24,'UNL Averages'!$A:$A,0))),"")) | D24: =IF(OR(B24="",C24=""),"",B24-C24) | E24: =IF($A24="","",IFERROR(IF(INDEX('UNL Averages'!$B:$B,MATCH($A24,'UNL Averages'!$A:$A,0))="","",INDEX('UNL Averages'!$B:$B,MATCH($A24,'UNL Averages'!$A:$A,0))),"")) | F24: =IF(B24="","",COUNTIFS('UNL Data'!$A$2:$A$1500,$A24,'UNL Data'!$E$2:$E$1500,">"&B24)+1&" of "&COUNTIFS('UNL Data'!$A$2:$A$1500,$A24,'UNL Data'!$E$2:$E$1500,">0")) | G24: =IF($A24="","",IF(COUNTIFS('UNL Data'!$A$2:$A$1500,$A24,'UNL Data'!$B$2:$B$1500,"Theta Xi",'UNL Data'!$C$2:$C$1500,"<>")=0,"",SUMIFS('UNL Data'!$C$2:$C$1500,'UNL Data'!$A$2:$A$1500,$A24,'UNL Data'!$B$2:$B$1500,"Theta Xi"))) | H24: =IF($A24="","",IFERROR(AVERAGEIFS('UNL Data'!$C$2:$C$1500,'UNL Data'!$A$2:$A$1500,$A24),"")) | I24: =IF($A24="","",IF(COUNTIFS('UNL Data'!$A$2:$A$1500,$A24,'UNL Data'!$B$2:$B$1500,"Theta Xi",'UNL Data'!$D$2:$D$1500,"<>")=0,"",SUMIFS('UNL Data'!$D$2:$D$1500,'UNL Data'!$A$2:$A$1500,$A24,'UNL Data'!$B$2:$B$1500,"Theta Xi"))) | J24: =IF($A24="","",IFERROR(AVERAGEIFS('UNL Data'!$D$2:$D$1500,'UNL Data'!$A$2:$A$1500,$A24),"")) | K24: =IF(I24="","",COUNTIFS('UNL Data'!$A$2:$A$1500,$A24,'UNL Data'!$D$2:$D$1500,">"&I24)+1&" of "&COUNTIFS('UNL Data'!$A$2:$A$1500,$A24,'UNL Data'!$D$2:$D$1500,">=0"))
A25: Blank = UNL didn't report it that semester.

Sheet By Year
A1: Recruitment by Year
A2: Year = spring + fall recruitment, the same exec board (elected in November, trained in December).
A4: Year | B4: TX New Members | C4: IFC Avg New Members | D4: TX vs Avg House | E4: TX Members (Fall) | F4: Change From Last Fall | G4: IFC Avg Members (Fall)
A5: 2018 | B5: =IF(OR(COUNTIFS('UNL Data'!$A$2:$A$1500,"Spring "&$A5,'UNL Data'!$B$2:$B$1500,"Theta Xi",'UNL Data'!$D$2:$D$1500,"<>")=0,COUNTIFS('UNL Data'!$A$2:$A$1500,"Fall "&$A5,'UNL Data'!$B$2:$B$1500,"Theta Xi",'UNL Data'!$D$2:$D$1500,"<>")=0),"",SUMIFS('UNL Data'!$D$2:$D$1500,'UNL Data'!$A$2:$A$1500,"Spring "&$A5,'UNL Data'!$B$2:$B$1500,"Theta Xi")+SUMIFS('UNL Data'!$D$2:$D$1500,'UNL Data'!$A$2:$A$1500,"Fall "&$A5,'UNL Data'!$B$2:$B$1500,"Theta Xi")) | C5: =IFERROR(AVERAGEIFS('UNL Data'!$D$2:$D$1500,'UNL Data'!$A$2:$A$1500,"Spring "&$A5)+AVERAGEIFS('UNL Data'!$D$2:$D$1500,'UNL Data'!$A$2:$A$1500,"Fall "&$A5),"") | D5: =IF(OR(B5="",C5=""),"",B5/C5) | E5: =IF(COUNTIFS('UNL Data'!$A$2:$A$1500,"Fall "&$A5,'UNL Data'!$B$2:$B$1500,"Theta Xi",'UNL Data'!$C$2:$C$1500,"<>")=0,"",SUMIFS('UNL Data'!$C$2:$C$1500,'UNL Data'!$A$2:$A$1500,"Fall "&$A5,'UNL Data'!$B$2:$B$1500,"Theta Xi")) -> 62 | G5: =IFERROR(AVERAGEIFS('UNL Data'!$C$2:$C$1500,'UNL Data'!$A$2:$A$1500,"Fall "&$A5),"") -> 65.64
A6: 2019 | B6: =IF(OR(COUNTIFS('UNL Data'!$A$2:$A$1500,"Spring "&$A6,'UNL Data'!$B$2:$B$1500,"Theta Xi",'UNL Data'!$D$2:$D$1500,"<>")=0,COUNTIFS('UNL Data'!$A$2:$A$1500,"Fall "&$A6,'UNL Data'!$B$2:$B$1500,"Theta Xi",'UNL Data'!$D$2:$D$1500,"<>")=0),"",SUMIFS('UNL Data'!$D$2:$D$1500,'UNL Data'!$A$2:$A$1500,"Spring "&$A6,'UNL Data'!$B$2:$B$1500,"Theta Xi")+SUMIFS('UNL Data'!$D$2:$D$1500,'UNL Data'!$A$2:$A$1500,"Fall "&$A6,'UNL Data'!$B$2:$B$1500,"Theta Xi")) -> 34 | C6: =IFERROR(AVERAGEIFS('UNL Data'!$D$2:$D$1500,'UNL Data'!$A$2:$A$1500,"Spring "&$A6)+AVERAGEIFS('UNL Data'!$D$2:$D$1500,'UNL Data'!$A$2:$A$1500,"Fall "&$A6),"") -> 23.72 | D6: =IF(OR(B6="",C6=""),"",B6/C6) -> 1.4333895 | E6: =IF(COUNTIFS('UNL Data'!$A$2:$A$1500,"Fall "&$A6,'UNL Data'!$B$2:$B$1500,"Theta Xi",'UNL Data'!$C$2:$C$1500,"<>")=0,"",SUMIFS('UNL Data'!$C$2:$C$1500,'UNL Data'!$A$2:$A$1500,"Fall "&$A6,'UNL Data'!$B$2:$B$1500,"Theta Xi")) -> 86 | F6: =IF(OR(E6="",E5=""),"",E6-E5) -> 24 | G6: =IFERROR(AVERAGEIFS('UNL Data'!$C$2:$C$1500,'UNL Data'!$A$2:$A$1500,"Fall "&$A6),"") -> 71.851852
A7: 2020 | B7: =IF(OR(COUNTIFS('UNL Data'!$A$2:$A$1500,"Spring "&$A7,'UNL Data'!$B$2:$B$1500,"Theta Xi",'UNL Data'!$D$2:$D$1500,"<>")=0,COUNTIFS('UNL Data'!$A$2:$A$1500,"Fall "&$A7,'UNL Data'!$B$2:$B$1500,"Theta Xi",'UNL Data'!$D$2:$D$1500,"<>")=0),"",SUMIFS('UNL Data'!$D$2:$D$1500,'UNL Data'!$A$2:$A$1500,"Spring "&$A7,'UNL Data'!$B$2:$B$1500,"Theta Xi")+SUMIFS('UNL Data'!$D$2:$D$1500,'UNL Data'!$A$2:$A$1500,"Fall "&$A7,'UNL Data'!$B$2:$B$1500,"Theta Xi")) | C7: =IFERROR(AVERAGEIFS('UNL Data'!$D$2:$D$1500,'UNL Data'!$A$2:$A$1500,"Spring "&$A7)+AVERAGEIFS('UNL Data'!$D$2:$D$1500,'UNL Data'!$A$2:$A$1500,"Fall "&$A7),"") | D7: =IF(OR(B7="",C7=""),"",B7/C7) | E7: =IF(COUNTIFS('UNL Data'!$A$2:$A$1500,"Fall "&$A7,'UNL Data'!$B$2:$B$1500,"Theta Xi",'UNL Data'!$C$2:$C$1500,"<>")=0,"",SUMIFS('UNL Data'!$C$2:$C$1500,'UNL Data'!$A$2:$A$1500,"Fall "&$A7,'UNL Data'!$B$2:$B$1500,"Theta Xi")) -> 78 | F7: =IF(OR(E7="",E6=""),"",E7-E6) -> -8 | G7: =IFERROR(AVERAGEIFS('UNL Data'!$C$2:$C$1500,'UNL Data'!$A$2:$A$1500,"Fall "&$A7),"") -> 72.038462
A8: 2021 | B8: =IF(OR(COUNTIFS('UNL Data'!$A$2:$A$1500,"Spring "&$A8,'UNL Data'!$B$2:$B$1500,"Theta Xi",'UNL Data'!$D$2:$D$1500,"<>")=0,COUNTIFS('UNL Data'!$A$2:$A$1500,"Fall "&$A8,'UNL Data'!$B$2:$B$1500,"Theta Xi",'UNL Data'!$D$2:$D$1500,"<>")=0),"",SUMIFS('UNL Data'!$D$2:$D$1500,'UNL Data'!$A$2:$A$1500,"Spring "&$A8,'UNL Data'!$B$2:$B$1500,"Theta Xi")+SUMIFS('UNL Data'!$D$2:$D$1500,'UNL Data'!$A$2:$A$1500,"Fall "&$A8,'UNL Data'!$B$2:$B$1500,"Theta Xi")) -> 24 | C8: =IFERROR(AVERAGEIFS('UNL Data'!$D$2:$D$1500,'UNL Data'!$A$2:$A$1500,"Spring "&$A8)+AVERAGEIFS('UNL Data'!$D$2:$D$1500,'UNL Data'!$A$2:$A$1500,"Fall "&$A8),"") -> 24.346154 | D8: =IF(OR(B8="",C8=""),"",B8/C8) -> 0.98578199 | E8: =IF(COUNTIFS('UNL Data'!$A$2:$A$1500,"Fall "&$A8,'UNL Data'!$B$2:$B$1500,"Theta Xi",'UNL Data'!$C$2:$C$1500,"<>")=0,"",SUMIFS('UNL Data'!$C$2:$C$1500,'UNL Data'!$A$2:$A$1500,"Fall "&$A8,'UNL Data'!$B$2:$B$1500,"Theta Xi")) -> 74 | F8: =IF(OR(E8="",E7=""),"",E8-E7) -> -4 | G8: =IFERROR(AVERAGEIFS('UNL Data'!$C$2:$C$1500,'UNL Data'!$A$2:$A$1500,"Fall "&$A8),"") -> 70.36
A9: 2022 | B9: =IF(OR(COUNTIFS('UNL Data'!$A$2:$A$1500,"Spring "&$A9,'UNL Data'!$B$2:$B$1500,"Theta Xi",'UNL Data'!$D$2:$D$1500,"<>")=0,COUNTIFS('UNL Data'!$A$2:$A$1500,"Fall "&$A9,'UNL Data'!$B$2:$B$1500,"Theta Xi",'UNL Data'!$D$2:$D$1500,"<>")=0),"",SUMIFS('UNL Data'!$D$2:$D$1500,'UNL Data'!$A$2:$A$1500,"Spring "&$A9,'UNL Data'!$B$2:$B$1500,"Theta Xi")+SUMIFS('UNL Data'!$D$2:$D$1500,'UNL Data'!$A$2:$A$1500,"Fall "&$A9,'UNL Data'!$B$2:$B$1500,"Theta Xi")) | C9: =IFERROR(AVERAGEIFS('UNL Data'!$D$2:$D$1500,'UNL Data'!$A$2:$A$1500,"Spring "&$A9)+AVERAGEIFS('UNL Data'!$D$2:$D$1500,'UNL Data'!$A$2:$A$1500,"Fall "&$A9),"") | D9: =IF(OR(B9="",C9=""),"",B9/C9) | E9: =IF(COUNTIFS('UNL Data'!$A$2:$A$1500,"Fall "&$A9,'UNL Data'!$B$2:$B$1500,"Theta Xi",'UNL Data'!$C$2:$C$1500,"<>")=0,"",SUMIFS('UNL Data'!$C$2:$C$1500,'UNL Data'!$A$2:$A$1500,"Fall "&$A9,'UNL Data'!$B$2:$B$1500,"Theta Xi")) -> 71 | F9: =IF(OR(E9="",E8=""),"",E9-E8) -> -3 | G9: =IFERROR(AVERAGEIFS('UNL Data'!$C$2:$C$1500,'UNL Data'!$A$2:$A$1500,"Fall "&$A9),"") -> 74.25
A10: 2023 | B10: =IF(OR(COUNTIFS('UNL Data'!$A$2:$A$1500,"Spring "&$A10,'UNL Data'!$B$2:$B$1500,"Theta Xi",'UNL Data'!$D$2:$D$1500,"<>")=0,COUNTIFS('UNL Data'!$A$2:$A$1500,"Fall "&$A10,'UNL Data'!$B$2:$B$1500,"Theta Xi",'UNL Data'!$D$2:$D$1500,"<>")=0),"",SUMIFS('UNL Data'!$D$2:$D$1500,'UNL Data'!$A$2:$A$1500,"Spring "&$A10,'UNL Data'!$B$2:$B$1500,"Theta Xi")+SUMIFS('UNL Data'!$D$2:$D$1500,'UNL Data'!$A$2:$A$1500,"Fall "&$A10,'UNL Data'!$B$2:$B$1500,"Theta Xi")) | C10: =IFERROR(AVERAGEIFS('UNL Data'!$D$2:$D$1500,'UNL Data'!$A$2:$A$1500,"Spring "&$A10)+AVERAGEIFS('UNL Data'!$D$2:$D$1500,'UNL Data'!$A$2:$A$1500,"Fall "&$A10),"") | D10: =IF(OR(B10="",C10=""),"",B10/C10) | E10: =IF(COUNTIFS('UNL Data'!$A$2:$A$1500,"Fall "&$A10,'UNL Data'!$B$2:$B$1500,"Theta Xi",'UNL Data'!$C$2:$C$1500,"<>")=0,"",SUMIFS('UNL Data'!$C$2:$C$1500,'UNL Data'!$A$2:$A$1500,"Fall "&$A10,'UNL Data'!$B$2:$B$1500,"Theta Xi")) -> 60 | F10: =IF(OR(E10="",E9=""),"",E10-E9) -> -11 | G10: =IFERROR(AVERAGEIFS('UNL Data'!$C$2:$C$1500,'UNL Data'!$A$2:$A$1500,"Fall "&$A10),"") -> 72.32
A11: 2024 | B11: =IF(OR(COUNTIFS('UNL Data'!$A$2:$A$1500,"Spring "&$A11,'UNL Data'!$B$2:$B$1500,"Theta Xi",'UNL Data'!$D$2:$D$1500,"<>")=0,COUNTIFS('UNL Data'!$A$2:$A$1500,"Fall "&$A11,'UNL Data'!$B$2:$B$1500,"Theta Xi",'UNL Data'!$D$2:$D$1500,"<>")=0),"",SUMIFS('UNL Data'!$D$2:$D$1500,'UNL Data'!$A$2:$A$1500,"Spring "&$A11,'UNL Data'!$B$2:$B$1500,"Theta Xi")+SUMIFS('UNL Data'!$D$2:$D$1500,'UNL Data'!$A$2:$A$1500,"Fall "&$A11,'UNL Data'!$B$2:$B$1500,"Theta Xi")) -> 17 | C11: =IFERROR(AVERAGEIFS('UNL Data'!$D$2:$D$1500,'UNL Data'!$A$2:$A$1500,"Spring "&$A11)+AVERAGEIFS('UNL Data'!$D$2:$D$1500,'UNL Data'!$A$2:$A$1500,"Fall "&$A11),"") -> 25.069231 | D11: =IF(OR(B11="",C11=""),"",B11/C11) -> 0.67812212 | E11: =IF(COUNTIFS('UNL Data'!$A$2:$A$1500,"Fall "&$A11,'UNL Data'!$B$2:$B$1500,"Theta Xi",'UNL Data'!$C$2:$C$1500,"<>")=0,"",SUMIFS('UNL Data'!$C$2:$C$1500,'UNL Data'!$A$2:$A$1500,"Fall "&$A11,'UNL Data'!$B$2:$B$1500,"Theta Xi")) -> 48 | F11: =IF(OR(E11="",E10=""),"",E11-E10) -> -12 | G11: =IFERROR(AVERAGEIFS('UNL Data'!$C$2:$C$1500,'UNL Data'!$A$2:$A$1500,"Fall "&$A11),"") -> 73.230769
A12: 2025 | B12: =IF(OR(COUNTIFS('UNL Data'!$A$2:$A$1500,"Spring "&$A12,'UNL Data'!$B$2:$B$1500,"Theta Xi",'UNL Data'!$D$2:$D$1500,"<>")=0,COUNTIFS('UNL Data'!$A$2:$A$1500,"Fall "&$A12,'UNL Data'!$B$2:$B$1500,"Theta Xi",'UNL Data'!$D$2:$D$1500,"<>")=0),"",SUMIFS('UNL Data'!$D$2:$D$1500,'UNL Data'!$A$2:$A$1500,"Spring "&$A12,'UNL Data'!$B$2:$B$1500,"Theta Xi")+SUMIFS('UNL Data'!$D$2:$D$1500,'UNL Data'!$A$2:$A$1500,"Fall "&$A12,'UNL Data'!$B$2:$B$1500,"Theta Xi")) -> 15 | C12: =IFERROR(AVERAGEIFS('UNL Data'!$D$2:$D$1500,'UNL Data'!$A$2:$A$1500,"Spring "&$A12)+AVERAGEIFS('UNL Data'!$D$2:$D$1500,'UNL Data'!$A$2:$A$1500,"Fall "&$A12),"") -> 26.831667 | D12: =IF(OR(B12="",C12=""),"",B12/C12) -> 0.55904093 | E12: =IF(COUNTIFS('UNL Data'!$A$2:$A$1500,"Fall "&$A12,'UNL Data'!$B$2:$B$1500,"Theta Xi",'UNL Data'!$C$2:$C$1500,"<>")=0,"",SUMIFS('UNL Data'!$C$2:$C$1500,'UNL Data'!$A$2:$A$1500,"Fall "&$A12,'UNL Data'!$B$2:$B$1500,"Theta Xi")) -> 44 | F12: =IF(OR(E12="",E11=""),"",E12-E11) -> -4 | G12: =IFERROR(AVERAGEIFS('UNL Data'!$C$2:$C$1500,'UNL Data'!$A$2:$A$1500,"Fall "&$A12),"") -> 79.2
A13: 2026 | B13: =IF(OR(COUNTIFS('UNL Data'!$A$2:$A$1500,"Spring "&$A13,'UNL Data'!$B$2:$B$1500,"Theta Xi",'UNL Data'!$D$2:$D$1500,"<>")=0,COUNTIFS('UNL Data'!$A$2:$A$1500,"Fall "&$A13,'UNL Data'!$B$2:$B$1500,"Theta Xi",'UNL Data'!$D$2:$D$1500,"<>")=0),"",SUMIFS('UNL Data'!$D$2:$D$1500,'UNL Data'!$A$2:$A$1500,"Spring "&$A13,'UNL Data'!$B$2:$B$1500,"Theta Xi")+SUMIFS('UNL Data'!$D$2:$D$1500,'UNL Data'!$A$2:$A$1500,"Fall "&$A13,'UNL Data'!$B$2:$B$1500,"Theta Xi")) | C13: =IFERROR(AVERAGEIFS('UNL Data'!$D$2:$D$1500,'UNL Data'!$A$2:$A$1500,"Spring "&$A13)+AVERAGEIFS('UNL Data'!$D$2:$D$1500,'UNL Data'!$A$2:$A$1500,"Fall "&$A13),"") | D13: =IF(OR(B13="",C13=""),"",B13/C13) | E13: =IF(COUNTIFS('UNL Data'!$A$2:$A$1500,"Fall "&$A13,'UNL Data'!$B$2:$B$1500,"Theta Xi",'UNL Data'!$C$2:$C$1500,"<>")=0,"",SUMIFS('UNL Data'!$C$2:$C$1500,'UNL Data'!$A$2:$A$1500,"Fall "&$A13,'UNL Data'!$B$2:$B$1500,"Theta Xi")) | F13: =IF(OR(E13="",E12=""),"",E13-E12) | G13: =IFERROR(AVERAGEIFS('UNL Data'!$C$2:$C$1500,'UNL Data'!$A$2:$A$1500,"Fall "&$A13),"")
A14: 2027 | B14: =IF(OR(COUNTIFS('UNL Data'!$A$2:$A$1500,"Spring "&$A14,'UNL Data'!$B$2:$B$1500,"Theta Xi",'UNL Data'!$D$2:$D$1500,"<>")=0,COUNTIFS('UNL Data'!$A$2:$A$1500,"Fall "&$A14,'UNL Data'!$B$2:$B$1500,"Theta Xi",'UNL Data'!$D$2:$D$1500,"<>")=0),"",SUMIFS('UNL Data'!$D$2:$D$1500,'UNL Data'!$A$2:$A$1500,"Spring "&$A14,'UNL Data'!$B$2:$B$1500,"Theta Xi")+SUMIFS('UNL Data'!$D$2:$D$1500,'UNL Data'!$A$2:$A$1500,"Fall "&$A14,'UNL Data'!$B$2:$B$1500,"Theta Xi")) | C14: =IFERROR(AVERAGEIFS('UNL Data'!$D$2:$D$1500,'UNL Data'!$A$2:$A$1500,"Spring "&$A14)+AVERAGEIFS('UNL Data'!$D$2:$D$1500,'UNL Data'!$A$2:$A$1500,"Fall "&$A14),"") | D14: =IF(OR(B14="",C14=""),"",B14/C14) | E14: =IF(COUNTIFS('UNL Data'!$A$2:$A$1500,"Fall "&$A14,'UNL Data'!$B$2:$B$1500,"Theta Xi",'UNL Data'!$C$2:$C$1500,"<>")=0,"",SUMIFS('UNL Data'!$C$2:$C$1500,'UNL Data'!$A$2:$A$1500,"Fall "&$A14,'UNL Data'!$B$2:$B$1500,"Theta Xi")) | F14: =IF(OR(E14="",E13=""),"",E14-E13) | G14: =IFERROR(AVERAGEIFS('UNL Data'!$C$2:$C$1500,'UNL Data'!$A$2:$A$1500,"Fall "&$A14),"")
A15: 2028 | B15: =IF(OR(COUNTIFS('UNL Data'!$A$2:$A$1500,"Spring "&$A15,'UNL Data'!$B$2:$B$1500,"Theta Xi",'UNL Data'!$D$2:$D$1500,"<>")=0,COUNTIFS('UNL Data'!$A$2:$A$1500,"Fall "&$A15,'UNL Data'!$B$2:$B$1500,"Theta Xi",'UNL Data'!$D$2:$D$1500,"<>")=0),"",SUMIFS('UNL Data'!$D$2:$D$1500,'UNL Data'!$A$2:$A$1500,"Spring "&$A15,'UNL Data'!$B$2:$B$1500,"Theta Xi")+SUMIFS('UNL Data'!$D$2:$D$1500,'UNL Data'!$A$2:$A$1500,"Fall "&$A15,'UNL Data'!$B$2:$B$1500,"Theta Xi")) | C15: =IFERROR(AVERAGEIFS('UNL Data'!$D$2:$D$1500,'UNL Data'!$A$2:$A$1500,"Spring "&$A15)+AVERAGEIFS('UNL Data'!$D$2:$D$1500,'UNL Data'!$A$2:$A$1500,"Fall "&$A15),"") | D15: =IF(OR(B15="",C15=""),"",B15/C15) | E15: =IF(COUNTIFS('UNL Data'!$A$2:$A$1500,"Fall "&$A15,'UNL Data'!$B$2:$B$1500,"Theta Xi",'UNL Data'!$C$2:$C$1500,"<>")=0,"",SUMIFS('UNL Data'!$C$2:$C$1500,'UNL Data'!$A$2:$A$1500,"Fall "&$A15,'UNL Data'!$B$2:$B$1500,"Theta Xi")) | F15: =IF(OR(E15="",E14=""),"",E15-E14) | G15: =IFERROR(AVERAGEIFS('UNL Data'!$C$2:$C$1500,'UNL Data'!$A$2:$A$1500,"Fall "&$A15),"")
A16: 2029 | B16: =IF(OR(COUNTIFS('UNL Data'!$A$2:$A$1500,"Spring "&$A16,'UNL Data'!$B$2:$B$1500,"Theta Xi",'UNL Data'!$D$2:$D$1500,"<>")=0,COUNTIFS('UNL Data'!$A$2:$A$1500,"Fall "&$A16,'UNL Data'!$B$2:$B$1500,"Theta Xi",'UNL Data'!$D$2:$D$1500,"<>")=0),"",SUMIFS('UNL Data'!$D$2:$D$1500,'UNL Data'!$A$2:$A$1500,"Spring "&$A16,'UNL Data'!$B$2:$B$1500,"Theta Xi")+SUMIFS('UNL Data'!$D$2:$D$1500,'UNL Data'!$A$2:$A$1500,"Fall "&$A16,'UNL Data'!$B$2:$B$1500,"Theta Xi")) | C16: =IFERROR(AVERAGEIFS('UNL Data'!$D$2:$D$1500,'UNL Data'!$A$2:$A$1500,"Spring "&$A16)+AVERAGEIFS('UNL Data'!$D$2:$D$1500,'UNL Data'!$A$2:$A$1500,"Fall "&$A16),"") | D16: =IF(OR(B16="",C16=""),"",B16/C16) | E16: =IF(COUNTIFS('UNL Data'!$A$2:$A$1500,"Fall "&$A16,'UNL Data'!$B$2:$B$1500,"Theta Xi",'UNL Data'!$C$2:$C$1500,"<>")=0,"",SUMIFS('UNL Data'!$C$2:$C$1500,'UNL Data'!$A$2:$A$1500,"Fall "&$A16,'UNL Data'!$B$2:$B$1500,"Theta Xi")) | F16: =IF(OR(E16="",E15=""),"",E16-E15) | G16: =IFERROR(AVERAGEIFS('UNL Data'!$C$2:$C$1500,'UNL Data'!$A$2:$A$1500,"Fall "&$A16),"")
A17: TX vs Avg House: 100% = recruited as many as the average IFC house. Blank = UNL left new members off one of that year's reports.

Sheet IFC Houses
A1: Every IFC House
A2: Change the two blue cells to look at a different semester or year.
A3: GPA and members for | C3: Spring 2026
A4: New members for year | C4: 2025
A6: House | C6: GPA | D6: GPA Rank | E6: Members | F6: New Members (Spring + Fall) | G6: New Member Rank
A7: Farmhouse | C7: =IF(COUNTIFS('UNL Data'!$A$2:$A$1500,$C$3,'UNL Data'!$B$2:$B$1500,$A7,'UNL Data'!$E$2:$E$1500,"<>")=0,"",SUMIFS('UNL Data'!$E$2:$E$1500,'UNL Data'!$A$2:$A$1500,$C$3,'UNL Data'!$B$2:$B$1500,$A7)) -> 3.683 | D7: =IF(C7="","",COUNTIF($C$7:$C$29,">"&C7)+1) -> 1 | E7: =IF(COUNTIFS('UNL Data'!$A$2:$A$1500,$C$3,'UNL Data'!$B$2:$B$1500,$A7,'UNL Data'!$C$2:$C$1500,"<>")=0,"",SUMIFS('UNL Data'!$C$2:$C$1500,'UNL Data'!$A$2:$A$1500,$C$3,'UNL Data'!$B$2:$B$1500,$A7)) -> 109 | F7: =IF(OR(COUNTIFS('UNL Data'!$A$2:$A$1500,"Spring "&$C$4,'UNL Data'!$B$2:$B$1500,$A7,'UNL Data'!$D$2:$D$1500,"<>")=0,COUNTIFS('UNL Data'!$A$2:$A$1500,"Fall "&$C$4,'UNL Data'!$B$2:$B$1500,$A7,'UNL Data'!$D$2:$D$1500,"<>")=0),"",SUMIFS('UNL Data'!$D$2:$D$1500,'UNL Data'!$A$2:$A$1500,"Spring "&$C$4,'UNL Data'!$B$2:$B$1500,$A7)+SUMIFS('UNL Data'!$D$2:$D$1500,'UNL Data'!$A$2:$A$1500,"Fall "&$C$4,'UNL Data'!$B$2:$B$1500,$A7)) -> 32 | G7: =IF(F7="","",COUNTIF($F$7:$F$29,">"&F7)+1) -> 11
A8: Sigma Phi Epsilon | C8: =IF(COUNTIFS('UNL Data'!$A$2:$A$1500,$C$3,'UNL Data'!$B$2:$B$1500,$A8,'UNL Data'!$E$2:$E$1500,"<>")=0,"",SUMIFS('UNL Data'!$E$2:$E$1500,'UNL Data'!$A$2:$A$1500,$C$3,'UNL Data'!$B$2:$B$1500,$A8)) -> 3.664 | D8: =IF(C8="","",COUNTIF($C$7:$C$29,">"&C8)+1) -> 2 | E8: =IF(COUNTIFS('UNL Data'!$A$2:$A$1500,$C$3,'UNL Data'!$B$2:$B$1500,$A8,'UNL Data'!$C$2:$C$1500,"<>")=0,"",SUMIFS('UNL Data'!$C$2:$C$1500,'UNL Data'!$A$2:$A$1500,$C$3,'UNL Data'!$B$2:$B$1500,$A8)) -> 155 | F8: =IF(OR(COUNTIFS('UNL Data'!$A$2:$A$1500,"Spring "&$C$4,'UNL Data'!$B$2:$B$1500,$A8,'UNL Data'!$D$2:$D$1500,"<>")=0,COUNTIFS('UNL Data'!$A$2:$A$1500,"Fall "&$C$4,'UNL Data'!$B$2:$B$1500,$A8,'UNL Data'!$D$2:$D$1500,"<>")=0),"",SUMIFS('UNL Data'!$D$2:$D$1500,'UNL Data'!$A$2:$A$1500,"Spring "&$C$4,'UNL Data'!$B$2:$B$1500,$A8)+SUMIFS('UNL Data'!$D$2:$D$1500,'UNL Data'!$A$2:$A$1500,"Fall "&$C$4,'UNL Data'!$B$2:$B$1500,$A8)) -> 45 | G8: =IF(F8="","",COUNTIF($F$7:$F$29,">"&F8)+1) -> 3
A9: Beta Theta Pi | C9: =IF(COUNTIFS('UNL Data'!$A$2:$A$1500,$C$3,'UNL Data'!$B$2:$B$1500,$A9,'UNL Data'!$E$2:$E$1500,"<>")=0,"",SUMIFS('UNL Data'!$E$2:$E$1500,'UNL Data'!$A$2:$A$1500,$C$3,'UNL Data'!$B$2:$B$1500,$A9)) -> 3.607 | D9: =IF(C9="","",COUNTIF($C$7:$C$29,">"&C9)+1) -> 3 | E9: =IF(COUNTIFS('UNL Data'!$A$2:$A$1500,$C$3,'UNL Data'!$B$2:$B$1500,$A9,'UNL Data'!$C$2:$C$1500,"<>")=0,"",SUMIFS('UNL Data'!$C$2:$C$1500,'UNL Data'!$A$2:$A$1500,$C$3,'UNL Data'!$B$2:$B$1500,$A9)) -> 119 | F9: =IF(OR(COUNTIFS('UNL Data'!$A$2:$A$1500,"Spring "&$C$4,'UNL Data'!$B$2:$B$1500,$A9,'UNL Data'!$D$2:$D$1500,"<>")=0,COUNTIFS('UNL Data'!$A$2:$A$1500,"Fall "&$C$4,'UNL Data'!$B$2:$B$1500,$A9,'UNL Data'!$D$2:$D$1500,"<>")=0),"",SUMIFS('UNL Data'!$D$2:$D$1500,'UNL Data'!$A$2:$A$1500,"Spring "&$C$4,'UNL Data'!$B$2:$B$1500,$A9)+SUMIFS('UNL Data'!$D$2:$D$1500,'UNL Data'!$A$2:$A$1500,"Fall "&$C$4,'UNL Data'!$B$2:$B$1500,$A9)) -> 34 | G9: =IF(F9="","",COUNTIF($F$7:$F$29,">"&F9)+1) -> 10
A10: Pi Kappa Alpha | C10: =IF(COUNTIFS('UNL Data'!$A$2:$A$1500,$C$3,'UNL Data'!$B$2:$B$1500,$A10,'UNL Data'!$E$2:$E$1500,"<>")=0,"",SUMIFS('UNL Data'!$E$2:$E$1500,'UNL Data'!$A$2:$A$1500,$C$3,'UNL Data'!$B$2:$B$1500,$A10)) -> 3.577 | D10: =IF(C10="","",COUNTIF($C$7:$C$29,">"&C10)+1) -> 4 | E10: =IF(COUNTIFS('UNL Data'!$A$2:$A$1500,$C$3,'UNL Data'!$B$2:$B$1500,$A10,'UNL Data'!$C$2:$C$1500,"<>")=0,"",SUMIFS('UNL Data'!$C$2:$C$1500,'UNL Data'!$A$2:$A$1500,$C$3,'UNL Data'!$B$2:$B$1500,$A10)) -> 165 | F10: =IF(OR(COUNTIFS('UNL Data'!$A$2:$A$1500,"Spring "&$C$4,'UNL Data'!$B$2:$B$1500,$A10,'UNL Data'!$D$2:$D$1500,"<>")=0,COUNTIFS('UNL Data'!$A$2:$A$1500,"Fall "&$C$4,'UNL Data'!$B$2:$B$1500,$A10,'UNL Data'!$D$2:$D$1500,"<>")=0),"",SUMIFS('UNL Data'!$D$2:$D$1500,'UNL Data'!$A$2:$A$1500,"Spring "&$C$4,'UNL Data'!$B$2:$B$1500,$A10)+SUMIFS('UNL Data'!$D$2:$D$1500,'UNL Data'!$A$2:$A$1500,"Fall "&$C$4,'UNL Data'!$B$2:$B$1500,$A10)) -> 52 | G10: =IF(F10="","",COUNTIF($F$7:$F$29,">"&F10)+1) -> 1
A11: Phi Gamma Delta | C11: =IF(COUNTIFS('UNL Data'!$A$2:$A$1500,$C$3,'UNL Data'!$B$2:$B$1500,$A11,'UNL Data'!$E$2:$E$1500,"<>")=0,"",SUMIFS('UNL Data'!$E$2:$E$1500,'UNL Data'!$A$2:$A$1500,$C$3,'UNL Data'!$B$2:$B$1500,$A11)) -> 3.509 | D11: =IF(C11="","",COUNTIF($C$7:$C$29,">"&C11)+1) -> 5 | E11: =IF(COUNTIFS('UNL Data'!$A$2:$A$1500,$C$3,'UNL Data'!$B$2:$B$1500,$A11,'UNL Data'!$C$2:$C$1500,"<>")=0,"",SUMIFS('UNL Data'!$C$2:$C$1500,'UNL Data'!$A$2:$A$1500,$C$3,'UNL Data'!$B$2:$B$1500,$A11)) -> 14 | F11: =IF(OR(COUNTIFS('UNL Data'!$A$2:$A$1500,"Spring "&$C$4,'UNL Data'!$B$2:$B$1500,$A11,'UNL Data'!$D$2:$D$1500,"<>")=0,COUNTIFS('UNL Data'!$A$2:$A$1500,"Fall "&$C$4,'UNL Data'!$B$2:$B$1500,$A11,'UNL Data'!$D$2:$D$1500,"<>")=0),"",SUMIFS('UNL Data'!$D$2:$D$1500,'UNL Data'!$A$2:$A$1500,"Spring "&$C$4,'UNL Data'!$B$2:$B$1500,$A11)+SUMIFS('UNL Data'!$D$2:$D$1500,'UNL Data'!$A$2:$A$1500,"Fall "&$C$4,'UNL Data'!$B$2:$B$1500,$A11)) | G11: =IF(F11="","",COUNTIF($F$7:$F$29,">"&F11)+1)
A12: Beta Sigma Psi | C12: =IF(COUNTIFS('UNL Data'!$A$2:$A$1500,$C$3,'UNL Data'!$B$2:$B$1500,$A12,'UNL Data'!$E$2:$E$1500,"<>")=0,"",SUMIFS('UNL Data'!$E$2:$E$1500,'UNL Data'!$A$2:$A$1500,$C$3,'UNL Data'!$B$2:$B$1500,$A12)) -> 3.494 | D12: =IF(C12="","",COUNTIF($C$7:$C$29,">"&C12)+1) -> 6 | E12: =IF(COUNTIFS('UNL Data'!$A$2:$A$1500,$C$3,'UNL Data'!$B$2:$B$1500,$A12,'UNL Data'!$C$2:$C$1500,"<>")=0,"",SUMIFS('UNL Data'!$C$2:$C$1500,'UNL Data'!$A$2:$A$1500,$C$3,'UNL Data'!$B$2:$B$1500,$A12)) -> 15 | F12: =IF(OR(COUNTIFS('UNL Data'!$A$2:$A$1500,"Spring "&$C$4,'UNL Data'!$B$2:$B$1500,$A12,'UNL Data'!$D$2:$D$1500,"<>")=0,COUNTIFS('UNL Data'!$A$2:$A$1500,"Fall "&$C$4,'UNL Data'!$B$2:$B$1500,$A12,'UNL Data'!$D$2:$D$1500,"<>")=0),"",SUMIFS('UNL Data'!$D$2:$D$1500,'UNL Data'!$A$2:$A$1500,"Spring "&$C$4,'UNL Data'!$B$2:$B$1500,$A12)+SUMIFS('UNL Data'!$D$2:$D$1500,'UNL Data'!$A$2:$A$1500,"Fall "&$C$4,'UNL Data'!$B$2:$B$1500,$A12)) -> 4 | G12: =IF(F12="","",COUNTIF($F$7:$F$29,">"&F12)+1) -> 22
A13: Sigma Chi | C13: =IF(COUNTIFS('UNL Data'!$A$2:$A$1500,$C$3,'UNL Data'!$B$2:$B$1500,$A13,'UNL Data'!$E$2:$E$1500,"<>")=0,"",SUMIFS('UNL Data'!$E$2:$E$1500,'UNL Data'!$A$2:$A$1500,$C$3,'UNL Data'!$B$2:$B$1500,$A13)) -> 3.464 | D13: =IF(C13="","",COUNTIF($C$7:$C$29,">"&C13)+1) -> 7 | E13: =IF(COUNTIFS('UNL Data'!$A$2:$A$1500,$C$3,'UNL Data'!$B$2:$B$1500,$A13,'UNL Data'!$C$2:$C$1500,"<>")=0,"",SUMIFS('UNL Data'!$C$2:$C$1500,'UNL Data'!$A$2:$A$1500,$C$3,'UNL Data'!$B$2:$B$1500,$A13)) -> 112 | F13: =IF(OR(COUNTIFS('UNL Data'!$A$2:$A$1500,"Spring "&$C$4,'UNL Data'!$B$2:$B$1500,$A13,'UNL Data'!$D$2:$D$1500,"<>")=0,COUNTIFS('UNL Data'!$A$2:$A$1500,"Fall "&$C$4,'UNL Data'!$B$2:$B$1500,$A13,'UNL Data'!$D$2:$D$1500,"<>")=0),"",SUMIFS('UNL Data'!$D$2:$D$1500,'UNL Data'!$A$2:$A$1500,"Spring "&$C$4,'UNL Data'!$B$2:$B$1500,$A13)+SUMIFS('UNL Data'!$D$2:$D$1500,'UNL Data'!$A$2:$A$1500,"Fall "&$C$4,'UNL Data'!$B$2:$B$1500,$A13)) -> 47 | G13: =IF(F13="","",COUNTIF($F$7:$F$29,">"&F13)+1) -> 2
A14: Alpha Gamma Sigma | C14: =IF(COUNTIFS('UNL Data'!$A$2:$A$1500,$C$3,'UNL Data'!$B$2:$B$1500,$A14,'UNL Data'!$E$2:$E$1500,"<>")=0,"",SUMIFS('UNL Data'!$E$2:$E$1500,'UNL Data'!$A$2:$A$1500,$C$3,'UNL Data'!$B$2:$B$1500,$A14)) -> 3.454 | D14: =IF(C14="","",COUNTIF($C$7:$C$29,">"&C14)+1) -> 8 | E14: =IF(COUNTIFS('UNL Data'!$A$2:$A$1500,$C$3,'UNL Data'!$B$2:$B$1500,$A14,'UNL Data'!$C$2:$C$1500,"<>")=0,"",SUMIFS('UNL Data'!$C$2:$C$1500,'UNL Data'!$A$2:$A$1500,$C$3,'UNL Data'!$B$2:$B$1500,$A14)) -> 88 | F14: =IF(OR(COUNTIFS('UNL Data'!$A$2:$A$1500,"Spring "&$C$4,'UNL Data'!$B$2:$B$1500,$A14,'UNL Data'!$D$2:$D$1500,"<>")=0,COUNTIFS('UNL Data'!$A$2:$A$1500,"Fall "&$C$4,'UNL Data'!$B$2:$B$1500,$A14,'UNL Data'!$D$2:$D$1500,"<>")=0),"",SUMIFS('UNL Data'!$D$2:$D$1500,'UNL Data'!$A$2:$A$1500,"Spring "&$C$4,'UNL Data'!$B$2:$B$1500,$A14)+SUMIFS('UNL Data'!$D$2:$D$1500,'UNL Data'!$A$2:$A$1500,"Fall "&$C$4,'UNL Data'!$B$2:$B$1500,$A14)) -> 37 | G14: =IF(F14="","",COUNTIF($F$7:$F$29,">"&F14)+1) -> 7
A15: Phi Delta Theta | C15: =IF(COUNTIFS('UNL Data'!$A$2:$A$1500,$C$3,'UNL Data'!$B$2:$B$1500,$A15,'UNL Data'!$E$2:$E$1500,"<>")=0,"",SUMIFS('UNL Data'!$E$2:$E$1500,'UNL Data'!$A$2:$A$1500,$C$3,'UNL Data'!$B$2:$B$1500,$A15)) -> 3.427 | D15: =IF(C15="","",COUNTIF($C$7:$C$29,">"&C15)+1) -> 9 | E15: =IF(COUNTIFS('UNL Data'!$A$2:$A$1500,$C$3,'UNL Data'!$B$2:$B$1500,$A15,'UNL Data'!$C$2:$C$1500,"<>")=0,"",SUMIFS('UNL Data'!$C$2:$C$1500,'UNL Data'!$A$2:$A$1500,$C$3,'UNL Data'!$B$2:$B$1500,$A15)) -> 127 | F15: =IF(OR(COUNTIFS('UNL Data'!$A$2:$A$1500,"Spring "&$C$4,'UNL Data'!$B$2:$B$1500,$A15,'UNL Data'!$D$2:$D$1500,"<>")=0,COUNTIFS('UNL Data'!$A$2:$A$1500,"Fall "&$C$4,'UNL Data'!$B$2:$B$1500,$A15,'UNL Data'!$D$2:$D$1500,"<>")=0),"",SUMIFS('UNL Data'!$D$2:$D$1500,'UNL Data'!$A$2:$A$1500,"Spring "&$C$4,'UNL Data'!$B$2:$B$1500,$A15)+SUMIFS('UNL Data'!$D$2:$D$1500,'UNL Data'!$A$2:$A$1500,"Fall "&$C$4,'UNL Data'!$B$2:$B$1500,$A15)) -> 38 | G15: =IF(F15="","",COUNTIF($F$7:$F$29,">"&F15)+1) -> 6
A16: Alpha Gamma Rho | C16: =IF(COUNTIFS('UNL Data'!$A$2:$A$1500,$C$3,'UNL Data'!$B$2:$B$1500,$A16,'UNL Data'!$E$2:$E$1500,"<>")=0,"",SUMIFS('UNL Data'!$E$2:$E$1500,'UNL Data'!$A$2:$A$1500,$C$3,'UNL Data'!$B$2:$B$1500,$A16)) -> 3.421 | D16: =IF(C16="","",COUNTIF($C$7:$C$29,">"&C16)+1) -> 10 | E16: =IF(COUNTIFS('UNL Data'!$A$2:$A$1500,$C$3,'UNL Data'!$B$2:$B$1500,$A16,'UNL Data'!$C$2:$C$1500,"<>")=0,"",SUMIFS('UNL Data'!$C$2:$C$1500,'UNL Data'!$A$2:$A$1500,$C$3,'UNL Data'!$B$2:$B$1500,$A16)) -> 92 | F16: =IF(OR(COUNTIFS('UNL Data'!$A$2:$A$1500,"Spring "&$C$4,'UNL Data'!$B$2:$B$1500,$A16,'UNL Data'!$D$2:$D$1500,"<>")=0,COUNTIFS('UNL Data'!$A$2:$A$1500,"Fall "&$C$4,'UNL Data'!$B$2:$B$1500,$A16,'UNL Data'!$D$2:$D$1500,"<>")=0),"",SUMIFS('UNL Data'!$D$2:$D$1500,'UNL Data'!$A$2:$A$1500,"Spring "&$C$4,'UNL Data'!$B$2:$B$1500,$A16)+SUMIFS('UNL Data'!$D$2:$D$1500,'UNL Data'!$A$2:$A$1500,"Fall "&$C$4,'UNL Data'!$B$2:$B$1500,$A16)) -> 29 | G16: =IF(F16="","",COUNTIF($F$7:$F$29,">"&F16)+1) -> 13
A17: Sigma Alpha Mu | C17: =IF(COUNTIFS('UNL Data'!$A$2:$A$1500,$C$3,'UNL Data'!$B$2:$B$1500,$A17,'UNL Data'!$E$2:$E$1500,"<>")=0,"",SUMIFS('UNL Data'!$E$2:$E$1500,'UNL Data'!$A$2:$A$1500,$C$3,'UNL Data'!$B$2:$B$1500,$A17)) -> 3.376 | D17: =IF(C17="","",COUNTIF($C$7:$C$29,">"&C17)+1) -> 11 | E17: =IF(COUNTIFS('UNL Data'!$A$2:$A$1500,$C$3,'UNL Data'!$B$2:$B$1500,$A17,'UNL Data'!$C$2:$C$1500,"<>")=0,"",SUMIFS('UNL Data'!$C$2:$C$1500,'UNL Data'!$A$2:$A$1500,$C$3,'UNL Data'!$B$2:$B$1500,$A17)) -> 9 | F17: =IF(OR(COUNTIFS('UNL Data'!$A$2:$A$1500,"Spring "&$C$4,'UNL Data'!$B$2:$B$1500,$A17,'UNL Data'!$D$2:$D$1500,"<>")=0,COUNTIFS('UNL Data'!$A$2:$A$1500,"Fall "&$C$4,'UNL Data'!$B$2:$B$1500,$A17,'UNL Data'!$D$2:$D$1500,"<>")=0),"",SUMIFS('UNL Data'!$D$2:$D$1500,'UNL Data'!$A$2:$A$1500,"Spring "&$C$4,'UNL Data'!$B$2:$B$1500,$A17)+SUMIFS('UNL Data'!$D$2:$D$1500,'UNL Data'!$A$2:$A$1500,"Fall "&$C$4,'UNL Data'!$B$2:$B$1500,$A17)) -> 5 | G17: =IF(F17="","",COUNTIF($F$7:$F$29,">"&F17)+1) -> 20
A18: Phi Kappa Theta | C18: =IF(COUNTIFS('UNL Data'!$A$2:$A$1500,$C$3,'UNL Data'!$B$2:$B$1500,$A18,'UNL Data'!$E$2:$E$1500,"<>")=0,"",SUMIFS('UNL Data'!$E$2:$E$1500,'UNL Data'!$A$2:$A$1500,$C$3,'UNL Data'!$B$2:$B$1500,$A18)) -> 3.351 | D18: =IF(C18="","",COUNTIF($C$7:$C$29,">"&C18)+1) -> 12 | E18: =IF(COUNTIFS('UNL Data'!$A$2:$A$1500,$C$3,'UNL Data'!$B$2:$B$1500,$A18,'UNL Data'!$C$2:$C$1500,"<>")=0,"",SUMIFS('UNL Data'!$C$2:$C$1500,'UNL Data'!$A$2:$A$1500,$C$3,'UNL Data'!$B$2:$B$1500,$A18)) -> 95 | F18: =IF(OR(COUNTIFS('UNL Data'!$A$2:$A$1500,"Spring "&$C$4,'UNL Data'!$B$2:$B$1500,$A18,'UNL Data'!$D$2:$D$1500,"<>")=0,COUNTIFS('UNL Data'!$A$2:$A$1500,"Fall "&$C$4,'UNL Data'!$B$2:$B$1500,$A18,'UNL Data'!$D$2:$D$1500,"<>")=0),"",SUMIFS('UNL Data'!$D$2:$D$1500,'UNL Data'!$A$2:$A$1500,"Spring "&$C$4,'UNL Data'!$B$2:$B$1500,$A18)+SUMIFS('UNL Data'!$D$2:$D$1500,'UNL Data'!$A$2:$A$1500,"Fall "&$C$4,'UNL Data'!$B$2:$B$1500,$A18)) -> 35 | G18: =IF(F18="","",COUNTIF($F$7:$F$29,">"&F18)+1) -> 9
... A29: Chi Phi | C29: =IF(COUNTIFS('UNL Data'!$A$2:$A$1500,$C$3,'UNL Data'!$B$2:$B$1500,$A29,'UNL Data'!$E$2:$E$1500,"<>")=0,"",SUMIFS('UNL Data'!$E$2:$E$1500,'UNL Data'!$A$2:$A$1500,$C$3,'UNL Data'!$B$2:$B$1500,$A29)) -> 2.687 | D29: =IF(C29="","",COUNTIF($C$7:$C$29,">"&C29)+1) -> 23 | E29: =IF(COUNTIFS('UNL Data'!$A$2:$A$1500,$C$3,'UNL Data'!$B$2:$B$1500,$A29,'UNL Data'!$C$2:$C$1500,"<>")=0,"",SUMIFS('UNL Data'!$C$2:$C$1500,'UNL Data'!$A$2:$A$1500,$C$3,'UNL Data'!$B$2:$B$1500,$A29)) -> 15 | F29: =IF(OR(COUNTIFS('UNL Data'!$A$2:$A$1500,"Spring "&$C$4,'UNL Data'!$B$2:$B$1500,$A29,'UNL Data'!$D$2:$D$1500,"<>")=0,COUNTIFS('UNL Data'!$A$2:$A$1500,"Fall "&$C$4,'UNL Data'!$B$2:$B$1500,$A29,'UNL Data'!$D$2:$D$1500,"<>")=0),"",SUMIFS('UNL Data'!$D$2:$D$1500,'UNL Data'!$A$2:$A$1500,"Spring "&$C$4,'UNL Data'!$B$2:$B$1500,$A29)+SUMIFS('UNL Data'!$D$2:$D$1500,'UNL Data'!$A$2:$A$1500,"Fall "&$C$4,'UNL Data'!$B$2:$B$1500,$A29)) -> 5 | G29: =IF(F29="","",COUNTIF($F$7:$F$29,">"&F29)+1) -> 20
A31: Houses listed are the IFC houses on the Spring 2026 report, sorted by Spring 2026 GPA.

Sheet UNL Data
A1: Semester | B1: House | C1: Members | D1: New Members | E1: GPA | G1: IFC houses only, straight from UNL's semester report cards and scorecards.
A2: Fall 2018 | B2: Acacia | C2: 28 | D2: 12 | E2: 2.946 | G2: Fall 2023 has no scorecard, so it comes from UNL's grade report (no new-member counts).
A3: Fall 2018 | B3: Alpha Gamma Nu | C3: 47 | D3: 12 | E3: 2.964 | G3: Spring 2020 has no GPAs (pass/no-pass semester). Spring 2020 and Spring 2022 have no new-member counts.
A4: Fall 2018 | B4: Alpha Gamma Rho | C4: 96 | D4: 31 | E4: 3.121 | G4: To add a semester, paste the IFC rows at the bottom.
A5: Fall 2018 | B5: Alpha Gamma Sigma | C5: 83 | D5: 23 | E5: 3.057
A6: Fall 2018 | B6: Alpha Tau Omega | C6: 71 | D6: 32 | E6: 3.074
A7: Fall 2018 | B7: Beta Sigma Psi | C7: 23 | D7: 6 | E7: 3.327
A8: Fall 2018 | B8: Beta Theta Pi | C8: 112 | D8: 32 | E8: 3.426
A9: Fall 2018 | B9: Chi Phi | C9: 15 | D9: 3 | E9: 2.742
A10: Fall 2018 | B10: Delta Tau Delta
A11: Fall 2018 | B11: Delta Upsilon | C11: 113 | D11: 41 | E11: 3.153
A12: Fall 2018 | B12: Farmhouse | C12: 95 | D12: 28 | E12: 3.508
A13: Fall 2018 | B13: Kappa Sigma | C13: 61 | D13: 9 | E13: 2.677
A14: Fall 2018 | B14: Phi Delta Theta | C14: 114 | D14: 33 | E14: 3.292
A15: Fall 2018 | B15: Phi Gamma Delta
A16: Fall 2018 | B16: Phi Kappa Psi | C16: 31 | D16: 15 | E16: 3.043
A17: Fall 2018 | B17: Phi Kappa Theta | C17: 77 | D17: 27 | E17: 3.255
A18: Fall 2018 | B18: Pi Kappa Alpha | C18: 111 | D18: 24 | E18: 3.387
A19: Fall 2018 | B19: Pi Kappa Phi | C19: 56 | D19: 11 | E19: 3.149
A20: Fall 2018 | B20: Sigma Alpha Epsilon | C20: 128 | D20: 33 | E20: 2.983
A21: Fall 2018 | B21: Sigma Alpha Mu | C21: 12 | D21: 4 | E21: 3.162
A22: Fall 2018 | B22: Sigma Chi | C22: 76 | D22: 23 | E22: 3.15
A23: Fall 2018 | B23: Sigma Nu | C23: 36 | D23: 10 | E23: 2.927
A24: Fall 2018 | B24: Sigma Phi Epsilon | C24: 130 | D24: 43 | E24: 3.437
A25: Fall 2018 | B25: Tau Kappa Epsilon | C25: 28 | D25: 1 | E25: 2.941
A26: Fall 2018 | B26: Theta Chi | C26: 18 | D26: 0 | E26: 2.489
A27: Fall 2018 | B27: Theta Xi | C27: 62 | D27: 22 | E27: 2.733
... A36: Spring 2019 | B36: Chi Phi | C36: 15 | D36: 0 | E36: 2.772
A37: Spring 2019 | B37: Delta Tau Delta
A38: Spring 2019 | B38: Delta Upsilon | C38: 105 | D38: 1 | E38: 3.147
A39: Spring 2019 | B39: Farmhouse | C39: 90 | D39: 0 | E39: 3.466
A40: Spring 2019 | B40: Kappa Sigma | C40: 57 | D40: 7 | E40: 2.806
A41: Spring 2019 | B41: Phi Delta Theta | C41: 112 | D41: 1 | E41: 3.256
A42: Spring 2019 | B42: Phi Gamma Delta
A43: Spring 2019 | B43: Phi Kappa Psi | C43: 34 | D43: 3 | E43: 2.936
A44: Spring 2019 | B44: Phi Kappa Theta | C44: 76 | D44: 0 | E44: 3.42
A45: Spring 2019 | B45: Pi Kappa Alpha | C45: 132 | D45: 21 | E45: 3.355
A46: Spring 2019 | B46: Pi Kappa Phi | C46: 55 | D46: 2 | E46: 3.05
A47: Spring 2019 | B47: Sigma Alpha Epsilon | C47: 130 | D47: 0 | E47: 3.007
A48: Spring 2019 | B48: Sigma Alpha Mu | C48: 12 | D48: 0 | E48: 3.114
...

Sheet UNL Averages
A1: Semester | B1: All UNL Men | C1: All Greek Men | D1: All UNL Students | F1: From UNL's All-Community Grade Report each semester.
A2: Fall 2018 | B2: 2.976 | C2: 3.149 | D2: 3.106
A3: Spring 2019 | B3: 3.012 | C3: 3.154 | D3: 3.149
A4: Fall 2019 | B4: 3.032 | C4: 3.133 | D4: 3.152
A5: Spring 2020 | B5: 3.365 | C5: 3.439 | D5: 3.439
A6: Fall 2020 | B6: 3.032 | C6: 3.213 | D6: 3.12
A7: Spring 2021 | B7: 3.187 | C7: 3.307 | D7: 3.288
A8: Fall 2021 | B8: 3.084 | C8: 3.221 | D8: 3.189
A9: Spring 2022 | B9: 3.161 | C9: 3.29 | D9: 3.253
A10: Fall 2022 | B10: 3.131 | C10: 3.265 | D10: 3.24
A11: Spring 2023 | B11: 3.198 | C11: 3.337 | D11: 3.296
A12: Fall 2023 | B12: 3.132 | C12: 3.257 | D12: 3.241
A13: Spring 2024 | B13: 3.208 | C13: 3.328 | D13: 3.305
... A17: Spring 2026 | B17: 3.226 | C17: 3.384 | D17: 3.27
