Workbook

Sheet Read Me
A1: Theta Xi vs UNL fraternities: GPA and recruitment
A3: What this is
A4: Purpose | B4: Compares Theta Xi (UNL) with every other IFC house on grades and recruitment. Every house is covered semester by semester from Fall 2018, and our own history goes back to 2010. It replaces the multi-university GPA Data.xlsx and the recruitment index in AE List.xlsx, both kept in legacy/.
A5: Our chapter | B5: Set on the Lists tab (yellow cell). Type any IFC house name there and every tab recalculates for that house.
A7: Tabs
A8: Summary | B8: Latest-semester snapshot, calendar-year recruitment, combined ranks, targets and the written evaluation.
A9: TX vs IFC | B9: One row per semester: GPA, size, new members and retention against the IFC, with charts.
A10: Combined Score | B10: Every IFC house over a window you choose. GPA and recruitment are scored as percentiles and blended with weights you set.
A11: Recruitment Index | B11: Recruitment Index v2 by calendar year (Spring + Fall, one exec term): recruiting, size-adjusted, replacement and growth vs the IFC.
A12: GPA / Members / New Members Matrix | B12: Every IFC house by semester, with IFC averages, medians and our rank at the bottom.
A13: TX History | B13: Our GPA and size since 2010 against the campus benchmarks, plus pledge-class retention.
A14: Chapter Data | B14: The raw numbers from UNL's reports: one row per chapter per semester, all four councils.
A15: Campus Stats | B15: All-UNL GPAs by group (men, women, Greek, non-Greek).
A16: IFC Size (legacy) | B16: Average IFC chapter size before 2018, from AE List.xlsx.
A17: Lists | B17: Semester order, IFC chapter list and settings.
A18: Old Index Review | B18: What was off in the old recruitment score and GPA math, and what v2 does instead.
A20: Adding a new semester
A21: 1. Chapter Data | B21: Paste the new scorecard's rows at the bottom (Semester, Council, Chapter, Total Members, New Members, GPA, ranks, retention). Type the semester exactly like 'Fall 2026', and spell chapters the way the Lists tab does (for example 'Farmhouse'). Column B fills itself in. Formulas read rows 2 to 2500.
A22: 2. New chapters | B22: If a new IFC house appears, add it to column D on the Lists tab. The matrices and Combined Score have five spare rows for new houses.
A23: 3. Campus Stats | B23: Type in the all-campus GPAs from UNL's All-Community Grade Report (fsl.unl.edu, Councils & Chapters page, Academic Reports).
A24: 4. Settings | B24: Update 'Latest semester' on the Lists tab, the recruitment year on Summary and the window on Combined Score. Then reread the written evaluation on Summary, since it does not update itself.
A25: Room to grow | B25: Semesters are set up through Spring 2028. To go further, add semesters to Lists column A, add rows to Campus Stats, copy the last column of each matrix one to the right, and extend the TX vs IFC and Recruitment Index rows.
A27: Definitions
A28: GPA | B28: The term GPA printed on UNL's report. 'IFC average' is weighted by members, so it equals the GPA of all IFC men. 'IFC median' is the middle house.
A29: New members | B29: As printed by UNL. Scorecards from 2024 on say 'new members initiated', so pledges who dropped before initiation are not counted. Spring classes are small for every house.
A30: Calendar year | B30: Spring + Fall of the same year. This matches the exec term: elected in November, trained in December, running recruitment from January.
A31: Indexes | B31: 100 = matches the benchmark, 150 = 50% better, 50 = half as good.
A32: Percentiles | B32: Among IFC houses in the Combined Score window. 100% = best, 0% = worst.
A34: Sources and gaps
A35: Reports | B35: UNL IFC report cards for Fall 2018 to Fall 2022, Community Scorecards for Spring 2023 to Spring 2026, and the Fall 2023 All-Community Grade Report, all in source-data/. The data is also kept as a CSV in data/.
A36: Campus GPAs | B36: UNL All-Community Grade Reports (the UNL tab of GPA Data.xlsx through Spring 2024, then the Spring 2025, Fall 2025 and Spring 2026 reports).
A37: Missing | B37: Fall 2023 new-member counts (no scorecard that term). GPAs for Spring 2020 (pass/no-pass semester). New-member counts for Spring 2020 and Spring 2022. The Sigma Tau Gamma row in Fall 2022, which is blacked out on the PDF.
A38: Chapter records | B38: Theta Xi numbers before Fall 2018 come from AE List.xlsx and GPA Data.xlsx. From Fall 2018 on, only UNL's numbers are used so every house is measured the same way. Where our records differ, the Chapter Data notes say so.
A40: Color key
A41: Blue text | B41: typed-in data
A42: Black text | B42: formula
A43: Green text | B43: formula that pulls from another tab
A44: Yellow fill | B44: setting you can change
A45: Orange fill | B45: number missing from the repo; fill it in when you find it
A46: Light gold row | B46: our chapter (set on the Lists tab)

Sheet Summary
A1: =OurChapter&" at UNL: GPA and recruitment compared with the other IFC houses" -> Theta Xi at UNL: GPA and recruitment compared with the other IFC houses
A2: The tables are live formulas. The written evaluation below them was written from data through Spring 2026.
A4: Latest semester | B4: =LatestTerm -> Spring 2026
A5: Recruitment year to show (calendar year) | B5: 2025 | C5: Pick the last year with both a Spring and a Fall report.
A7: Latest semester | B7: Us | C7: IFC benchmark | D7: Our IFC rank | E7: Houses ranked
A8: Chapter GPA (benchmark = IFC average, member weighted) | B8: =IFERROR(INDEX('TX vs IFC'!$B$5:$B$24,MATCH(LatestTerm,'TX vs IFC'!$A$5:$A$24,0)),"") -> 3.163 | C8: =IFERROR(INDEX('TX vs IFC'!$C$5:$C$24,MATCH(LatestTerm,'TX vs IFC'!$A$5:$A$24,0)),"") -> 3.3919755 | D8: =IFERROR(INDEX('TX vs IFC'!$H$5:$H$24,MATCH(LatestTerm,'TX vs IFC'!$A$5:$A$24,0)),"") -> 17 | E8: =IFERROR(INDEX('TX vs IFC'!$I$5:$I$24,MATCH(LatestTerm,'TX vs IFC'!$A$5:$A$24,0)),"") -> 23
A9: Members (benchmark = IFC median house) | B9: =IFERROR(INDEX('TX vs IFC'!$K$5:$K$24,MATCH(LatestTerm,'TX vs IFC'!$A$5:$A$24,0)),"") -> 43 | C9: =IFERROR(INDEX('TX vs IFC'!$L$5:$L$24,MATCH(LatestTerm,'TX vs IFC'!$A$5:$A$24,0)),"") -> 78 | D9: =IFERROR(INDEX('TX vs IFC'!$M$5:$M$24,MATCH(LatestTerm,'TX vs IFC'!$A$5:$A$24,0)),"") -> 14 | E9: =IFERROR(INDEX('TX vs IFC'!$I$5:$I$24,MATCH(LatestTerm,'TX vs IFC'!$A$5:$A$24,0)),"") -> 23
A10: New members this semester (benchmark = IFC average house) | B10: =IFERROR(INDEX('TX vs IFC'!$O$5:$O$24,MATCH(LatestTerm,'TX vs IFC'!$A$5:$A$24,0)),"") -> 6 | C10: =IFERROR(INDEX('TX vs IFC'!$P$5:$P$24,MATCH(LatestTerm,'TX vs IFC'!$A$5:$A$24,0)),"") -> 4.1304348 | D10: =IFERROR(INDEX('TX vs IFC'!$R$5:$R$24,MATCH(LatestTerm,'TX vs IFC'!$A$5:$A$24,0)),"") -> 5 | E10: =IFERROR(INDEX('TX vs IFC'!$I$5:$I$24,MATCH(LatestTerm,'TX vs IFC'!$A$5:$A$24,0)),"") -> 23
A11: New-member retention (benchmark = IFC median) | B11: =IFERROR(INDEX('TX vs IFC'!$U$5:$U$24,MATCH(LatestTerm,'TX vs IFC'!$A$5:$A$24,0)),"") -> 1 | C11: =IFERROR(INDEX('TX vs IFC'!$V$5:$V$24,MATCH(LatestTerm,'TX vs IFC'!$A$5:$A$24,0)),"") -> 1
A13: Recruitment for the chosen calendar year | B13: Us | C13: Benchmark
A14: New members (Spring + Fall) vs the average IFC house | B14: =IFERROR(INDEX('Recruitment Index'!$I$5:$I$14,MATCH($B$5,'Recruitment Index'!$A$5:$A$14,0)),"") -> 15 | C14: =IFERROR(INDEX('Recruitment Index'!$J$5:$J$14,MATCH($B$5,'Recruitment Index'!$A$5:$A$14,0)),"") -> 26.831667
A15: Recruiting index (100 = average IFC house) | B15: =IFERROR(INDEX('Recruitment Index'!$D$5:$D$14,MATCH($B$5,'Recruitment Index'!$A$5:$A$14,0)),"") -> 55.904093 | C15: 100
A16: Size-adjusted recruiting index (100 = IFC rate) | B16: =IFERROR(INDEX('Recruitment Index'!$E$5:$E$14,MATCH($B$5,'Recruitment Index'!$A$5:$A$14,0)),"") -> 89.339339 | C16: 100
A17: Replacement index (100 = replaced everyone who left) | B17: =IFERROR(INDEX('Recruitment Index'!$F$5:$F$14,MATCH($B$5,'Recruitment Index'!$A$5:$A$14,0)),"") -> 78.947368 | C17: 100
A18: Membership growth, Fall to Fall (us vs the IFC) | B18: =IFERROR(INDEX('Recruitment Index'!$O$5:$O$14,MATCH($B$5,'Recruitment Index'!$A$5:$A$14,0)),"") -> -0.083333333 | C18: =IFERROR(INDEX('Recruitment Index'!$T$5:$T$14,MATCH($B$5,'Recruitment Index'!$A$5:$A$14,0)),"") -> 0.039915966
A19: Share of all IFC new members | B19: =IFERROR(INDEX('Recruitment Index'!$K$5:$K$14,MATCH($B$5,'Recruitment Index'!$A$5:$A$14,0)),"") -> 0.022522523 | C19: =IFERROR(1/INDEX('New Members Matrix'!$B$39:$U$39,MATCH("Fall "&$B$5,'New Members Matrix'!$B$2:$U$2,0)),"") -> 0.04 | D19: <- benchmark = an equal share (1 / number of houses)
A21: Combined scorecard (window on the Combined Score tab) | B21: Our rank | C21: Houses scored
A22: GPA rank | B22: =IFERROR(INDEX('Combined Score'!$Q$10:$Q$44,MATCH(OurChapter,'Combined Score'!$A$10:$A$44,0)),"") -> 18 | C22: =COUNT('Combined Score'!$O$10:$O$44) -> 23
A23: Recruitment rank | B23: =IFERROR(INDEX('Combined Score'!$R$10:$R$44,MATCH(OurChapter,'Combined Score'!$A$10:$A$44,0)),"") -> 20 | C23: =COUNT('Combined Score'!$O$10:$O$44) -> 23
A24: Combined rank | B24: =IFERROR(INDEX('Combined Score'!$P$10:$P$44,MATCH(OurChapter,'Combined Score'!$A$10:$A$44,0)),"") -> 20 | C24: =COUNT('Combined Score'!$O$10:$O$44) -> 23
A25: Window | B25: ='Combined Score'!B3&" to "&'Combined Score'!B4 -> Spring 2024 to Spring 2026
A27: Targets for the current exec team | B27: Value
A28: GPA points we are behind the IFC average (latest semester) | B28: =IF(OR(B8="",C8=""),"",C8-B8) -> 0.22897551
A29: New members this Fall to match last year's average IFC house | B29: =IFERROR(MAX(0,ROUNDUP(IFERROR(INDEX('Recruitment Index'!$J$5:$J$14,MATCH($B$5,'Recruitment Index'!$A$5:$A$14,0)),"")-INDEX('New Members Matrix'!$B$43:$U$43,MATCH("Spring "&($B$5+1),'New Members Matrix'!$B$2:$U$2,0)),0)),"") -> 21 | C29: ="(the " & $B$5 & " IFC average per house, minus our Spring " & ($B$5+1) & " new members)" -> (the 2025 IFC average per house, minus our Spring 2026 new members)
A30: New members this Fall to replace last year's departures | B30: =IFERROR(MAX(0,IFERROR(INDEX('Recruitment Index'!$N$5:$N$14,MATCH($B$5,'Recruitment Index'!$A$5:$A$14,0)),"")-INDEX('New Members Matrix'!$B$43:$U$43,MATCH("Spring "&($B$5+1),'New Members Matrix'!$B$2:$U$2,0))),"") -> 13 | C30: (assumes as many men leave this year as left last year)
A32: Evaluation
A33: Bottom line: Theta Xi is a below-average IFC house on grades, and it has shrunk from 86 men (Fall 2019) to 43 (Spring 2026) while the IFC grew. Over Spring 2024 to Spring 2026 we rank 18th of 23 active IFC houses on GPA, 20th on recruitment and 20th combined.
A34: GPA: we were below the IFC average (all IFC men) in every reported semester since Fall 2018 except Spring 2022 (+0.010). The gap shrank from -0.42 in Fall 2018 to within 0.06 in Spring 2021, Fall 2021 and Spring 2024 (11th of 25 that term). It opened up again in 2025: -0.32 in Spring 2025, -0.30 in Fall 2025 and -0.23 in Spring 2026 (3.163 vs 3.392, 17th of 23).
A35: Against all UNL men we were ahead in 5 of the 11 semesters from Spring 2021 to Spring 2026, but behind for the last three in a row: 3.053 vs 3.220 (Spring 2025), 3.033 vs 3.196 (Fall 2025) and 3.163 vs 3.226 (Spring 2026).
A36: Size: from 2018 to 2023 we were a median IFC house (60 to 86 men, about 13th of 25). Since Spring 2024 we have had 43 to 48 men, about 55% of the median house (78 in Spring 2026). Over the same years total IFC membership grew from 1,641 men (Fall 2018) to 1,980 (Fall 2025), so the drop is ours, not the market's.
A37: Recruiting volume: new members per calendar year were 34 (2019), 24 (2021), 17 (2024) and 15 (2025). UNL's reports are missing a term in 2020, 2022 and 2023, so those years are blank. The average IFC house took 24 to 27 a year, so our recruiting index fell from 143 in 2019 to 99 in 2021, 68 in 2024 and 56 in 2025. Our share of all IFC new members fell from 5.4% to 2.3%, where an equal share is about 4%.
A38: Replacement: in the years UNL's reports cover fully, the replacement index was 86 (2021), 59 (2024) and 79 (2025), so we lost more men than we brought in. Our Fall roster has dropped every year since 2019: 86, 78, 74, 71, 60, 48, 44.
A39: For our size, recruiting is closer to normal: the 2025 size-adjusted index was 89. So the problem is less that each member recruits badly and more that a smaller house brings in a smaller class, which shrinks the next class too. Getting back to a stable size means recruiting above the IFC rate for a few years, not just matching it.
A40: Retention is not the main leak now. UNL's new-member retention for us was 100% (Fall 2024), 75% (Spring 2025, 3 men), 92% (Fall 2025) and 100% (Spring 2026), close to the IFC median each term, and active retention was 90% to 98%. Our own records show heavier pledge losses in the 2020 to 2023 classes (30 of 86, 35%), so this has improved.
A41: The current exec team is off to a good start: 6 new members in Spring 2026, 5th most in the IFC (the average house took 4.1). To match the 2025 average IFC house for the year, Fall 2026 needs about 21 new members; to replace a 2025-sized loss it needs about 13 (Fall 2025 brought in 12, against an IFC median of 25).
A42: Houses that score well on both GPA and recruitment over Spring 2024 to Spring 2026 are Pi Kappa Alpha, Phi Kappa Theta and Sigma Chi: all three recruit big classes and keep GPAs above 3.38. Farmhouse, Sigma Phi Epsilon and Beta Theta Pi lead on GPA but sit in the bottom half on recruitment, mostly because they bring in fewer new men per member.
A43: Caveats: UNL has no Fall 2023 scorecard, so that semester uses the Fall 2023 All-Community Grade Report (GPA and members for every house, but no new-member counts). UNL's Spring 2020 report has no GPAs (pass/no-pass semester), and the Spring 2020 and Spring 2022 reports leave out new members. Some of our chapter records disagree with UNL's reports (for example Fall 2019: 77 vs 86 members). UNL's numbers are used everywhere so every house is measured the same way.

Sheet TX vs IFC
A1: =OurChapter&" vs. the IFC, semester by semester" -> Theta Xi vs. the IFC, semester by semester
A2: Everything on this tab is a formula. Change 'Our chapter' on the Lists tab to see any other house.
B3: GPA | K3: Size | O3: Recruitment | T3: Retention (reported Fall 2024+)
A4: Semester | B4: Our GPA | C4: IFC avg (member wtd) | D4: IFC median | E4: All UNL men | F4: Greek men | G4: Gap vs IFC avg | H4: IFC GPA rank | I4: Chapters w/ GPA | K4: Our members | L4: IFC median size | M4: Size rank | N4: Size vs median (100 = median) | O4: Our new members | P4: IFC avg new members | Q4: IFC median new members | R4: NM rank (1 = most) | S4: Share of all IFC NMs | T4: Our active retention | U4: Our NM retention | V4: IFC median NM retention
A5: Fall 2018 | B5: =IF(IFERROR(INDEX('GPA Matrix'!$B$43:$U$43,MATCH($A5,'GPA Matrix'!$B$2:$U$2,0)),"")="","",IFERROR(INDEX('GPA Matrix'!$B$43:$U$43,MATCH($A5,'GPA Matrix'!$B$2:$U$2,0)),"")) -> 2.733 | C5: =IF(IFERROR(INDEX('GPA Matrix'!$B$40:$U$40,MATCH($A5,'GPA Matrix'!$B$2:$U$2,0)),"")="","",IFERROR(INDEX('GPA Matrix'!$B$40:$U$40,MATCH($A5,'GPA Matrix'!$B$2:$U$2,0)),"")) -> 3.1567782 | D5: =IF(IFERROR(INDEX('GPA Matrix'!$B$41:$U$41,MATCH($A5,'GPA Matrix'!$B$2:$U$2,0)),"")="","",IFERROR(INDEX('GPA Matrix'!$B$41:$U$41,MATCH($A5,'GPA Matrix'!$B$2:$U$2,0)),"")) -> 3.074 | E5: =IFERROR(IF(INDEX('Campus Stats'!$C$2:$C$37,MATCH($A5,'Campus Stats'!$A$2:$A$37,0))="","",INDEX('Campus Stats'!$C$2:$C$37,MATCH($A5,'Campus Stats'!$A$2:$A$37,0))),"") -> 2.976 | F5: =IFERROR(IF(INDEX('Campus Stats'!$F$2:$F$37,MATCH($A5,'Campus Stats'!$A$2:$A$37,0))="","",INDEX('Campus Stats'!$F$2:$F$37,MATCH($A5,'Campus Stats'!$A$2:$A$37,0))),"") -> 3.149 | G5: =IF(OR(B5="",C5=""),"",B5-C5) -> -0.42377818 | H5: =IF(IFERROR(INDEX('GPA Matrix'!$B$44:$U$44,MATCH($A5,'GPA Matrix'!$B$2:$U$2,0)),"")="","",IFERROR(INDEX('GPA Matrix'!$B$44:$U$44,MATCH($A5,'GPA Matrix'!$B$2:$U$2,0)),"")) -> 23 | I5: =IF(H5="","",IFERROR(INDEX('GPA Matrix'!$B$39:$U$39,MATCH($A5,'GPA Matrix'!$B$2:$U$2,0)),"")) -> 25 | K5: =IF(IFERROR(INDEX('Members Matrix'!$B$43:$U$43,MATCH($A5,'Members Matrix'!$B$2:$U$2,0)),"")="","",IFERROR(INDEX('Members Matrix'!$B$43:$U$43,MATCH($A5,'Members Matrix'!$B$2:$U$2,0)),"")) -> 62 | L5: =IF(IFERROR(INDEX('Members Matrix'!$B$42:$U$42,MATCH($A5,'Members Matrix'!$B$2:$U$2,0)),"")="","",IFERROR(INDEX('Members Matrix'!$B$42:$U$42,MATCH($A5,'Members Matrix'!$B$2:$U$2,0)),"")) -> 62 | M5: =IF(IFERROR(INDEX('Members Matrix'!$B$44:$U$44,MATCH($A5,'Members Matrix'!$B$2:$U$2,0)),"")="","",IFERROR(INDEX('Members Matrix'!$B$44:$U$44,MATCH($A5,'Members Matrix'!$B$2:$U$2,0)),"")) -> 13 | N5: =IF(IFERROR(INDEX('Members Matrix'!$B$45:$U$45,MATCH($A5,'Members Matrix'!$B$2:$U$2,0)),"")="","",IFERROR(INDEX('Members Matrix'!$B$45:$U$45,MATCH($A5,'Members Matrix'!$B$2:$U$2,0)),"")) -> 100 | O5: =IF(IFERROR(INDEX('New Members Matrix'!$B$43:$U$43,MATCH($A5,'New Members Matrix'!$B$2:$U$2,0)),"")="","",IFERROR(INDEX('New Members Matrix'!$B$43:$U$43,MATCH($A5,'New Members Matrix'!$B$2:$U$2,0)),"")) -> 22 | P5: =IF(IFERROR(INDEX('New Members Matrix'!$B$41:$U$41,MATCH($A5,'New Members Matrix'!$B$2:$U$2,0)),"")="","",IFERROR(INDEX('New Members Matrix'!$B$41:$U$41,MATCH($A5,'New Members Matrix'!$B$2:$U$2,0)),"")) -> 19.44 | Q5: =IF(IFERROR(INDEX('New Members Matrix'!$B$42:$U$42,MATCH($A5,'New Members Matrix'!$B$2:$U$2,0)),"")="","",IFERROR(INDEX('New Members Matrix'!$B$42:$U$42,MATCH($A5,'New Members Matrix'!$B$2:$U$2,0)),"")) -> 22 | R5: =IF(IFERROR(INDEX('New Members Matrix'!$B$44:$U$44,MATCH($A5,'New Members Matrix'!$B$2:$U$2,0)),"")="","",IFERROR(INDEX('New Members Matrix'!$B$44:$U$44,MATCH($A5,'New Members Matrix'!$B$2:$U$2,0)),"")) -> 13 | S5: =IF(IFERROR(INDEX('New Members Matrix'!$B$45:$U$45,MATCH($A5,'New Members Matrix'!$B$2:$U$2,0)),"")="","",IFERROR(INDEX('New Members Matrix'!$B$45:$U$45,MATCH($A5,'New Members Matrix'!$B$2:$U$2,0)),"")) -> 0.04526749 | T5: =IFERROR(IF(COUNTIFS('Chapter Data'!$A$2:$A$2500,$A5,'Chapter Data'!$D$2:$D$2500,OurChapter,'Chapter Data'!$J$2:$J$2500,"<>")=0,"",SUMIFS('Chapter Data'!$J$2:$J$2500,'Chapter Data'!$A$2:$A$2500,$A5,'Chapter Data'!$D$2:$D$2500,OurChapter)),"") | U5: =IFERROR(IF(COUNTIFS('Chapter Data'!$A$2:$A$2500,$A5,'Chapter Data'!$D$2:$D$2500,OurChapter,'Chapter Data'!$K$2:$K$2500,"<>")=0,"",SUMIFS('Chapter Data'!$K$2:$K$2500,'Chapter Data'!$A$2:$A$2500,$A5,'Chapter Data'!$D$2:$D$2500,OurChapter)),"") | V5: {=IF(COUNTIFS('Chapter Data'!$A$2:$A$2500,$A5,'Chapter Data'!$C$2:$C$2500,"IFC",'Chapter Data'!$K$2:$K$2500,">=0")<MinChapters,"",MEDIAN(IF(('Chapter Data'!$A$2:$A$2500=$A5)*('Chapter Data'!$C$2:$C$2500="IFC")*ISNUMBER('Chapter Data'!$K$2:$K$2500),'Chapter Data'!$K$2:$K$2500)))}
A6: Spring 2019 | B6: =IF(IFERROR(INDEX('GPA Matrix'!$B$43:$U$43,MATCH($A6,'GPA Matrix'!$B$2:$U$2,0)),"")="","",IFERROR(INDEX('GPA Matrix'!$B$43:$U$43,MATCH($A6,'GPA Matrix'!$B$2:$U$2,0)),"")) -> 2.919 | C6: =IF(IFERROR(INDEX('GPA Matrix'!$B$40:$U$40,MATCH($A6,'GPA Matrix'!$B$2:$U$2,0)),"")="","",IFERROR(INDEX('GPA Matrix'!$B$40:$U$40,MATCH($A6,'GPA Matrix'!$B$2:$U$2,0)),"")) -> 3.1669912 | D6: =IF(IFERROR(INDEX('GPA Matrix'!$B$41:$U$41,MATCH($A6,'GPA Matrix'!$B$2:$U$2,0)),"")="","",IFERROR(INDEX('GPA Matrix'!$B$41:$U$41,MATCH($A6,'GPA Matrix'!$B$2:$U$2,0)),"")) -> 3.06 | E6: =IFERROR(IF(INDEX('Campus Stats'!$C$2:$C$37,MATCH($A6,'Campus Stats'!$A$2:$A$37,0))="","",INDEX('Campus Stats'!$C$2:$C$37,MATCH($A6,'Campus Stats'!$A$2:$A$37,0))),"") -> 3.012 | F6: =IFERROR(IF(INDEX('Campus Stats'!$F$2:$F$37,MATCH($A6,'Campus Stats'!$A$2:$A$37,0))="","",INDEX('Campus Stats'!$F$2:$F$37,MATCH($A6,'Campus Stats'!$A$2:$A$37,0))),"") -> 3.154 | G6: =IF(OR(B6="",C6=""),"",B6-C6) -> -0.24799122 | H6: =IF(IFERROR(INDEX('GPA Matrix'!$B$44:$U$44,MATCH($A6,'GPA Matrix'!$B$2:$U$2,0)),"")="","",IFERROR(INDEX('GPA Matrix'!$B$44:$U$44,MATCH($A6,'GPA Matrix'!$B$2:$U$2,0)),"")) -> 21 | I6: =IF(H6="","",IFERROR(INDEX('GPA Matrix'!$B$39:$U$39,MATCH($A6,'GPA Matrix'!$B$2:$U$2,0)),"")) -> 24 | K6: =IF(IFERROR(INDEX('Members Matrix'!$B$43:$U$43,MATCH($A6,'Members Matrix'!$B$2:$U$2,0)),"")="","",IFERROR(INDEX('Members Matrix'!$B$43:$U$43,MATCH($A6,'Members Matrix'!$B$2:$U$2,0)),"")) -> 64 | L6: =IF(IFERROR(INDEX('Members Matrix'!$B$42:$U$42,MATCH($A6,'Members Matrix'!$B$2:$U$2,0)),"")="","",IFERROR(INDEX('Members Matrix'!$B$42:$U$42,MATCH($A6,'Members Matrix'!$B$2:$U$2,0)),"")) -> 64 | M6: =IF(IFERROR(INDEX('Members Matrix'!$B$44:$U$44,MATCH($A6,'Members Matrix'!$B$2:$U$2,0)),"")="","",IFERROR(INDEX('Members Matrix'!$B$44:$U$44,MATCH($A6,'Members Matrix'!$B$2:$U$2,0)),"")) -> 13 | N6: =IF(IFERROR(INDEX('Members Matrix'!$B$45:$U$45,MATCH($A6,'Members Matrix'!$B$2:$U$2,0)),"")="","",IFERROR(INDEX('Members Matrix'!$B$45:$U$45,MATCH($A6,'Members Matrix'!$B$2:$U$2,0)),"")) -> 100 | O6: =IF(IFERROR(INDEX('New Members Matrix'!$B$43:$U$43,MATCH($A6,'New Members Matrix'!$B$2:$U$2,0)),"")="","",IFERROR(INDEX('New Members Matrix'!$B$43:$U$43,MATCH($A6,'New Members Matrix'!$B$2:$U$2,0)),"")) -> 9 | P6: =IF(IFERROR(INDEX('New Members Matrix'!$B$41:$U$41,MATCH($A6,'New Members Matrix'!$B$2:$U$2,0)),"")="","",IFERROR(INDEX('New Members Matrix'!$B$41:$U$41,MATCH($A6,'New Members Matrix'!$B$2:$U$2,0)),"")) -> 2.72 | Q6: =IF(IFERROR(INDEX('New Members Matrix'!$B$42:$U$42,MATCH($A6,'New Members Matrix'!$B$2:$U$2,0)),"")="","",IFERROR(INDEX('New Members Matrix'!$B$42:$U$42,MATCH($A6,'New Members Matrix'!$B$2:$U$2,0)),"")) -> 1 | R6: =IF(IFERROR(INDEX('New Members Matrix'!$B$44:$U$44,MATCH($A6,'New Members Matrix'!$B$2:$U$2,0)),"")="","",IFERROR(INDEX('New Members Matrix'!$B$44:$U$44,MATCH($A6,'New Members Matrix'!$B$2:$U$2,0)),"")) -> 3 | S6: =IF(IFERROR(INDEX('New Members Matrix'!$B$45:$U$45,MATCH($A6,'New Members Matrix'!$B$2:$U$2,0)),"")="","",IFERROR(INDEX('New Members Matrix'!$B$45:$U$45,MATCH($A6,'New Members Matrix'!$B$2:$U$2,0)),"")) -> 0.13235294 | T6: =IFERROR(IF(COUNTIFS('Chapter Data'!$A$2:$A$2500,$A6,'Chapter Data'!$D$2:$D$2500,OurChapter,'Chapter Data'!$J$2:$J$2500,"<>")=0,"",SUMIFS('Chapter Data'!$J$2:$J$2500,'Chapter Data'!$A$2:$A$2500,$A6,'Chapter Data'!$D$2:$D$2500,OurChapter)),"") | U6: =IFERROR(IF(COUNTIFS('Chapter Data'!$A$2:$A$2500,$A6,'Chapter Data'!$D$2:$D$2500,OurChapter,'Chapter Data'!$K$2:$K$2500,"<>")=0,"",SUMIFS('Chapter Data'!$K$2:$K$2500,'Chapter Data'!$A$2:$A$2500,$A6,'Chapter Data'!$D$2:$D$2500,OurChapter)),"") | V6: {=IF(COUNTIFS('Chapter Data'!$A$2:$A$2500,$A6,'Chapter Data'!$C$2:$C$2500,"IFC",'Chapter Data'!$K$2:$K$2500,">=0")<MinChapters,"",MEDIAN(IF(('Chapter Data'!$A$2:$A$2500=$A6)*('Chapter Data'!$C$2:$C$2500="IFC")*ISNUMBER('Chapter Data'!$K$2:$K$2500),'Chapter Data'!$K$2:$K$2500)))}
A7: Fall 2019 | B7: =IF(IFERROR(INDEX('GPA Matrix'!$B$43:$U$43,MATCH($A7,'GPA Matrix'!$B$2:$U$2,0)),"")="","",IFERROR(INDEX('GPA Matrix'!$B$43:$U$43,MATCH($A7,'GPA Matrix'!$B$2:$U$2,0)),"")) -> 2.819 | C7: =IF(IFERROR(INDEX('GPA Matrix'!$B$40:$U$40,MATCH($A7,'GPA Matrix'!$B$2:$U$2,0)),"")="","",IFERROR(INDEX('GPA Matrix'!$B$40:$U$40,MATCH($A7,'GPA Matrix'!$B$2:$U$2,0)),"")) -> 3.143051 | D7: =IF(IFERROR(INDEX('GPA Matrix'!$B$41:$U$41,MATCH($A7,'GPA Matrix'!$B$2:$U$2,0)),"")="","",IFERROR(INDEX('GPA Matrix'!$B$41:$U$41,MATCH($A7,'GPA Matrix'!$B$2:$U$2,0)),"")) -> 3.084 | E7: =IFERROR(IF(INDEX('Campus Stats'!$C$2:$C$37,MATCH($A7,'Campus Stats'!$A$2:$A$37,0))="","",INDEX('Campus Stats'!$C$2:$C$37,MATCH($A7,'Campus Stats'!$A$2:$A$37,0))),"") -> 3.032 | F7: =IFERROR(IF(INDEX('Campus Stats'!$F$2:$F$37,MATCH($A7,'Campus Stats'!$A$2:$A$37,0))="","",INDEX('Campus Stats'!$F$2:$F$37,MATCH($A7,'Campus Stats'!$A$2:$A$37,0))),"") -> 3.133 | G7: =IF(OR(B7="",C7=""),"",B7-C7) -> -0.32405103 | H7: =IF(IFERROR(INDEX('GPA Matrix'!$B$44:$U$44,MATCH($A7,'GPA Matrix'!$B$2:$U$2,0)),"")="","",IFERROR(INDEX('GPA Matrix'!$B$44:$U$44,MATCH($A7,'GPA Matrix'!$B$2:$U$2,0)),"")) -> 24 | I7: =IF(H7="","",IFERROR(INDEX('GPA Matrix'!$B$39:$U$39,MATCH($A7,'GPA Matrix'!$B$2:$U$2,0)),"")) -> 27 | K7: =IF(IFERROR(INDEX('Members Matrix'!$B$43:$U$43,MATCH($A7,'Members Matrix'!$B$2:$U$2,0)),"")="","",IFERROR(INDEX('Members Matrix'!$B$43:$U$43,MATCH($A7,'Members Matrix'!$B$2:$U$2,0)),"")) -> 86 | L7: =IF(IFERROR(INDEX('Members Matrix'!$B$42:$U$42,MATCH($A7,'Members Matrix'!$B$2:$U$2,0)),"")="","",IFERROR(INDEX('Members Matrix'!$B$42:$U$42,MATCH($A7,'Members Matrix'!$B$2:$U$2,0)),"")) -> 83 | M7: =IF(IFERROR(INDEX('Members Matrix'!$B$44:$U$44,MATCH($A7,'Members Matrix'!$B$2:$U$2,0)),"")="","",IFERROR(INDEX('Members Matrix'!$B$44:$U$44,MATCH($A7,'Members Matrix'!$B$2:$U$2,0)),"")) -> 12 | N7: =IF(IFERROR(INDEX('Members Matrix'!$B$45:$U$45,MATCH($A7,'Members Matrix'!$B$2:$U$2,0)),"")="","",IFERROR(INDEX('Members Matrix'!$B$45:$U$45,MATCH($A7,'Members Matrix'!$B$2:$U$2,0)),"")) -> 103.61446 | O7: =IF(IFERROR(INDEX('New Members Matrix'!$B$43:$U$43,MATCH($A7,'New Members Matrix'!$B$2:$U$2,0)),"")="","",IFERROR(INDEX('New Members Matrix'!$B$43:$U$43,MATCH($A7,'New Members Matrix'!$B$2:$U$2,0)),"")) -> 25 | P7: =IF(IFERROR(INDEX('New Members Matrix'!$B$41:$U$41,MATCH($A7,'New Members Matrix'!$B$2:$U$2,0)),"")="","",IFERROR(INDEX('New Members Matrix'!$B$41:$U$41,MATCH($A7,'New Members Matrix'!$B$2:$U$2,0)),"")) -> 21 | Q7: =IF(IFERROR(INDEX('New Members Matrix'!$B$42:$U$42,MATCH($A7,'New Members Matrix'!$B$2:$U$2,0)),"")="","",IFERROR(INDEX('New Members Matrix'!$B$42:$U$42,MATCH($A7,'New Members Matrix'!$B$2:$U$2,0)),"")) -> 25 | R7: =IF(IFERROR(INDEX('New Members Matrix'!$B$44:$U$44,MATCH($A7,'New Members Matrix'!$B$2:$U$2,0)),"")="","",IFERROR(INDEX('New Members Matrix'!$B$44:$U$44,MATCH($A7,'New Members Matrix'!$B$2:$U$2,0)),"")) -> 14 | S7: =IF(IFERROR(INDEX('New Members Matrix'!$B$45:$U$45,MATCH($A7,'New Members Matrix'!$B$2:$U$2,0)),"")="","",IFERROR(INDEX('New Members Matrix'!$B$45:$U$45,MATCH($A7,'New Members Matrix'!$B$2:$U$2,0)),"")) -> 0.044091711 | T7: =IFERROR(IF(COUNTIFS('Chapter Data'!$A$2:$A$2500,$A7,'Chapter Data'!$D$2:$D$2500,OurChapter,'Chapter Data'!$J$2:$J$2500,"<>")=0,"",SUMIFS('Chapter Data'!$J$2:$J$2500,'Chapter Data'!$A$2:$A$2500,$A7,'Chapter Data'!$D$2:$D$2500,OurChapter)),"") | U7: =IFERROR(IF(COUNTIFS('Chapter Data'!$A$2:$A$2500,$A7,'Chapter Data'!$D$2:$D$2500,OurChapter,'Chapter Data'!$K$2:$K$2500,"<>")=0,"",SUMIFS('Chapter Data'!$K$2:$K$2500,'Chapter Data'!$A$2:$A$2500,$A7,'Chapter Data'!$D$2:$D$2500,OurChapter)),"") | V7: {=IF(COUNTIFS('Chapter Data'!$A$2:$A$2500,$A7,'Chapter Data'!$C$2:$C$2500,"IFC",'Chapter Data'!$K$2:$K$2500,">=0")<MinChapters,"",MEDIAN(IF(('Chapter Data'!$A$2:$A$2500=$A7)*('Chapter Data'!$C$2:$C$2500="IFC")*ISNUMBER('Chapter Data'!$K$2:$K$2500),'Chapter Data'!$K$2:$K$2500)))}
A8: Spring 2020 | B8: =IF(IFERROR(INDEX('GPA Matrix'!$B$43:$U$43,MATCH($A8,'GPA Matrix'!$B$2:$U$2,0)),"")="","",IFERROR(INDEX('GPA Matrix'!$B$43:$U$43,MATCH($A8,'GPA Matrix'!$B$2:$U$2,0)),"")) | C8: =IF(IFERROR(INDEX('GPA Matrix'!$B$40:$U$40,MATCH($A8,'GPA Matrix'!$B$2:$U$2,0)),"")="","",IFERROR(INDEX('GPA Matrix'!$B$40:$U$40,MATCH($A8,'GPA Matrix'!$B$2:$U$2,0)),"")) | D8: =IF(IFERROR(INDEX('GPA Matrix'!$B$41:$U$41,MATCH($A8,'GPA Matrix'!$B$2:$U$2,0)),"")="","",IFERROR(INDEX('GPA Matrix'!$B$41:$U$41,MATCH($A8,'GPA Matrix'!$B$2:$U$2,0)),"")) | E8: =IFERROR(IF(INDEX('Campus Stats'!$C$2:$C$37,MATCH($A8,'Campus Stats'!$A$2:$A$37,0))="","",INDEX('Campus Stats'!$C$2:$C$37,MATCH($A8,'Campus Stats'!$A$2:$A$37,0))),"") -> 3.365 | F8: =IFERROR(IF(INDEX('Campus Stats'!$F$2:$F$37,MATCH($A8,'Campus Stats'!$A$2:$A$37,0))="","",INDEX('Campus Stats'!$F$2:$F$37,MATCH($A8,'Campus Stats'!$A$2:$A$37,0))),"") -> 3.439 | G8: =IF(OR(B8="",C8=""),"",B8-C8) | H8: =IF(IFERROR(INDEX('GPA Matrix'!$B$44:$U$44,MATCH($A8,'GPA Matrix'!$B$2:$U$2,0)),"")="","",IFERROR(INDEX('GPA Matrix'!$B$44:$U$44,MATCH($A8,'GPA Matrix'!$B$2:$U$2,0)),"")) | I8: =IF(H8="","",IFERROR(INDEX('GPA Matrix'!$B$39:$U$39,MATCH($A8,'GPA Matrix'!$B$2:$U$2,0)),"")) | K8: =IF(IFERROR(INDEX('Members Matrix'!$B$43:$U$43,MATCH($A8,'Members Matrix'!$B$2:$U$2,0)),"")="","",IFERROR(INDEX('Members Matrix'!$B$43:$U$43,MATCH($A8,'Members Matrix'!$B$2:$U$2,0)),"")) -> 73 | L8: =IF(IFERROR(INDEX('Members Matrix'!$B$42:$U$42,MATCH($A8,'Members Matrix'!$B$2:$U$2,0)),"")="","",IFERROR(INDEX('Members Matrix'!$B$42:$U$42,MATCH($A8,'Members Matrix'!$B$2:$U$2,0)),"")) -> 75.5 | M8: =IF(IFERROR(INDEX('Members Matrix'!$B$44:$U$44,MATCH($A8,'Members Matrix'!$B$2:$U$2,0)),"")="","",IFERROR(INDEX('Members Matrix'!$B$44:$U$44,MATCH($A8,'Members Matrix'!$B$2:$U$2,0)),"")) -> 15 | N8: =IF(IFERROR(INDEX('Members Matrix'!$B$45:$U$45,MATCH($A8,'Members Matrix'!$B$2:$U$2,0)),"")="","",IFERROR(INDEX('Members Matrix'!$B$45:$U$45,MATCH($A8,'Members Matrix'!$B$2:$U$2,0)),"")) -> 96.688742 | O8: =IF(IFERROR(INDEX('New Members Matrix'!$B$43:$U$43,MATCH($A8,'New Members Matrix'!$B$2:$U$2,0)),"")="","",IFERROR(INDEX('New Members Matrix'!$B$43:$U$43,MATCH($A8,'New Members Matrix'!$B$2:$U$2,0)),"")) | P8: =IF(IFERROR(INDEX('New Members Matrix'!$B$41:$U$41,MATCH($A8,'New Members Matrix'!$B$2:$U$2,0)),"")="","",IFERROR(INDEX('New Members Matrix'!$B$41:$U$41,MATCH($A8,'New Members Matrix'!$B$2:$U$2,0)),"")) | Q8: =IF(IFERROR(INDEX('New Members Matrix'!$B$42:$U$42,MATCH($A8,'New Members Matrix'!$B$2:$U$2,0)),"")="","",IFERROR(INDEX('New Members Matrix'!$B$42:$U$42,MATCH($A8,'New Members Matrix'!$B$2:$U$2,0)),"")) | R8: =IF(IFERROR(INDEX('New Members Matrix'!$B$44:$U$44,MATCH($A8,'New Members Matrix'!$B$2:$U$2,0)),"")="","",IFERROR(INDEX('New Members Matrix'!$B$44:$U$44,MATCH($A8,'New Members Matrix'!$B$2:$U$2,0)),"")) | S8: =IF(IFERROR(INDEX('New Members Matrix'!$B$45:$U$45,MATCH($A8,'New Members Matrix'!$B$2:$U$2,0)),"")="","",IFERROR(INDEX('New Members Matrix'!$B$45:$U$45,MATCH($A8,'New Members Matrix'!$B$2:$U$2,0)),"")) | T8: =IFERROR(IF(COUNTIFS('Chapter Data'!$A$2:$A$2500,$A8,'Chapter Data'!$D$2:$D$2500,OurChapter,'Chapter Data'!$J$2:$J$2500,"<>")=0,"",SUMIFS('Chapter Data'!$J$2:$J$2500,'Chapter Data'!$A$2:$A$2500,$A8,'Chapter Data'!$D$2:$D$2500,OurChapter)),"") | U8: =IFERROR(IF(COUNTIFS('Chapter Data'!$A$2:$A$2500,$A8,'Chapter Data'!$D$2:$D$2500,OurChapter,'Chapter Data'!$K$2:$K$2500,"<>")=0,"",SUMIFS('Chapter Data'!$K$2:$K$2500,'Chapter Data'!$A$2:$A$2500,$A8,'Chapter Data'!$D$2:$D$2500,OurChapter)),"") | V8: {=IF(COUNTIFS('Chapter Data'!$A$2:$A$2500,$A8,'Chapter Data'!$C$2:$C$2500,"IFC",'Chapter Data'!$K$2:$K$2500,">=0")<MinChapters,"",MEDIAN(IF(('Chapter Data'!$A$2:$A$2500=$A8)*('Chapter Data'!$C$2:$C$2500="IFC")*ISNUMBER('Chapter Data'!$K$2:$K$2500),'Chapter Data'!$K$2:$K$2500)))}
A9: Fall 2020 | B9: =IF(IFERROR(INDEX('GPA Matrix'!$B$43:$U$43,MATCH($A9,'GPA Matrix'!$B$2:$U$2,0)),"")="","",IFERROR(INDEX('GPA Matrix'!$B$43:$U$43,MATCH($A9,'GPA Matrix'!$B$2:$U$2,0)),"")) -> 2.957 | C9: =IF(IFERROR(INDEX('GPA Matrix'!$B$40:$U$40,MATCH($A9,'GPA Matrix'!$B$2:$U$2,0)),"")="","",IFERROR(INDEX('GPA Matrix'!$B$40:$U$40,MATCH($A9,'GPA Matrix'!$B$2:$U$2,0)),"")) -> 3.1999045 | D9: =IF(IFERROR(INDEX('GPA Matrix'!$B$41:$U$41,MATCH($A9,'GPA Matrix'!$B$2:$U$2,0)),"")="","",IFERROR(INDEX('GPA Matrix'!$B$41:$U$41,MATCH($A9,'GPA Matrix'!$B$2:$U$2,0)),"")) -> 3.223 | E9: =IFERROR(IF(INDEX('Campus Stats'!$C$2:$C$37,MATCH($A9,'Campus Stats'!$A$2:$A$37,0))="","",INDEX('Campus Stats'!$C$2:$C$37,MATCH($A9,'Campus Stats'!$A$2:$A$37,0))),"") -> 3.032 | F9: =IFERROR(IF(INDEX('Campus Stats'!$F$2:$F$37,MATCH($A9,'Campus Stats'!$A$2:$A$37,0))="","",INDEX('Campus Stats'!$F$2:$F$37,MATCH($A9,'Campus Stats'!$A$2:$A$37,0))),"") -> 3.213 | G9: =IF(OR(B9="",C9=""),"",B9-C9) -> -0.24290453 | H9: =IF(IFERROR(INDEX('GPA Matrix'!$B$44:$U$44,MATCH($A9,'GPA Matrix'!$B$2:$U$2,0)),"")="","",IFERROR(INDEX('GPA Matrix'!$B$44:$U$44,MATCH($A9,'GPA Matrix'!$B$2:$U$2,0)),"")) -> 20 | I9: =IF(H9="","",IFERROR(INDEX('GPA Matrix'!$B$39:$U$39,MATCH($A9,'GPA Matrix'!$B$2:$U$2,0)),"")) -> 24 | K9: =IF(IFERROR(INDEX('Members Matrix'!$B$43:$U$43,MATCH($A9,'Members Matrix'!$B$2:$U$2,0)),"")="","",IFERROR(INDEX('Members Matrix'!$B$43:$U$43,MATCH($A9,'Members Matrix'!$B$2:$U$2,0)),"")) -> 78 | L9: =IF(IFERROR(INDEX('Members Matrix'!$B$42:$U$42,MATCH($A9,'Members Matrix'!$B$2:$U$2,0)),"")="","",IFERROR(INDEX('Members Matrix'!$B$42:$U$42,MATCH($A9,'Members Matrix'!$B$2:$U$2,0)),"")) -> 77.5 | M9: =IF(IFERROR(INDEX('Members Matrix'!$B$44:$U$44,MATCH($A9,'Members Matrix'!$B$2:$U$2,0)),"")="","",IFERROR(INDEX('Members Matrix'!$B$44:$U$44,MATCH($A9,'Members Matrix'!$B$2:$U$2,0)),"")) -> 13 | N9: =IF(IFERROR(INDEX('Members Matrix'!$B$45:$U$45,MATCH($A9,'Members Matrix'!$B$2:$U$2,0)),"")="","",IFERROR(INDEX('Members Matrix'!$B$45:$U$45,MATCH($A9,'Members Matrix'!$B$2:$U$2,0)),"")) -> 100.64516 | O9: =IF(IFERROR(INDEX('New Members Matrix'!$B$43:$U$43,MATCH($A9,'New Members Matrix'!$B$2:$U$2,0)),"")="","",IFERROR(INDEX('New Members Matrix'!$B$43:$U$43,MATCH($A9,'New Members Matrix'!$B$2:$U$2,0)),"")) -> 28 | P9: =IF(IFERROR(INDEX('New Members Matrix'!$B$41:$U$41,MATCH($A9,'New Members Matrix'!$B$2:$U$2,0)),"")="","",IFERROR(INDEX('New Members Matrix'!$B$41:$U$41,MATCH($A9,'New Members Matrix'!$B$2:$U$2,0)),"")) -> 21 | Q9: =IF(IFERROR(INDEX('New Members Matrix'!$B$42:$U$42,MATCH($A9,'New Members Matrix'!$B$2:$U$2,0)),"")="","",IFERROR(INDEX('New Members Matrix'!$B$42:$U$42,MATCH($A9,'New Members Matrix'!$B$2:$U$2,0)),"")) -> 24 | R9: =IF(IFERROR(INDEX('New Members Matrix'!$B$44:$U$44,MATCH($A9,'New Members Matrix'!$B$2:$U$2,0)),"")="","",IFERROR(INDEX('New Members Matrix'!$B$44:$U$44,MATCH($A9,'New Members Matrix'!$B$2:$U$2,0)),"")) -> 9 | S9: =IF(IFERROR(INDEX('New Members Matrix'!$B$45:$U$45,MATCH($A9,'New Members Matrix'!$B$2:$U$2,0)),"")="","",IFERROR(INDEX('New Members Matrix'!$B$45:$U$45,MATCH($A9,'New Members Matrix'!$B$2:$U$2,0)),"")) -> 0.051282051 | T9: =IFERROR(IF(COUNTIFS('Chapter Data'!$A$2:$A$2500,$A9,'Chapter Data'!$D$2:$D$2500,OurChapter,'Chapter Data'!$J$2:$J$2500,"<>")=0,"",SUMIFS('Chapter Data'!$J$2:$J$2500,'Chapter Data'!$A$2:$A$2500,$A9,'Chapter Data'!$D$2:$D$2500,OurChapter)),"") | U9: =IFERROR(IF(COUNTIFS('Chapter Data'!$A$2:$A$2500,$A9,'Chapter Data'!$D$2:$D$2500,OurChapter,'Chapter Data'!$K$2:$K$2500,"<>")=0,"",SUMIFS('Chapter Data'!$K$2:$K$2500,'Chapter Data'!$A$2:$A$2500,$A9,'Chapter Data'!$D$2:$D$2500,OurChapter)),"") | V9: {=IF(COUNTIFS('Chapter Data'!$A$2:$A$2500,$A9,'Chapter Data'!$C$2:$C$2500,"IFC",'Chapter Data'!$K$2:$K$2500,">=0")<MinChapters,"",MEDIAN(IF(('Chapter Data'!$A$2:$A$2500=$A9)*('Chapter Data'!$C$2:$C$2500="IFC")*ISNUMBER('Chapter Data'!$K$2:$K$2500),'Chapter Data'!$K$2:$K$2500)))}
A10: Spring 2021 | B10: =IF(IFERROR(INDEX('GPA Matrix'!$B$43:$U$43,MATCH($A10,'GPA Matrix'!$B$2:$U$2,0)),"")="","",IFERROR(INDEX('GPA Matrix'!$B$43:$U$43,MATCH($A10,'GPA Matrix'!$B$2:$U$2,0)),"")) -> 3.267 | C10: =IF(IFERROR(INDEX('GPA Matrix'!$B$40:$U$40,MATCH($A10,'GPA Matrix'!$B$2:$U$2,0)),"")="","",IFERROR(INDEX('GPA Matrix'!$B$40:$U$40,MATCH($A10,'GPA Matrix'!$B$2:$U$2,0)),"")) -> 3.3159273 | D10: =IF(IFERROR(INDEX('GPA Matrix'!$B$41:$U$41,MATCH($A10,'GPA Matrix'!$B$2:$U$2,0)),"")="","",IFERROR(INDEX('GPA Matrix'!$B$41:$U$41,MATCH($A10,'GPA Matrix'!$B$2:$U$2,0)),"")) -> 3.311 | E10: =IFERROR(IF(INDEX('Campus Stats'!$C$2:$C$37,MATCH($A10,'Campus Stats'!$A$2:$A$37,0))="","",INDEX('Campus Stats'!$C$2:$C$37,MATCH($A10,'Campus Stats'!$A$2:$A$37,0))),"") -> 3.187 | F10: =IFERROR(IF(INDEX('Campus Stats'!$F$2:$F$37,MATCH($A10,'Campus Stats'!$A$2:$A$37,0))="","",INDEX('Campus Stats'!$F$2:$F$37,MATCH($A10,'Campus Stats'!$A$2:$A$37,0))),"") -> 3.307 | G10: =IF(OR(B10="",C10=""),"",B10-C10) -> -0.048927293 | H10: =IF(IFERROR(INDEX('GPA Matrix'!$B$44:$U$44,MATCH($A10,'GPA Matrix'!$B$2:$U$2,0)),"")="","",IFERROR(INDEX('GPA Matrix'!$B$44:$U$44,MATCH($A10,'GPA Matrix'!$B$2:$U$2,0)),"")) -> 15 | I10: =IF(H10="","",IFERROR(INDEX('GPA Matrix'!$B$39:$U$39,MATCH($A10,'GPA Matrix'!$B$2:$U$2,0)),"")) -> 26 | K10: =IF(IFERROR(INDEX('Members Matrix'!$B$43:$U$43,MATCH($A10,'Members Matrix'!$B$2:$U$2,0)),"")="","",IFERROR(INDEX('Members Matrix'!$B$43:$U$43,MATCH($A10,'Members Matrix'!$B$2:$U$2,0)),"")) -> 74 | L10: =IF(IFERROR(INDEX('Members Matrix'!$B$42:$U$42,MATCH($A10,'Members Matrix'!$B$2:$U$2,0)),"")="","",IFERROR(INDEX('Members Matrix'!$B$42:$U$42,MATCH($A10,'Members Matrix'!$B$2:$U$2,0)),"")) -> 74 | M10: =IF(IFERROR(INDEX('Members Matrix'!$B$44:$U$44,MATCH($A10,'Members Matrix'!$B$2:$U$2,0)),"")="","",IFERROR(INDEX('Members Matrix'!$B$44:$U$44,MATCH($A10,'Members Matrix'!$B$2:$U$2,0)),"")) -> 12 | N10: =IF(IFERROR(INDEX('Members Matrix'!$B$45:$U$45,MATCH($A10,'Members Matrix'!$B$2:$U$2,0)),"")="","",IFERROR(INDEX('Members Matrix'!$B$45:$U$45,MATCH($A10,'Members Matrix'!$B$2:$U$2,0)),"")) -> 100 | O10: =IF(IFERROR(INDEX('New Members Matrix'!$B$43:$U$43,MATCH($A10,'New Members Matrix'!$B$2:$U$2,0)),"")="","",IFERROR(INDEX('New Members Matrix'!$B$43:$U$43,MATCH($A10,'New Members Matrix'!$B$2:$U$2,0)),"")) -> 10 | P10: =IF(IFERROR(INDEX('New Members Matrix'!$B$41:$U$41,MATCH($A10,'New Members Matrix'!$B$2:$U$2,0)),"")="","",IFERROR(INDEX('New Members Matrix'!$B$41:$U$41,MATCH($A10,'New Members Matrix'!$B$2:$U$2,0)),"")) -> 3.3461538 | Q10: =IF(IFERROR(INDEX('New Members Matrix'!$B$42:$U$42,MATCH($A10,'New Members Matrix'!$B$2:$U$2,0)),"")="","",IFERROR(INDEX('New Members Matrix'!$B$42:$U$42,MATCH($A10,'New Members Matrix'!$B$2:$U$2,0)),"")) -> 2 | R10: =IF(IFERROR(INDEX('New Members Matrix'!$B$44:$U$44,MATCH($A10,'New Members Matrix'!$B$2:$U$2,0)),"")="","",IFERROR(INDEX('New Members Matrix'!$B$44:$U$44,MATCH($A10,'New Members Matrix'!$B$2:$U$2,0)),"")) -> 2 | S10: =IF(IFERROR(INDEX('New Members Matrix'!$B$45:$U$45,MATCH($A10,'New Members Matrix'!$B$2:$U$2,0)),"")="","",IFERROR(INDEX('New Members Matrix'!$B$45:$U$45,MATCH($A10,'New Members Matrix'!$B$2:$U$2,0)),"")) -> 0.11494253 | T10: =IFERROR(IF(COUNTIFS('Chapter Data'!$A$2:$A$2500,$A10,'Chapter Data'!$D$2:$D$2500,OurChapter,'Chapter Data'!$J$2:$J$2500,"<>")=0,"",SUMIFS('Chapter Data'!$J$2:$J$2500,'Chapter Data'!$A$2:$A$2500,$A10,'Chapter Data'!$D$2:$D$2500,OurChapter)),"") | U10: =IFERROR(IF(COUNTIFS('Chapter Data'!$A$2:$A$2500,$A10,'Chapter Data'!$D$2:$D$2500,OurChapter,'Chapter Data'!$K$2:$K$2500,"<>")=0,"",SUMIFS('Chapter Data'!$K$2:$K$2500,'Chapter Data'!$A$2:$A$2500,$A10,'Chapter Data'!$D$2:$D$2500,OurChapter)),"") | V10: {=IF(COUNTIFS('Chapter Data'!$A$2:$A$2500,$A10,'Chapter Data'!$C$2:$C$2500,"IFC",'Chapter Data'!$K$2:$K$2500,">=0")<MinChapters,"",MEDIAN(IF(('Chapter Data'!$A$2:$A$2500=$A10)*('Chapter Data'!$C$2:$C$2500="IFC")*ISNUMBER('Chapter Data'!$K$2:$K$2500),'Chapter Data'!$K$2:$K$2500)))}
A11: Fall 2021 | B11: =IF(IFERROR(INDEX('GPA Matrix'!$B$43:$U$43,MATCH($A11,'GPA Matrix'!$B$2:$U$2,0)),"")="","",IFERROR(INDEX('GPA Matrix'!$B$43:$U$43,MATCH($A11,'GPA Matrix'!$B$2:$U$2,0)),"")) -> 3.167 | C11: =IF(IFERROR(INDEX('GPA Matrix'!$B$40:$U$40,MATCH($A11,'GPA Matrix'!$B$2:$U$2,0)),"")="","",IFERROR(INDEX('GPA Matrix'!$B$40:$U$40,MATCH($A11,'GPA Matrix'!$B$2:$U$2,0)),"")) -> 3.2240222 | D11: =IF(IFERROR(INDEX('GPA Matrix'!$B$41:$U$41,MATCH($A11,'GPA Matrix'!$B$2:$U$2,0)),"")="","",IFERROR(INDEX('GPA Matrix'!$B$41:$U$41,MATCH($A11,'GPA Matrix'!$B$2:$U$2,0)),"")) -> 3.183 | E11: =IFERROR(IF(INDEX('Campus Stats'!$C$2:$C$37,MATCH($A11,'Campus Stats'!$A$2:$A$37,0))="","",INDEX('Campus Stats'!$C$2:$C$37,MATCH($A11,'Campus Stats'!$A$2:$A$37,0))),"") -> 3.084 | F11: =IFERROR(IF(INDEX('Campus Stats'!$F$2:$F$37,MATCH($A11,'Campus Stats'!$A$2:$A$37,0))="","",INDEX('Campus Stats'!$F$2:$F$37,MATCH($A11,'Campus Stats'!$A$2:$A$37,0))),"") -> 3.221 | G11: =IF(OR(B11="",C11=""),"",B11-C11) -> -0.057022172 | H11: =IF(IFERROR(INDEX('GPA Matrix'!$B$44:$U$44,MATCH($A11,'GPA Matrix'!$B$2:$U$2,0)),"")="","",IFERROR(INDEX('GPA Matrix'!$B$44:$U$44,MATCH($A11,'GPA Matrix'!$B$2:$U$2,0)),"")) -> 14 | I11: =IF(H11="","",IFERROR(INDEX('GPA Matrix'!$B$39:$U$39,MATCH($A11,'GPA Matrix'!$B$2:$U$2,0)),"")) -> 25 | K11: =IF(IFERROR(INDEX('Members Matrix'!$B$43:$U$43,MATCH($A11,'Members Matrix'!$B$2:$U$2,0)),"")="","",IFERROR(INDEX('Members Matrix'!$B$43:$U$43,MATCH($A11,'Members Matrix'!$B$2:$U$2,0)),"")) -> 74 | L11: =IF(IFERROR(INDEX('Members Matrix'!$B$42:$U$42,MATCH($A11,'Members Matrix'!$B$2:$U$2,0)),"")="","",IFERROR(INDEX('Members Matrix'!$B$42:$U$42,MATCH($A11,'Members Matrix'!$B$2:$U$2,0)),"")) -> 74 | M11: =IF(IFERROR(INDEX('Members Matrix'!$B$44:$U$44,MATCH($A11,'Members Matrix'!$B$2:$U$2,0)),"")="","",IFERROR(INDEX('Members Matrix'!$B$44:$U$44,MATCH($A11,'Members Matrix'!$B$2:$U$2,0)),"")) -> 13 | N11: =IF(IFERROR(INDEX('Members Matrix'!$B$45:$U$45,MATCH($A11,'Members Matrix'!$B$2:$U$2,0)),"")="","",IFERROR(INDEX('Members Matrix'!$B$45:$U$45,MATCH($A11,'Members Matrix'!$B$2:$U$2,0)),"")) -> 100 | O11: =IF(IFERROR(INDEX('New Members Matrix'!$B$43:$U$43,MATCH($A11,'New Members Matrix'!$B$2:$U$2,0)),"")="","",IFERROR(INDEX('New Members Matrix'!$B$43:$U$43,MATCH($A11,'New Members Matrix'!$B$2:$U$2,0)),"")) -> 14 | P11: =IF(IFERROR(INDEX('New Members Matrix'!$B$41:$U$41,MATCH($A11,'New Members Matrix'!$B$2:$U$2,0)),"")="","",IFERROR(INDEX('New Members Matrix'!$B$41:$U$41,MATCH($A11,'New Members Matrix'!$B$2:$U$2,0)),"")) -> 21 | Q11: =IF(IFERROR(INDEX('New Members Matrix'!$B$42:$U$42,MATCH($A11,'New Members Matrix'!$B$2:$U$2,0)),"")="","",IFERROR(INDEX('New Members Matrix'!$B$42:$U$42,MATCH($A11,'New Members Matrix'!$B$2:$U$2,0)),"")) -> 20 | R11: =IF(IFERROR(INDEX('New Members Matrix'!$B$44:$U$44,MATCH($A11,'New Members Matrix'!$B$2:$U$2,0)),"")="","",IFERROR(INDEX('New Members Matrix'!$B$44:$U$44,MATCH($A11,'New Members Matrix'!$B$2:$U$2,0)),"")) -> 16 | S11: =IF(IFERROR(INDEX('New Members Matrix'!$B$45:$U$45,MATCH($A11,'New Members Matrix'!$B$2:$U$2,0)),"")="","",IFERROR(INDEX('New Members Matrix'!$B$45:$U$45,MATCH($A11,'New Members Matrix'!$B$2:$U$2,0)),"")) -> 0.026666667 | T11: =IFERROR(IF(COUNTIFS('Chapter Data'!$A$2:$A$2500,$A11,'Chapter Data'!$D$2:$D$2500,OurChapter,'Chapter Data'!$J$2:$J$2500,"<>")=0,"",SUMIFS('Chapter Data'!$J$2:$J$2500,'Chapter Data'!$A$2:$A$2500,$A11,'Chapter Data'!$D$2:$D$2500,OurChapter)),"") | U11: =IFERROR(IF(COUNTIFS('Chapter Data'!$A$2:$A$2500,$A11,'Chapter Data'!$D$2:$D$2500,OurChapter,'Chapter Data'!$K$2:$K$2500,"<>")=0,"",SUMIFS('Chapter Data'!$K$2:$K$2500,'Chapter Data'!$A$2:$A$2500,$A11,'Chapter Data'!$D$2:$D$2500,OurChapter)),"") | V11: {=IF(COUNTIFS('Chapter Data'!$A$2:$A$2500,$A11,'Chapter Data'!$C$2:$C$2500,"IFC",'Chapter Data'!$K$2:$K$2500,">=0")<MinChapters,"",MEDIAN(IF(('Chapter Data'!$A$2:$A$2500=$A11)*('Chapter Data'!$C$2:$C$2500="IFC")*ISNUMBER('Chapter Data'!$K$2:$K$2500),'Chapter Data'!$K$2:$K$2500)))}
A12: Spring 2022 | B12: =IF(IFERROR(INDEX('GPA Matrix'!$B$43:$U$43,MATCH($A12,'GPA Matrix'!$B$2:$U$2,0)),"")="","",IFERROR(INDEX('GPA Matrix'!$B$43:$U$43,MATCH($A12,'GPA Matrix'!$B$2:$U$2,0)),"")) -> 3.316 | C12: =IF(IFERROR(INDEX('GPA Matrix'!$B$40:$U$40,MATCH($A12,'GPA Matrix'!$B$2:$U$2,0)),"")="","",IFERROR(INDEX('GPA Matrix'!$B$40:$U$40,MATCH($A12,'GPA Matrix'!$B$2:$U$2,0)),"")) -> 3.3063156 | D12: =IF(IFERROR(INDEX('GPA Matrix'!$B$41:$U$41,MATCH($A12,'GPA Matrix'!$B$2:$U$2,0)),"")="","",IFERROR(INDEX('GPA Matrix'!$B$41:$U$41,MATCH($A12,'GPA Matrix'!$B$2:$U$2,0)),"")) -> 3.266 | E12: =IFERROR(IF(INDEX('Campus Stats'!$C$2:$C$37,MATCH($A12,'Campus Stats'!$A$2:$A$37,0))="","",INDEX('Campus Stats'!$C$2:$C$37,MATCH($A12,'Campus Stats'!$A$2:$A$37,0))),"") -> 3.161 | F12: =IFERROR(IF(INDEX('Campus Stats'!$F$2:$F$37,MATCH($A12,'Campus Stats'!$A$2:$A$37,0))="","",INDEX('Campus Stats'!$F$2:$F$37,MATCH($A12,'Campus Stats'!$A$2:$A$37,0))),"") -> 3.29 | G12: =IF(OR(B12="",C12=""),"",B12-C12) -> 0.0096843641 | H12: =IF(IFERROR(INDEX('GPA Matrix'!$B$44:$U$44,MATCH($A12,'GPA Matrix'!$B$2:$U$2,0)),"")="","",IFERROR(INDEX('GPA Matrix'!$B$44:$U$44,MATCH($A12,'GPA Matrix'!$B$2:$U$2,0)),"")) -> 10 | I12: =IF(H12="","",IFERROR(INDEX('GPA Matrix'!$B$39:$U$39,MATCH($A12,'GPA Matrix'!$B$2:$U$2,0)),"")) -> 25 | K12: =IF(IFERROR(INDEX('Members Matrix'!$B$43:$U$43,MATCH($A12,'Members Matrix'!$B$2:$U$2,0)),"")="","",IFERROR(INDEX('Members Matrix'!$B$43:$U$43,MATCH($A12,'Members Matrix'!$B$2:$U$2,0)),"")) -> 68 | L12: =IF(IFERROR(INDEX('Members Matrix'!$B$42:$U$42,MATCH($A12,'Members Matrix'!$B$2:$U$2,0)),"")="","",IFERROR(INDEX('Members Matrix'!$B$42:$U$42,MATCH($A12,'Members Matrix'!$B$2:$U$2,0)),"")) -> 68 | M12: =IF(IFERROR(INDEX('Members Matrix'!$B$44:$U$44,MATCH($A12,'Members Matrix'!$B$2:$U$2,0)),"")="","",IFERROR(INDEX('Members Matrix'!$B$44:$U$44,MATCH($A12,'Members Matrix'!$B$2:$U$2,0)),"")) -> 13 | N12: =IF(IFERROR(INDEX('Members Matrix'!$B$45:$U$45,MATCH($A12,'Members Matrix'!$B$2:$U$2,0)),"")="","",IFERROR(INDEX('Members Matrix'!$B$45:$U$45,MATCH($A12,'Members Matrix'!$B$2:$U$2,0)),"")) -> 100 | O12: =IF(IFERROR(INDEX('New Members Matrix'!$B$43:$U$43,MATCH($A12,'New Members Matrix'!$B$2:$U$2,0)),"")="","",IFERROR(INDEX('New Members Matrix'!$B$43:$U$43,MATCH($A12,'New Members Matrix'!$B$2:$U$2,0)),"")) | P12: =IF(IFERROR(INDEX('New Members Matrix'!$B$41:$U$41,MATCH($A12,'New Members Matrix'!$B$2:$U$2,0)),"")="","",IFERROR(INDEX('New Members Matrix'!$B$41:$U$41,MATCH($A12,'New Members Matrix'!$B$2:$U$2,0)),"")) | Q12: =IF(IFERROR(INDEX('New Members Matrix'!$B$42:$U$42,MATCH($A12,'New Members Matrix'!$B$2:$U$2,0)),"")="","",IFERROR(INDEX('New Members Matrix'!$B$42:$U$42,MATCH($A12,'New Members Matrix'!$B$2:$U$2,0)),"")) | R12: =IF(IFERROR(INDEX('New Members Matrix'!$B$44:$U$44,MATCH($A12,'New Members Matrix'!$B$2:$U$2,0)),"")="","",IFERROR(INDEX('New Members Matrix'!$B$44:$U$44,MATCH($A12,'New Members Matrix'!$B$2:$U$2,0)),"")) | S12: =IF(IFERROR(INDEX('New Members Matrix'!$B$45:$U$45,MATCH($A12,'New Members Matrix'!$B$2:$U$2,0)),"")="","",IFERROR(INDEX('New Members Matrix'!$B$45:$U$45,MATCH($A12,'New Members Matrix'!$B$2:$U$2,0)),"")) | T12: =IFERROR(IF(COUNTIFS('Chapter Data'!$A$2:$A$2500,$A12,'Chapter Data'!$D$2:$D$2500,OurChapter,'Chapter Data'!$J$2:$J$2500,"<>")=0,"",SUMIFS('Chapter Data'!$J$2:$J$2500,'Chapter Data'!$A$2:$A$2500,$A12,'Chapter Data'!$D$2:$D$2500,OurChapter)),"") | U12: =IFERROR(IF(COUNTIFS('Chapter Data'!$A$2:$A$2500,$A12,'Chapter Data'!$D$2:$D$2500,OurChapter,'Chapter Data'!$K$2:$K$2500,"<>")=0,"",SUMIFS('Chapter Data'!$K$2:$K$2500,'Chapter Data'!$A$2:$A$2500,$A12,'Chapter Data'!$D$2:$D$2500,OurChapter)),"") | V12: {=IF(COUNTIFS('Chapter Data'!$A$2:$A$2500,$A12,'Chapter Data'!$C$2:$C$2500,"IFC",'Chapter Data'!$K$2:$K$2500,">=0")<MinChapters,"",MEDIAN(IF(('Chapter Data'!$A$2:$A$2500=$A12)*('Chapter Data'!$C$2:$C$2500="IFC")*ISNUMBER('Chapter Data'!$K$2:$K$2500),'Chapter Data'!$K$2:$K$2500)))}
A13: Fall 2022 | B13: =IF(IFERROR(INDEX('GPA Matrix'!$B$43:$U$43,MATCH($A13,'GPA Matrix'!$B$2:$U$2,0)),"")="","",IFERROR(INDEX('GPA Matrix'!$B$43:$U$43,MATCH($A13,'GPA Matrix'!$B$2:$U$2,0)),"")) -> 3.096 | C13: =IF(IFERROR(INDEX('GPA Matrix'!$B$40:$U$40,MATCH($A13,'GPA Matrix'!$B$2:$U$2,0)),"")="","",IFERROR(INDEX('GPA Matrix'!$B$40:$U$40,MATCH($A13,'GPA Matrix'!$B$2:$U$2,0)),"")) -> 3.2802256 | D13: =IF(IFERROR(INDEX('GPA Matrix'!$B$41:$U$41,MATCH($A13,'GPA Matrix'!$B$2:$U$2,0)),"")="","",IFERROR(INDEX('GPA Matrix'!$B$41:$U$41,MATCH($A13,'GPA Matrix'!$B$2:$U$2,0)),"")) -> 3.2415 | E13: =IFERROR(IF(INDEX('Campus Stats'!$C$2:$C$37,MATCH($A13,'Campus Stats'!$A$2:$A$37,0))="","",INDEX('Campus Stats'!$C$2:$C$37,MATCH($A13,'Campus Stats'!$A$2:$A$37,0))),"") -> 3.131 | F13: =IFERROR(IF(INDEX('Campus Stats'!$F$2:$F$37,MATCH($A13,'Campus Stats'!$A$2:$A$37,0))="","",INDEX('Campus Stats'!$F$2:$F$37,MATCH($A13,'Campus Stats'!$A$2:$A$37,0))),"") -> 3.265 | G13: =IF(OR(B13="",C13=""),"",B13-C13) -> -0.18422559 | H13: =IF(IFERROR(INDEX('GPA Matrix'!$B$44:$U$44,MATCH($A13,'GPA Matrix'!$B$2:$U$2,0)),"")="","",IFERROR(INDEX('GPA Matrix'!$B$44:$U$44,MATCH($A13,'GPA Matrix'!$B$2:$U$2,0)),"")) -> 18 | I13: =IF(H13="","",IFERROR(INDEX('GPA Matrix'!$B$39:$U$39,MATCH($A13,'GPA Matrix'!$B$2:$U$2,0)),"")) -> 24 | K13: =IF(IFERROR(INDEX('Members Matrix'!$B$43:$U$43,MATCH($A13,'Members Matrix'!$B$2:$U$2,0)),"")="","",IFERROR(INDEX('Members Matrix'!$B$43:$U$43,MATCH($A13,'Members Matrix'!$B$2:$U$2,0)),"")) -> 71 | L13: =IF(IFERROR(INDEX('Members Matrix'!$B$42:$U$42,MATCH($A13,'Members Matrix'!$B$2:$U$2,0)),"")="","",IFERROR(INDEX('Members Matrix'!$B$42:$U$42,MATCH($A13,'Members Matrix'!$B$2:$U$2,0)),"")) -> 77 | M13: =IF(IFERROR(INDEX('Members Matrix'!$B$44:$U$44,MATCH($A13,'Members Matrix'!$B$2:$U$2,0)),"")="","",IFERROR(INDEX('Members Matrix'!$B$44:$U$44,MATCH($A13,'Members Matrix'!$B$2:$U$2,0)),"")) -> 13 | N13: =IF(IFERROR(INDEX('Members Matrix'!$B$45:$U$45,MATCH($A13,'Members Matrix'!$B$2:$U$2,0)),"")="","",IFERROR(INDEX('Members Matrix'!$B$45:$U$45,MATCH($A13,'Members Matrix'!$B$2:$U$2,0)),"")) -> 92.207792 | O13: =IF(IFERROR(INDEX('New Members Matrix'!$B$43:$U$43,MATCH($A13,'New Members Matrix'!$B$2:$U$2,0)),"")="","",IFERROR(INDEX('New Members Matrix'!$B$43:$U$43,MATCH($A13,'New Members Matrix'!$B$2:$U$2,0)),"")) -> 17 | P13: =IF(IFERROR(INDEX('New Members Matrix'!$B$41:$U$41,MATCH($A13,'New Members Matrix'!$B$2:$U$2,0)),"")="","",IFERROR(INDEX('New Members Matrix'!$B$41:$U$41,MATCH($A13,'New Members Matrix'!$B$2:$U$2,0)),"")) -> 19.791667 | Q13: =IF(IFERROR(INDEX('New Members Matrix'!$B$42:$U$42,MATCH($A13,'New Members Matrix'!$B$2:$U$2,0)),"")="","",IFERROR(INDEX('New Members Matrix'!$B$42:$U$42,MATCH($A13,'New Members Matrix'!$B$2:$U$2,0)),"")) -> 21.5 | R13: =IF(IFERROR(INDEX('New Members Matrix'!$B$44:$U$44,MATCH($A13,'New Members Matrix'!$B$2:$U$2,0)),"")="","",IFERROR(INDEX('New Members Matrix'!$B$44:$U$44,MATCH($A13,'New Members Matrix'!$B$2:$U$2,0)),"")) -> 14 | S13: =IF(IFERROR(INDEX('New Members Matrix'!$B$45:$U$45,MATCH($A13,'New Members Matrix'!$B$2:$U$2,0)),"")="","",IFERROR(INDEX('New Members Matrix'!$B$45:$U$45,MATCH($A13,'New Members Matrix'!$B$2:$U$2,0)),"")) -> 0.035789474 | T13: =IFERROR(IF(COUNTIFS('Chapter Data'!$A$2:$A$2500,$A13,'Chapter Data'!$D$2:$D$2500,OurChapter,'Chapter Data'!$J$2:$J$2500,"<>")=0,"",SUMIFS('Chapter Data'!$J$2:$J$2500,'Chapter Data'!$A$2:$A$2500,$A13,'Chapter Data'!$D$2:$D$2500,OurChapter)),"") | U13: =IFERROR(IF(COUNTIFS('Chapter Data'!$A$2:$A$2500,$A13,'Chapter Data'!$D$2:$D$2500,OurChapter,'Chapter Data'!$K$2:$K$2500,"<>")=0,"",SUMIFS('Chapter Data'!$K$2:$K$2500,'Chapter Data'!$A$2:$A$2500,$A13,'Chapter Data'!$D$2:$D$2500,OurChapter)),"") | V13: {=IF(COUNTIFS('Chapter Data'!$A$2:$A$2500,$A13,'Chapter Data'!$C$2:$C$2500,"IFC",'Chapter Data'!$K$2:$K$2500,">=0")<MinChapters,"",MEDIAN(IF(('Chapter Data'!$A$2:$A$2500=$A13)*('Chapter Data'!$C$2:$C$2500="IFC")*ISNUMBER('Chapter Data'!$K$2:$K$2500),'Chapter Data'!$K$2:$K$2500)))}
A14: Spring 2023 | B14: =IF(IFERROR(INDEX('GPA Matrix'!$B$43:$U$43,MATCH($A14,'GPA Matrix'!$B$2:$U$2,0)),"")="","",IFERROR(INDEX('GPA Matrix'!$B$43:$U$43,MATCH($A14,'GPA Matrix'!$B$2:$U$2,0)),"")) -> 3.121 | C14: =IF(IFERROR(INDEX('GPA Matrix'!$B$40:$U$40,MATCH($A14,'GPA Matrix'!$B$2:$U$2,0)),"")="","",IFERROR(INDEX('GPA Matrix'!$B$40:$U$40,MATCH($A14,'GPA Matrix'!$B$2:$U$2,0)),"")) -> 3.3549002 | D14: =IF(IFERROR(INDEX('GPA Matrix'!$B$41:$U$41,MATCH($A14,'GPA Matrix'!$B$2:$U$2,0)),"")="","",IFERROR(INDEX('GPA Matrix'!$B$41:$U$41,MATCH($A14,'GPA Matrix'!$B$2:$U$2,0)),"")) -> 3.287 | E14: =IFERROR(IF(INDEX('Campus Stats'!$C$2:$C$37,MATCH($A14,'Campus Stats'!$A$2:$A$37,0))="","",INDEX('Campus Stats'!$C$2:$C$37,MATCH($A14,'Campus Stats'!$A$2:$A$37,0))),"") -> 3.198 | F14: =IFERROR(IF(INDEX('Campus Stats'!$F$2:$F$37,MATCH($A14,'Campus Stats'!$A$2:$A$37,0))="","",INDEX('Campus Stats'!$F$2:$F$37,MATCH($A14,'Campus Stats'!$A$2:$A$37,0))),"") -> 3.337 | G14: =IF(OR(B14="",C14=""),"",B14-C14) -> -0.23390018 | H14: =IF(IFERROR(INDEX('GPA Matrix'!$B$44:$U$44,MATCH($A14,'GPA Matrix'!$B$2:$U$2,0)),"")="","",IFERROR(INDEX('GPA Matrix'!$B$44:$U$44,MATCH($A14,'GPA Matrix'!$B$2:$U$2,0)),"")) -> 19 | I14: =IF(H14="","",IFERROR(INDEX('GPA Matrix'!$B$39:$U$39,MATCH($A14,'GPA Matrix'!$B$2:$U$2,0)),"")) -> 25 | K14: =IF(IFERROR(INDEX('Members Matrix'!$B$43:$U$43,MATCH($A14,'Members Matrix'!$B$2:$U$2,0)),"")="","",IFERROR(INDEX('Members Matrix'!$B$43:$U$43,MATCH($A14,'Members Matrix'!$B$2:$U$2,0)),"")) -> 71 | L14: =IF(IFERROR(INDEX('Members Matrix'!$B$42:$U$42,MATCH($A14,'Members Matrix'!$B$2:$U$2,0)),"")="","",IFERROR(INDEX('Members Matrix'!$B$42:$U$42,MATCH($A14,'Members Matrix'!$B$2:$U$2,0)),"")) -> 71 | M14: =IF(IFERROR(INDEX('Members Matrix'!$B$44:$U$44,MATCH($A14,'Members Matrix'!$B$2:$U$2,0)),"")="","",IFERROR(INDEX('Members Matrix'!$B$44:$U$44,MATCH($A14,'Members Matrix'!$B$2:$U$2,0)),"")) -> 13 | N14: =IF(IFERROR(INDEX('Members Matrix'!$B$45:$U$45,MATCH($A14,'Members Matrix'!$B$2:$U$2,0)),"")="","",IFERROR(INDEX('Members Matrix'!$B$45:$U$45,MATCH($A14,'Members Matrix'!$B$2:$U$2,0)),"")) -> 100 | O14: =IF(IFERROR(INDEX('New Members Matrix'!$B$43:$U$43,MATCH($A14,'New Members Matrix'!$B$2:$U$2,0)),"")="","",IFERROR(INDEX('New Members Matrix'!$B$43:$U$43,MATCH($A14,'New Members Matrix'!$B$2:$U$2,0)),"")) -> 6 | P14: =IF(IFERROR(INDEX('New Members Matrix'!$B$41:$U$41,MATCH($A14,'New Members Matrix'!$B$2:$U$2,0)),"")="","",IFERROR(INDEX('New Members Matrix'!$B$41:$U$41,MATCH($A14,'New Members Matrix'!$B$2:$U$2,0)),"")) -> 5.9411765 | Q14: =IF(IFERROR(INDEX('New Members Matrix'!$B$42:$U$42,MATCH($A14,'New Members Matrix'!$B$2:$U$2,0)),"")="","",IFERROR(INDEX('New Members Matrix'!$B$42:$U$42,MATCH($A14,'New Members Matrix'!$B$2:$U$2,0)),"")) -> 5 | R14: =IF(IFERROR(INDEX('New Members Matrix'!$B$44:$U$44,MATCH($A14,'New Members Matrix'!$B$2:$U$2,0)),"")="","",IFERROR(INDEX('New Members Matrix'!$B$44:$U$44,MATCH($A14,'New Members Matrix'!$B$2:$U$2,0)),"")) -> 6 | S14: =IF(IFERROR(INDEX('New Members Matrix'!$B$45:$U$45,MATCH($A14,'New Members Matrix'!$B$2:$U$2,0)),"")="","",IFERROR(INDEX('New Members Matrix'!$B$45:$U$45,MATCH($A14,'New Members Matrix'!$B$2:$U$2,0)),"")) -> 0.059405941 | T14: =IFERROR(IF(COUNTIFS('Chapter Data'!$A$2:$A$2500,$A14,'Chapter Data'!$D$2:$D$2500,OurChapter,'Chapter Data'!$J$2:$J$2500,"<>")=0,"",SUMIFS('Chapter Data'!$J$2:$J$2500,'Chapter Data'!$A$2:$A$2500,$A14,'Chapter Data'!$D$2:$D$2500,OurChapter)),"") | U14: =IFERROR(IF(COUNTIFS('Chapter Data'!$A$2:$A$2500,$A14,'Chapter Data'!$D$2:$D$2500,OurChapter,'Chapter Data'!$K$2:$K$2500,"<>")=0,"",SUMIFS('Chapter Data'!$K$2:$K$2500,'Chapter Data'!$A$2:$A$2500,$A14,'Chapter Data'!$D$2:$D$2500,OurChapter)),"") | V14: {=IF(COUNTIFS('Chapter Data'!$A$2:$A$2500,$A14,'Chapter Data'!$C$2:$C$2500,"IFC",'Chapter Data'!$K$2:$K$2500,">=0")<MinChapters,"",MEDIAN(IF(('Chapter Data'!$A$2:$A$2500=$A14)*('Chapter Data'!$C$2:$C$2500="IFC")*ISNUMBER('Chapter Data'!$K$2:$K$2500),'Chapter Data'!$K$2:$K$2500)))}
A15: Fall 2023 | B15: =IF(IFERROR(INDEX('GPA Matrix'!$B$43:$U$43,MATCH($A15,'GPA Matrix'!$B$2:$U$2,0)),"")="","",IFERROR(INDEX('GPA Matrix'!$B$43:$U$43,MATCH($A15,'GPA Matrix'!$B$2:$U$2,0)),"")) -> 2.997 | C15: =IF(IFERROR(INDEX('GPA Matrix'!$B$40:$U$40,MATCH($A15,'GPA Matrix'!$B$2:$U$2,0)),"")="","",IFERROR(INDEX('GPA Matrix'!$B$40:$U$40,MATCH($A15,'GPA Matrix'!$B$2:$U$2,0)),"")) -> 3.2816753 | D15: =IF(IFERROR(INDEX('GPA Matrix'!$B$41:$U$41,MATCH($A15,'GPA Matrix'!$B$2:$U$2,0)),"")="","",IFERROR(INDEX('GPA Matrix'!$B$41:$U$41,MATCH($A15,'GPA Matrix'!$B$2:$U$2,0)),"")) -> 3.199 | E15: =IFERROR(IF(INDEX('Campus Stats'!$C$2:$C$37,MATCH($A15,'Campus Stats'!$A$2:$A$37,0))="","",INDEX('Campus Stats'!$C$2:$C$37,MATCH($A15,'Campus Stats'!$A$2:$A$37,0))),"") -> 3.132 | F15: =IFERROR(IF(INDEX('Campus Stats'!$F$2:$F$37,MATCH($A15,'Campus Stats'!$A$2:$A$37,0))="","",INDEX('Campus Stats'!$F$2:$F$37,MATCH($A15,'Campus Stats'!$A$2:$A$37,0))),"") -> 3.257 | G15: =IF(OR(B15="",C15=""),"",B15-C15) -> -0.28467533 | H15: =IF(IFERROR(INDEX('GPA Matrix'!$B$44:$U$44,MATCH($A15,'GPA Matrix'!$B$2:$U$2,0)),"")="","",IFERROR(INDEX('GPA Matrix'!$B$44:$U$44,MATCH($A15,'GPA Matrix'!$B$2:$U$2,0)),"")) -> 19 | I15: =IF(H15="","",IFERROR(INDEX('GPA Matrix'!$B$39:$U$39,MATCH($A15,'GPA Matrix'!$B$2:$U$2,0)),"")) -> 25 | K15: =IF(IFERROR(INDEX('Members Matrix'!$B$43:$U$43,MATCH($A15,'Members Matrix'!$B$2:$U$2,0)),"")="","",IFERROR(INDEX('Members Matrix'!$B$43:$U$43,MATCH($A15,'Members Matrix'!$B$2:$U$2,0)),"")) -> 60 | L15: =IF(IFERROR(INDEX('Members Matrix'!$B$42:$U$42,MATCH($A15,'Members Matrix'!$B$2:$U$2,0)),"")="","",IFERROR(INDEX('Members Matrix'!$B$42:$U$42,MATCH($A15,'Members Matrix'!$B$2:$U$2,0)),"")) -> 66 | M15: =IF(IFERROR(INDEX('Members Matrix'!$B$44:$U$44,MATCH($A15,'Members Matrix'!$B$2:$U$2,0)),"")="","",IFERROR(INDEX('Members Matrix'!$B$44:$U$44,MATCH($A15,'Members Matrix'!$B$2:$U$2,0)),"")) -> 15 | N15: =IF(IFERROR(INDEX('Members Matrix'!$B$45:$U$45,MATCH($A15,'Members Matrix'!$B$2:$U$2,0)),"")="","",IFERROR(INDEX('Members Matrix'!$B$45:$U$45,MATCH($A15,'Members Matrix'!$B$2:$U$2,0)),"")) -> 90.909091 | O15: =IF(IFERROR(INDEX('New Members Matrix'!$B$43:$U$43,MATCH($A15,'New Members Matrix'!$B$2:$U$2,0)),"")="","",IFERROR(INDEX('New Members Matrix'!$B$43:$U$43,MATCH($A15,'New Members Matrix'!$B$2:$U$2,0)),"")) | P15: =IF(IFERROR(INDEX('New Members Matrix'!$B$41:$U$41,MATCH($A15,'New Members Matrix'!$B$2:$U$2,0)),"")="","",IFERROR(INDEX('New Members Matrix'!$B$41:$U$41,MATCH($A15,'New Members Matrix'!$B$2:$U$2,0)),"")) | Q15: =IF(IFERROR(INDEX('New Members Matrix'!$B$42:$U$42,MATCH($A15,'New Members Matrix'!$B$2:$U$2,0)),"")="","",IFERROR(INDEX('New Members Matrix'!$B$42:$U$42,MATCH($A15,'New Members Matrix'!$B$2:$U$2,0)),"")) | R15: =IF(IFERROR(INDEX('New Members Matrix'!$B$44:$U$44,MATCH($A15,'New Members Matrix'!$B$2:$U$2,0)),"")="","",IFERROR(INDEX('New Members Matrix'!$B$44:$U$44,MATCH($A15,'New Members Matrix'!$B$2:$U$2,0)),"")) | S15: =IF(IFERROR(INDEX('New Members Matrix'!$B$45:$U$45,MATCH($A15,'New Members Matrix'!$B$2:$U$2,0)),"")="","",IFERROR(INDEX('New Members Matrix'!$B$45:$U$45,MATCH($A15,'New Members Matrix'!$B$2:$U$2,0)),"")) | T15: =IFERROR(IF(COUNTIFS('Chapter Data'!$A$2:$A$2500,$A15,'Chapter Data'!$D$2:$D$2500,OurChapter,'Chapter Data'!$J$2:$J$2500,"<>")=0,"",SUMIFS('Chapter Data'!$J$2:$J$2500,'Chapter Data'!$A$2:$A$2500,$A15,'Chapter Data'!$D$2:$D$2500,OurChapter)),"") | U15: =IFERROR(IF(COUNTIFS('Chapter Data'!$A$2:$A$2500,$A15,'Chapter Data'!$D$2:$D$2500,OurChapter,'Chapter Data'!$K$2:$K$2500,"<>")=0,"",SUMIFS('Chapter Data'!$K$2:$K$2500,'Chapter Data'!$A$2:$A$2500,$A15,'Chapter Data'!$D$2:$D$2500,OurChapter)),"") | V15: {=IF(COUNTIFS('Chapter Data'!$A$2:$A$2500,$A15,'Chapter Data'!$C$2:$C$2500,"IFC",'Chapter Data'!$K$2:$K$2500,">=0")<MinChapters,"",MEDIAN(IF(('Chapter Data'!$A$2:$A$2500=$A15)*('Chapter Data'!$C$2:$C$2500="IFC")*ISNUMBER('Chapter Data'!$K$2:$K$2500),'Chapter Data'!$K$2:$K$2500)))}
